Workbook
Name _CODIGOS2: #REF!
Name _CURSOS: #REF!

Sheet DEMANDA 2026-2
B3: PROYECCIÓN DEMANDA ACADÉMICA PERIODO 2026-1
A5: FACULTAD DE CIENCIAS ADMINISTRATIVAS, CONTABLES Y COMERCIO - CARRERA MERCADOTECNIA
A6: Carrera | B6: Asignatura | C6: Nivel | D6: Numero de horas clases semanales | E6: Proyección de estudiantes a matricularse | F6: Numeros de paralelos a aperturarse | G6: Paralelos por nivel | H6: Total Horas
A7: MERCADOTECNIA O MARKETING (2024NS) | B7: MATEMÁTICA APLICADA A LOS NEGOCIOS | C7: 1 | D7: 4 | E7: 31 | F7: 1 | G7: 1 | H7: =+D7*F7 -> 4
A8: MERCADOTECNIA O MARKETING (2024NS) | B8: TECNOLOGÍA Y TENDENCIAS DE LA CULTURA DIGITAL | C8: 1 | D8: 3 | E8: 31 | F8: 1 | H8: =+D8*F8 -> 3
A9: MERCADOTECNIA O MARKETING (2024NS) | B9: GESTIÓN ADMINISTRATIVA | C9: 1 | D9: 3 | E9: 31 | F9: 1 | H9: =+D9*F9 -> 3
A10: MERCADOTECNIA O MARKETING (2024NS) | B10: CONTABILIDAD ADMINISTRATIVA | C10: 1 | D10: 4 | E10: 31 | F10: 1 | H10: =+D10*F10 -> 4
A11: MERCADOTECNIA O MARKETING (2024NS) | B11: FUNDAMENTOS DE LA MERCADOTECNIA | C11: 1 | D11: 4 | E11: 31 | F11: 1 | H11: =+D11*F11 -> 4
A12: MERCADOTECNIA O MARKETING (2024NS) | B12: CONTEXTO SOCIO ECONÓMICO CULTURAL E INTERCULTURALIDAD | C12: 1 | D12: 3 | E12: 31 | F12: 1 | H12: =+D12*F12 -> 3
A13: MERCADOTECNIA O MARKETING (2024NS) | B13: CÁTEDRA ALFARO | C13: 1 | D13: 0 | E13: 31 | F13: 1 | H13: =+D13*F13 -> 0 | I13: =SUM(D7:D13) -> 21
A14: MERCADOTECNIA O MARKETING (2024NS) | B14: CÁLCULO PARA LA GESTIÓN EMPRESARIAL | C14: 2 | D14: 5 | E14: 35 | F14: 1 | G14: 1 | H14: =+D14*F14 -> 5
A15: MERCADOTECNIA O MARKETING (2024NS) | B15: COMUNICACIÓN INTEGRAL DE LA MERCADOTECNIA | C15: 2 | D15: 4 | E15: 35 | F15: 1 | H15: =+D15*F15 -> 4
A16: MERCADOTECNIA O MARKETING (2024NS) | B16: MICRO Y MACROECONOMÍA | C16: 2 | D16: 4 | E16: 35 | F16: 1 | H16: =+D16*F16 -> 4
A17: MERCADOTECNIA O MARKETING (2024NS) | B17: ANÁLISIS DE COSTOS | C17: 2 | D17: 4 | E17: 35 | F17: 1 | H17: =+D17*F17 -> 4
A18: MERCADOTECNIA O MARKETING (2024NS) | B18: DISEÑO Y COMPOSICIÓN GRÁFICA | C18: 2 | D18: 3 | E18: 35 | F18: 1 | H18: =+D18*F18 -> 3
A19: MERCADOTECNIA O MARKETING (2024NS) | B19: METODOLOGÍA DE LA INVESTIGACIÓN | C19: 2 | D19: 4 | E19: 35 | F19: 1 | H19: =+D19*F19 -> 4 | I19: =SUM(D14:D19) -> 24
A20: MERCADOTECNIA O MARKETING (2024NS) | B20: ESTADÍSTICA | C20: 3 | D20: 4 | E20: 60 | F20: 2 | G20: 2 | H20: =+D20*F20 -> 8
A21: MERCADOTECNIA O MARKETING (2024NS) | B21: REDACCIÓN PUBLICITARIA | C21: 3 | D21: 5 | E21: 60 | F21: 2 | H21: =+D21*F21 -> 10
A22: MERCADOTECNIA O MARKETING (2024NS) | B22: GESTIÓN DEL TALENTO HUMANO | C22: 3 | D22: 4 | E22: 60 | F22: 2 | H22: =+D22*F22 -> 8
A23: MERCADOTECNIA O MARKETING (2024NS) | B23: MATEMÁTICA FINANCIERA | C23: 3 | D23: 5 | E23: 60 | F23: 2 | H23: =+D23*F23 -> 10
A24: MERCADOTECNIA O MARKETING (2024NS) | B24: POLÍTICA Y FIJACIÓN DE PRECIOS | C24: 3 | D24: 5 | E24: 60 | F24: 2 | H24: =+D24*F24 -> 10 | I24: =SUM(D20:D24) -> 23
A25: MERCADOTECNIA O MARKETING (2024NS) | B25: INVESTIGACIÓN DE MERCADOS | C25: 4 | D25: 5 | E25: 50 | F25: 2 | G25: 2 | H25: =+D25*F25 -> 10
A26: MERCADOTECNIA O MARKETING (2024NS) | B26: BUSINESS ENGLISH | C26: 4 | D26: 4 | E26: 50 | F26: 2 | H26: =+D26*F26 -> 8
A27: MERCADOTECNIA O MARKETING (2024NS) | B27: MERCHANDISING AND WINDOW DRESSING | C27: 4 | D27: 4 | E27: 50 | F27: 2 | H27: =+D27*F27 -> 8
A28: MERCADOTECNIA O MARKETING (2024NS) | B28: GESTIÓN FINANCIERA | C28: 4 | D28: 5 | E28: 50 | F28: 2 | H28: =+D28*F28 -> 10
A29: MERCADOTECNIA O MARKETING (2024NS) | B29: TÉCNICAS DE VENTAS | C29: 4 | D29: 5 | E29: 50 | F29: 2 | H29: =+D29*F29 -> 10 | I29: =SUM(D25:D29) -> 23
A30: MERCADOTECNIA O MARKETING (2024NS) | B30: INTELIGENCIA DE MERCADOS | C30: 5 | D30: 5 | E30: 63 | F30: 2 | G30: 2 | H30: =+D30*F30 -> 10
A31: MERCADOTECNIA O MARKETING (2024NS) | B31: DESIGN OF PRODUCTS AND PACKAGING | C31: 5 | D31: 5 | E31: 63 | F31: 2 | H31: =+D31*F31 -> 10
A32: MERCADOTECNIA O MARKETING (2024NS) | B32: MARKETING ESTRATÉGICO Y OPERATIVO | C32: 5 | D32: 5 | E32: 63 | F32: 2 | H32: =+D32*F32 -> 10
A33: MERCADOTECNIA O MARKETING (2024NS) | B33: SUPPLY CHAIN MANAGEMENT | C33: 5 | D33: 4 | E33: 63 | F33: 2 | H33: =+D33*F33 -> 8
A34: MERCADOTECNIA O MARKETING (2024NS) | B34: PSYCHOLOGY AND CONSUMER BEHAVIOR | C34: 5 | D34: 4 | E34: 63 | F34: 2 | H34: =+D34*F34 -> 8 | I34: =SUM(D30:D34) -> 23
A35: MERCADOTECNIA O MARKETING (2024NS) | B35: NEUROMARKETING | C35: 6 | D35: 5 | E35: 62 | F35: 2 | G35: 2 | H35: =+D35*F35 -> 10
A36: MERCADOTECNIA O MARKETING (2024NS) | B36: BRAND MANAGEMENT | C36: 6 | D36: 5 | E36: 62 | F36: 2 | H36: =+D36*F36 -> 10
A37: MERCADOTECNIA O MARKETING (2024NS) | B37: TOURISM MARKETING AND SERVICES | C37: 6 | D37: 5 | E37: 62 | F37: 2 | H37: =+D37*F37 -> 10
A38: MERCADOTECNIA O MARKETING (2024NS) | B38: LOGÍSTICA DE PUERTOS | C38: 6 | D38: 4 | E38: 62 | F38: 2 | H38: =+D38*F38 -> 8
A39: MERCADOTECNIA O MARKETING (2024NS) | B39: ÉTICA Y RESPONSABILIDAD SOCIAL EMPRESARIAL | C39: 6 | D39: 4 | E39: 62 | F39: 2 | H39: =+D39*F39 -> 8 | I39: =SUM(D35:D39) -> 23
A40: MERCADOTECNIA O MARKETING (2024NS) | B40: TRADE MARKETING | C40: 7 | D40: 5 | E40: 61 | F40: 2 | G40: 2 | H40: =+D40*F40 -> 10
A41: MERCADOTECNIA O MARKETING (2024NS) | B41: DIGITAL MARKETING | C41: 7 | D41: 5 | E41: 61 | F41: 2 | H41: =+D41*F41 -> 10
A42: MERCADOTECNIA O MARKETING (2024NS) | B42: COMERCIO EXTERIOR | C42: 7 | D42: 5 | E42: 61 | F42: 2 | H42: =+D42*F42 -> 10
A43: MERCADOTECNIA O MARKETING (2024NS) | B43: DERECHO EMPRESARIAL | C43: 7 | D43: 5 | E43: 61 | F43: 2 | H43: =+D43*F43 -> 10 | I43: =SUM(D40:D43) -> 20
...

Sheet DOCENTES 2026-2
A1: CARRERA DE MERCADOTECNIA
A2: DOCENTES 2026-2
A3: No. | B3: APELLIDOS Y NOMBRES | C3: CÉDULA DE IDENTIDAD | D3: TIPO | E3: TIEMPO DEDICACIÓN | F3: CARRERA DE ORIGEN | G3: TERCER NIVEL | H3: ÁREA O CAMPO DE CONOCIMIENTO | I3: CUARTO NIVEL 1 | J3: ÁREA O CAMPO DE CONOCIMIENTO | K3: CUARTO NIVEL 2 | L3: ÁREA O CAMPO DE CONOCIMIENTO | M3: COMISIÓN | N3: HORAS CLASES | P3: NOTAS
A4: 1 | B4: ARIAS ARIAS ANA ELENA | C4: 1306260959 | D4: TITULAR | E4: TC | F4: MARKETING | G4: LICENCIADA EN SECRETARIADO EJECUTIVO LICENCIADO EN CIENCIAS DE LA COMUNICACION ESPECIALIDAD: RELACIONES PUBLICAS TECNICO EN RELACIONES PUBLICAS | H4: CIENCIAS SOCIALES, EDUCACION COMERCIAL Y DERECHO CIENCIAS SOCIALES, EDUCACION COMERCIAL Y DERECHO CIENCIAS SOCIALES, EDUCACION COMERCIAL Y DERECHO | I4: MAGISTER EN MARKETING ESPECIALISTA EN GERENCIA ESTRATEGICA DE LA COMUNICACION ORGANIZACIONAL ESPECIALISTA EN DISEÑO CURRICULAR POR COMPETENCIAS | J4: CIENCIAS SOCIALES, EDUCACION COMERCIAL Y DERECHO CIENCIAS SOCIALES, EDUCACION COMERCIAL Y DERECHO NO DEFINIDA | N4: =+GETPIVOTDATA("HORAS",'REPARTO HORAS'!$A$1,"APELLIDOS Y NOMBRES","ARIAS ARIAS ANA ELENA") -> 18
A5: 2 | B5: BADUY MOLINA AAROM LEONEL | C5: 1310640097 | D5: TITULAR | E5: TC | F5: MARKETING | G5: INGENIERO EN MARKETING | H5: CIENCIAS SOCIALES, EDUCACION COMERCIAL Y DERECHO | I5: MAGISTER EN MARKETING. | J5: CIENCIAS SOCIALES, EDUCACION COMERCIAL Y DERECHO | N5: =+GETPIVOTDATA("HORAS",'REPARTO HORAS'!$A$1,"APELLIDOS Y NOMBRES","BADUY MOLINA AAROM LEONEL") -> 16
A6: 3 | B6: CARREÑO VILLAVICENCIO DIANEXY VIVIANA | C6: 1309746871 | D6: TITULAR | E6: TC | F6: MARKETING | G6: INGENIERA EN MARKETING LICENCIADA EN SECRETARIADO EJECUTIVO SECRETARIA EJECUTIVA | H6: CIENCIAS SOCIALES, EDUCACION COMERCIAL Y DERECHO CIENCIAS SOCIALES, EDUCACION COMERCIAL Y DERECHO CIENCIAS SOCIALES, EDUCACION COMERCIAL Y DERECHO | I6: MAGISTER EN DIRECCIÓN ESTRATÉGICA DE MARKETING Y VENTAS. | J6: NO DEFINIDA | K6: DOCTORA EN CIENCIAS ADMINISTRATIVAS. | L6: NO DEFINIDA | N6: =+GETPIVOTDATA("HORAS",'REPARTO HORAS'!$A$1,"APELLIDOS Y NOMBRES","CARREÑO VILLAVICENCIO DIANEXY VIVIANA") -> 18
A7: 1 | B7: COVEÑA MENÉNDEZ JONATHAN KLEBER | C7: 1309715850 | D7: TITULAR | E7: TC | F7: GESTIÓN DE LA INFORMACIÓN GERENCIAL | G7: LICENCIADO EN CIENCIAS DE LA EDUCACION MENCION INGLES | H7: EDUCACION | I7: MAGISTER EN ENSEÑANZA DEL IDIOMA INGLES | J7: EDUCACION | N7: =+GETPIVOTDATA("HORAS",'REPARTO HORAS'!$A$1,"APELLIDOS Y NOMBRES","COVEÑA MENÉNDEZ JONATHAN KLEBER") -> 4
A8: 4 | B8: CRUZ MERA RAFER HENRY | C8: 922028709 | D8: TITULAR | E8: TC | F8: ADMINISTRACIÓN DE EMPRESAS | G8: INGENIERO COMERCIAL | H8: CIENCIAS SOCIALES, EDUCACION COMERCIAL Y DERECHO | I8: MAGISTER EN GERENCIA EDUCATIVA | J8: CIENCIAS SOCIALES, EDUCACION COMERCIAL Y DERECHO | K8: DOCTOR EN CIENCIAS ADMINISTRATIVAS | L8: ADMINISTRACION DE EMPRESAS Y DERECHO | N8: =+GETPIVOTDATA("HORAS",'REPARTO HORAS'!$A$1,"APELLIDOS Y NOMBRES","CRUZ MERA RAFER HENRY") -> 5
A9: 5 | B9: GRANDA GARCÍA MARCO IVÁN | C9: 910619543 | D9: TITULAR | E9: TC | F9: MARKETING | G9: INGENIERO EN CIENCIAS EMPRESARIALES CON ESPECIALIZACION EN GESTION EMPRESARIAL TECNICO SUPERIOR ESPECIALIZACION GESTION EMPRESARIAL | H9: CIENCIAS SOCIALES, EDUCACION COMERCIAL Y DERECHO CIENCIAS SOCIALES, EDUCACION COMERCIAL Y DERECHO | I9: MASTER UNIVERSITARIO EN INFORMACION DIGITAL, ESPECIALIDAD EN BUSCADORES: MARKETING ONLINE (SEM) Y POSICIONAMIENTO WEB (SEO). DIPLOMA SUPERIOR EN EDUCACION UNIVERSITARIA POR COMPETENCIAS | J9: NO DEFINIDA EDUCACION | M9: MIEMBRO REVISTA CIENTÍFICA | N9: =+GETPIVOTDATA("HORAS",'REPARTO HORAS'!$A$1,"APELLIDOS Y NOMBRES","GRANDA GARCÍA MARCO IVÁN") -> 20 | P9: HORARIOS HASTA MÁXIMO LAS 19H00
A10: 6 | B10: HEREDIA COPPIANO GENESIS ESTEFANÍA | C10: 1312925033 | D10: CONTRATO | E10: MT | F10: ADMINISTRACIÓN DE EMPRESAS | G10: ECONOMISTA MENCION EN GESTION PUBLICA | H10: CIENCIAS SOCIALES, EDUCACION COMERCIAL Y DERECHO | I10: MASTER UNIVERSITARIO EN FINANZAS, BANCA Y SEGUROS | J10: NO DEFINIDA | N10: =+GETPIVOTDATA("HORAS",'REPARTO HORAS'!$A$1,"APELLIDOS Y NOMBRES","HEREDIA COPPIANO GENESIS ESTEFANÍA") -> 4
A11: 7 | B11: HORMAZA VILLAFUERTE SANDY LISBETH | C11: 1311369464 | D11: TITULAR | E11: TC | F11: MARKETING | G11: GRADUADA EN TURISMO | H11: NO DEFINIDA | I11: MAGISTER EN CIENCIAS SOCIALES CON MENCIÓN EN INVESTIGACION PARA EL DESARROLLO SOCIAL MASTER UNIVERSITARIO EN MARKETING Y COMUNICACION . | J11: CIENCIAS SOCIALES, PERIODISMO, INFORMACION Y DERECHO NO DEFINIDA | N11: =+GETPIVOTDATA("HORAS",'REPARTO HORAS'!$A$1,"APELLIDOS Y NOMBRES","HORMAZA VILLAFUERTE SANDY LISBETH") -> 20
A12: 8 | B12: JACOME SANTOS XAVIER IVAN | C12: 1306763218 | D12: TITULAR | E12: TC | F12: MARKETING | G12: INGENIERO EN MARKETING LICENCIADO EN MERCADOTECNIA | H12: HUMANIDADES Y ARTES CIENCIAS SOCIALES, EDUCACION COMERCIAL Y DERECHO | I12: MAGISTER EN DIRECCION ESTRATEGICA DE MARKETING Y VENTAS. | J12: NO DEFINIDA | M12: LÍDER PROYECTO VINCULACIÓN | N12: =+GETPIVOTDATA("HORAS",'REPARTO HORAS'!$A$1,"APELLIDOS Y NOMBRES","JACOME SANTOS XAVIER IVAN") -> 15
A13: 9 | B13: LOOR CHAVEZ TEMISTOCLES DEODATO | C13: 1302940091 | D13: TITULAR | E13: TC | F13: MARKETING | G13: INGENIERO COMERCIAL | H13: CIENCIAS SOCIALES, EDUCACION COMERCIAL Y DERECHO | I13: MAGISTER EN DIRECCIÓN UNIVERSITARIA. DIPLOMA SUPERIOR EN EDUCACION UNIVERSITARIA POR COMPETENCIAS DIPLOMADO SUPERIOR EN EVALUACION INSTITUCIONAL UNIVERSITARIA | J13: EDUCACIÓN EDUCACIÓN EDUCACIÓN | K13: DOCTOR EN CIENCIAS AMINISTRATIVAS. | L13: NO DEFINIDA | M13: LIDER DE PROYECTO DE INVESTIGACIÓN. | N13: =+GETPIVOTDATA("HORAS",'REPARTO HORAS'!$A$1,"APELLIDOS Y NOMBRES","LOOR CHAVEZ TEMISTOCLES DEODATO") -> 14 | P13: HORARIOS HASTA MÁXIMO LAS 19H00
A14: 10 | B14: LOOR MOREIRA ALEXANDRA JACQUELINE | C14: 1311498222 | D14: TITULAR | E14: TC | F14: MARKETING | G14: INGENIERA EN MARKETING | H14: CIENCIAS SOCIALES, EDUCACION COMERCIAL Y DERECHO | I14: MAGISTER EN MARKETING. | J14: CIENCIAS SOCIALES, EDUCACION COMERCIAL Y DERECHO | M14: COMISIÓN ACADÉMICA | N14: =+GETPIVOTDATA("HORAS",'REPARTO HORAS'!$A$1,"APELLIDOS Y NOMBRES","LOOR MOREIRA ALEXANDRA JACQUELINE") -> 20
A15: 11 | B15: LOPEZ LEONES CRISTHIAN JOSÉ | C15: 1310419138 | D15: TITULAR | E15: TC | F15: MARKETING | G15: INGENIERO EN ADMINISTRACION DE EMPRESAS Y MARKETING SERVICIO NACIONAL DE CONTRATACION PUBLICA | H15: CIENCIAS SOCIALES, EDUCACION COMERCIAL Y DERECHO | I15: MAGÍSTER EN ADMINISTRACIÓN PÚBLICA MENCIÓN DESARROLLO INSTITUCIONAL. | J15: CIENCIAS SOCIALES, EDUCACION COMERCIAL Y DERECHO | N15: =+GETPIVOTDATA("HORAS",'REPARTO HORAS'!$A$1,"APELLIDOS Y NOMBRES","LOPEZ LEONES CRISTHIAN JOSÉ") -> 18
A16: 12 | B16: MEJIA VÁSQUEZ PERICLES RAMÓN | C16: 602990723 | D16: TITULAR | E16: TC | F16: MARKETING | G16: LICENCIADO EN PUBLICIDAD | H16: HUMANIDADES Y ARTES | I16: MAGISTER EN ADMINISTRACION DE EMPRESAS, MENCION MARKETING. MASTER UNIVERSITARIO EN INVESTIGACION EN ADMINISTRACION Y ECONOMIA DE LA EMPRESA | J16: NO DEFINIDA NO DEFINIDA | N16: =+GETPIVOTDATA("HORAS",'REPARTO HORAS'!$A$1,"APELLIDOS Y NOMBRES","MEJIA VÁSQUEZ PERICLES RAMÓN") -> 20
A17: 13 | B17: MERO CHAVEZ ULISES FEDERICO | C17: 1312875279 | D17: TITULAR | E17: TC | F17: MARKETING | G17: INGENIERO COMERCIAL | H17: CIENCIAS SOCIALES, EDUCACION COMERCIAL Y DERECHO | I17: MASTER UNIVERSITARIO EN DIRECCIÓN Y GESTIÓN DE RECURSOS HUMANOS. | J17: NO DEFINIDA | N17: =+GETPIVOTDATA("HORAS",'REPARTO HORAS'!$A$1,"APELLIDOS Y NOMBRES","MERO CHAVEZ ULISES FEDERICO") -> 8
A18: 14 | B18: MOLINA CEDEÑO JIMMY WILMER | C18: 1308524568 | D18: TITULAR | E18: TC | F18: MARKETING | G18: ANALISTA DE SISTEMAS | H18: CIENCIAS | I18: MAGISTER EN FINANZAS Y COMERCIO INTERNACIONAL. | J18: CIENCIAS SOCIALES, EDUCACION COMERCIAL Y DERECHO | N18: =+GETPIVOTDATA("HORAS",'REPARTO HORAS'!$A$1,"APELLIDOS Y NOMBRES","MOLINA CEDEÑO JIMMY WILMER") -> 10
A19: 15 | B19: MOLINA QUIROZ CLAUDIA ANALIA | C19: 1309662706 | D19: TITULAR | E19: TC | F19: MARKETING | G19: ECONOMISTA | H19: CIENCIAS SOCIALES, EDUCACION COMERCIAL Y DERECHO | I19: MAGISTER EN ADMINISTRACIÓN PÚBLICA MENCIÓN DESARROLLO INSTITUCIONAL. | J19: CIENCIAS SOCIALES, EDUCACION COMERCIAL Y DERECHO | K19: DOCTORA EN CIENCIAS ECONOMICAS. | L19: NO DEFINIDA | M19: EDITORA DE REVISTA - MIEMBRO OCS | N19: =+GETPIVOTDATA("HORAS",'REPARTO HORAS'!$A$1,"APELLIDOS Y NOMBRES","MOLINA QUIROZ CLAUDIA ANALIA") -> 16 | P19: HORARIOS EN LA MAÑANA Y TARDE
A20: 16 | B20: MORÁN QUIÑONEZ CARLOS JULIO | C20: 1708333115 | D20: TITULAR | E20: TC | F20: MARKETING | G20: INGENIERO EN SISTEMAS ANALISTA DE SISTEMAS TECNOLOGO EN COMPUTACION ADMINISTRATIVA | H20: CIENCIAS CIENCIAS CIENCIAS | I20: MAGISTER EN GERENCIA TURÍSTICA Y HOTELERA. | J20: CIENCIAS SOCIALES, EDUCACION COMERCIAL Y DERECHO | N20: =+GETPIVOTDATA("HORAS",'REPARTO HORAS'!$A$1,"APELLIDOS Y NOMBRES","MORÁN QUIÑONEZ CARLOS JULIO") -> 18 | P20: HORARIOS HASTA MÁXIMO LAS 19H00
A21: 17 | B21: PALACIOS BRIONES NURI LUPITA | C21: 1307822377 | D21: TITULAR | E21: TC | F21: MARKETING | G21: INGENIERA EN SISTEMAS ANALISTA DE SISTEMAS | H21: CIENCIAS CIENCIAS | I21: MAGISTER SCIENTIAE EN PEDAGOGÍA CRÍTICA. ESPECIALISTA EN DISEÑO CURRICULAR POR COMPETENCIAS | J21: EDUCACION NO DEFINIDA | N21: =+GETPIVOTDATA("HORAS",'REPARTO HORAS'!$A$1,"APELLIDOS Y NOMBRES","PALACIOS BRIONES NURI LUPITA") -> 11
A22: 18 | B22: PINARGOTE MONTENEGRO KAREN GISELA | C22: 1308645660 | D22: TITULAR | E22: TC | F22: MARKETING | G22: INGENIERA COMERCIAL | H22: CIENCIAS SOCIALES, EDUCACION COMERCIAL Y DERECHO | I22: MAGISTER EN ADMINISTRACION DE EMPRESAS (MBA) PROGRAMA INTEGRAL DE HABILIDADES MULTIPLES. DIPLOMA SUPERIOR EN TRIBUTACION | J22: CIENCIAS SOCIALES, EDUCACION COMERCIAL Y DERECHO CIENCIAS SOCIALES, EDUCACION COMERCIAL Y DERECHO | K22: DOCTORA DENTRO DEL PROGRAMA DE DOCTORADO EN ECONOMIA Y EMPRESA | L22: CIENCIAS SOCIALES Y JURIDICAS | N22: =+GETPIVOTDATA("HORAS",'REPARTO HORAS'!$A$1,"APELLIDOS Y NOMBRES","PINARGOTE MONTENEGRO KAREN GISELA") -> 15 | P22: DE 14H00 A 15H00 NO CONSIDERAR CLASES PARA PODER RETIRAR A HIJO DEL COLEGIO
A23: 19 | B23: PONCE ANDRADE JOHNNY EDISON | C23: 1305701243 | D23: TITULAR | E23: TC | F23: MARKETING | G23: INGENIERO COMERCIAL | H23: CIENCIAS SOCIALES, EDUCACION COMERCIAL Y DERECHO | I23: MAGISTER EN DIRECCION ESTRATEGICA DE MARKETING Y VENTAS MAGISTER EN DIRECCION ESTRATEGICA DE MARKETING Y VENTAS. ESPECIALISTA EN GERENCIA ESTRATEGICA DE LA COMUNICACION ORGANIZACIONAL | J23: NO DEFINIDA EDUCACION CIENCIAS SOCIALES, EDUCACION COMERCIAL Y DERECHO | K23: DOCTOR EN CIENCIAS ADMINISTRATIVAS | L23: NO DEFINIDA | N23: =+GETPIVOTDATA("HORAS",'REPARTO HORAS'!$A$1,"APELLIDOS Y NOMBRES","PONCE ANDRADE JOHNNY EDISON") -> 15
A24: 20 | B24: RODRIGUEZ SÁNCHEZ JOHNNY GUSTAVO | C24: 1312606476 | D24: TITULAR | E24: TC | F24: GESTIÓN DE LA INFORMACIÓN GERENCIAL | G24: INGENIERO COMERCIAL | H24: CIENCIAS SOCIALES, EDUCACION COMERCIAL Y DERECHO | I24: MAGISTER EN GESTIÓN EMPRESARIAL | J24: CIENCIAS SOCIALES, EDUCACION COMERCIAL Y DERECHO | N24: =+GETPIVOTDATA("HORAS",'REPARTO HORAS'!$A$1,"APELLIDOS Y NOMBRES","RODRIGUEZ SÁNCHEZ JOHNNY GUSTAVO") -> 4
A25: 21 | B25: SÁNCHEZ ARTEAGA ALEX ALFONSO | C25: 1307804532 | D25: TITULAR | E25: TC | F25: COMERCIO EXTERIOR | G25: ABOGADO DE LOS JUZGADOS Y TRIBUNALES DE LA REPUBLICA LICENCIADO EN CIENCIAS SOCIALES Y POLITICAS | H25: CIENCIAS SOCIALES, EDUCACION COMERCIAL Y DERECHO CIENCIAS SOCIALES, EDUCACION COMERCIAL Y DERECHO | I25: MAGISTER EN DERECHO DE EMPRESA | J25: ADMINISTRACIÓN DE EMPRESAS Y DERECHO | N25: =+GETPIVOTDATA("HORAS",'REPARTO HORAS'!$A$1,"APELLIDOS Y NOMBRES","SÁNCHEZ ARTEAGA ALEX ALFONSO") -> 10
A26: 22 | B26: SOLIS BRAVO HUGO ALFONSO | C26: 1311667495 | D26: CONTRATO | E26: TC | F26: MARKETING | G26: INGENIERO COMERCIAL | H26: CIENCIAS SOCIALES, EDUCACION COMERCIAL Y DERECHO | I26: MAGISTER EN DIRECCION DE EMPRESAS MENCIÓN EN GESTION DE EMPRESAS DE SERVICIOS. | J26: ADMINISTRACION | N26: =+GETPIVOTDATA("HORAS",'REPARTO HORAS'!$A$1,"APELLIDOS Y NOMBRES","SOLIS BRAVO HUGO ALFONSO") -> 21
A27: 23 | B27: VERA DELGADO BRYAN ADRIÁN | C27: 1312319641 | D27: CONTRATO | E27: TC | F27: CONTABILIDAD Y AUDITORÍA | G27: INGENIERO EN CONTABILIDAD Y AUDITORIA | H27: CIENCIAS SOCIALES, EDUCACION COMERCIAL Y DERECHO | I27: MAGISTER EN CONTABILIDAD Y FINANZAS MENCIÓN GESTION FISCAL, FINANCIERA Y TRIBUTARIA | J27: ADMINISTRACION | N27: =+GETPIVOTDATA("HORAS",'REPARTO HORAS'!$A$1,"APELLIDOS Y NOMBRES","VERA DELGADO BRYAN ADRIÁN") -> 8
A28: 24 | B28: VILLAMARIN VILLOTA WALTER HUMBERTO | C28: 1309029815 | D28: TITULAR | E28: TC | F28: MARKETING | G28: ECONOMISTA AGRICOLA | H28: AGRICULTURA | I28: MAGISTER EN FINANZAS Y COMERCIO INTERNACIONAL. | J28: CIENCIAS SOCIALES, EDUCACION COMERCIAL Y DERECHO | N28: =+GETPIVOTDATA("HORAS",'REPARTO HORAS'!$A$1,"APELLIDOS Y NOMBRES","VILLAMARIN VILLOTA WALTER HUMBERTO") -> 10
A29: 25 | B29: VILLAFUERTE MUÑOZ WAGNER OSWALDO | C29: 909466674 | D29: TITULAR | E29: TC | F29: MARKETING | G29: LICENCIADO EN CIENCIAS DE LA EDUCACION MENCION EN INGLES | H29: EDUCACION | I29: MAGISTER EN ENSEÑANZA DEL IDIOMA INGLES DIPLOMA SUPERIOR EN GESTION DIRECTIVA | J29: EDUCACION CIENCIAS SOCIALES, EDUCACION COMERCIAL Y DERECHO | K29: DIPLOMA SUPERIOR EN GESTION DIRECTIVA | M29: COORDINADOR SEGURIDAD INSTITUCIONAL | N29: =+GETPIVOTDATA("HORAS",'REPARTO HORAS'!$A$1,"APELLIDOS Y NOMBRES","VILLAFUERTE MUÑOZ WAGNER OSWALDO") -> 4 | P29: NO COLOCAR CLASES LOS VIERNES YA QUE VIAJA A EXTENSIONES
A30: 26 | B30: ZAMBRANO PEÑARRIETA JOSSELYN JAMILETH | C30: 1350123640 | D30: TITULAR | E30: TC | F30: MARKETING | G30: INGENIERA EN MARKETING | H30: EDUCACION | I30: MAGISTER EN MERCADOTECNIA MENCIÓN EN ESTRATEGIA DIGITAL. | J30: ADMINISTRACIÓN | M30: COMISIÓN ACADÉMICA | N30: =+GETPIVOTDATA("HORAS",'REPARTO HORAS'!$A$1,"APELLIDOS Y NOMBRES","ZAMBRANO PEÑARRIETA JOSSELYN JAMILETH") -> 13
N31: =SUM(N4:N30) -> 355
N32: Horas Docentes
A36: 1 | B36: GUEVARA CAÑIZARES MARISSA ALEJANDRA | D36: CONTRATO | E36: TC | F36: ADMINISTRACIÓN DE EMPRESAS | G36: BACHELOR OF SCIENCE IN ENVIRONMENTAL SCIENCE | H36: NO DEFINIDA | I36: MASTER OF SCIENCE IN POLLUTION AND ENVIRONMENTAL CONTROL | J36: NO DEFINIDA
A37: 2 | B37: VIDAL FERNANDEZ PABLO | C37: 1315680429 | D37: TITULAR | E37: TC | F37: GESTIÓN DE LA INFORMACIÓN GERENCIAL | G37: DIPLOMADO EN CIENCIAS EMPRESARIALES | H37: NO DEFINIDA | I37: MASTER UNIVERSITARIO EN NUEVAS TENDENCIAS Y PROCESOS DE INNOVACION EN COMUNICACIÓN MASTER UNIVERSITARIO EN INFORMACION DIGITAL EN LA ESPECIALIDAD DE BUSCADORES: MARKETING ONLINE (SEM) Y POSICIONAMIENTO WEB (SEO) | J37: NO DEFINIDA NO DEFINIDA | K37: DOCTOR DENTRO DEL PROGRAMA DE DOCTORADO EN CIENCIAS DE LA COMUNICACIÓN

Sheet ASIG 2026-1
A3: NIVEL | B3: ASIGNATURA | C3: APELLIDOS Y NOMBRES | D3: HORAS | E3: COMISIÓN | F3: CARRERA | G3: DEDIC | H3: HORAS2 | J3: NOTAS
A4: 1A | B4: TECNOLOGÍA Y TENDENCIA DE LA CULTURA DIGITAL | C4: SOLIS BRAVO HUGO ALFONSO | D4: =(32+16)/16 -> 3 | F4: MALLA 2024NS | G4: TC | H4: =SUMIF(Tabla14[APELLIDOS Y NOMBRES],Tabla14[[#This Row],[APELLIDOS Y NOMBRES]],Tabla14[HORAS]) -> 21
A5: 1A | B5: MATEMÁTICA APLICADA A LOS NEGOCIOS | C5: RODRIGUEZ SÁNCHEZ JOHNNY GUSTAVO | D5: =(48+16)/16 -> 4 | F5: MALLA 2024NS | G5: TC | H5: =SUMIF(Tabla14[APELLIDOS Y NOMBRES],Tabla14[[#This Row],[APELLIDOS Y NOMBRES]],Tabla14[HORAS]) -> 4
A6: 1A | B6: GESTIÓN ADMINISTRATIVA | C6: ARIAS ARIAS ANA ELENA | D6: =(32+16)/16 -> 3 | F6: MALLA 2024NS | G6: TC | H6: =SUMIF(Tabla14[APELLIDOS Y NOMBRES],Tabla14[[#This Row],[APELLIDOS Y NOMBRES]],Tabla14[HORAS]) -> 18
A7: 1A | B7: FUNDAMENTOS DE LA MERCADOTECNIA | C7: LOOR MOREIRA ALEXANDRA JACQUELINE | D7: 4 | F7: MALLA 2024NS | G7: TC | H7: =SUMIF(Tabla14[APELLIDOS Y NOMBRES],Tabla14[[#This Row],[APELLIDOS Y NOMBRES]],Tabla14[HORAS]) -> 20
A8: 1A | B8: CONTEXTO SOCIO ECONÓMICO, CULTURAL E INTERCULTURALIDAD | C8: PALACIOS BRIONES NURI LUPITA | D8: =(32+16)/16 -> 3 | F8: MALLA 2024NS | G8: TC | H8: =SUMIF(Tabla14[APELLIDOS Y NOMBRES],Tabla14[[#This Row],[APELLIDOS Y NOMBRES]],Tabla14[HORAS]) -> 11
A9: 1A | B9: CONTABILIDAD ADMINISTRATIVA | C9: VERA DELGADO BRYAN ADRIÁN | D9: =(32+32)/16 -> 4 | F9: MALLA 2024NS | G9: TC | H9: =SUMIF(Tabla14[APELLIDOS Y NOMBRES],Tabla14[[#This Row],[APELLIDOS Y NOMBRES]],Tabla14[HORAS]) -> 8
A10: 2A | B10: METODOLOGÍA DE LA INVESTIGACIÓN | C10: LOOR CHAVEZ TEMISTOCLES DEODATO | D10: 4 | F10: MALLA 2024NS | G10: TC | H10: =SUMIF(Tabla14[APELLIDOS Y NOMBRES],Tabla14[[#This Row],[APELLIDOS Y NOMBRES]],Tabla14[HORAS]) -> 14
A11: 2A | B11: MACRO Y MICRO ECONOMÍA | C11: HEREDIA COPPIANO GENESIS ESTEFANÍA | D11: 4 | F11: MALLA 2024NS | G11: TC | H11: =SUMIF(Tabla14[APELLIDOS Y NOMBRES],Tabla14[[#This Row],[APELLIDOS Y NOMBRES]],Tabla14[HORAS]) -> 4
A12: 2A | B12: DISEÑO Y COMPOSICIÓN GRÁFICA | C12: ZAMBRANO PEÑARRIETA JOSSELYN JAMILETH | D12: =(32+16)/16 -> 3 | F12: MALLA 2024NS | G12: TC | H12: =SUMIF(Tabla14[APELLIDOS Y NOMBRES],Tabla14[[#This Row],[APELLIDOS Y NOMBRES]],Tabla14[HORAS]) -> 13
A13: 2A | B13: COMUNICACIÓN INTEGRAL DE LA MERCADOTECNIA | C13: ARIAS ARIAS ANA ELENA | D13: 4 | F13: MALLA 2024NS | G13: TC | H13: =SUMIF(Tabla14[APELLIDOS Y NOMBRES],Tabla14[[#This Row],[APELLIDOS Y NOMBRES]],Tabla14[HORAS]) -> 18
A14: 2A | B14: CÁLCULO PARA LA GESTIÓN EMPRESARIAL | C14: CRUZ MERA RAFER HENRY | D14: 5 | F14: MALLA 2024NS | G14: TC | H14: =SUMIF(Tabla14[APELLIDOS Y NOMBRES],Tabla14[[#This Row],[APELLIDOS Y NOMBRES]],Tabla14[HORAS]) -> 5
A15: 2A | B15: ANÁLISIS DE COSTOS | C15: VERA DELGADO BRYAN ADRIÁN | D15: =(48+16)/16 -> 4 | F15: MALLA 2024NS | G15: TC | H15: =SUMIF(Tabla14[APELLIDOS Y NOMBRES],Tabla14[[#This Row],[APELLIDOS Y NOMBRES]],Tabla14[HORAS]) -> 8
A16: 3A | B16: REDACCIÓN PUBLICITARIA | C16: MEJIA VÁSQUEZ PERICLES RAMÓN | D16: 5 | F16: MALLA 2024NS | G16: TC | H16: =SUMIF(Tabla14[APELLIDOS Y NOMBRES],Tabla14[[#This Row],[APELLIDOS Y NOMBRES]],Tabla14[HORAS]) -> 20
A17: 3A | B17: POLÍTICA Y FIJACIÓN DE PRECIOS | C17: LOOR MOREIRA ALEXANDRA JACQUELINE | D17: 5 | F17: MALLA 2024NS | G17: TC | H17: =SUMIF(Tabla14[APELLIDOS Y NOMBRES],Tabla14[[#This Row],[APELLIDOS Y NOMBRES]],Tabla14[HORAS]) -> 20
A18: 3A | B18: MATEMÁTICAS FINANCIERA | C18: MOLINA CEDEÑO JIMMY WILMER | D18: 5 | F18: MALLA 2024NS | G18: TC | H18: =SUMIF(Tabla14[APELLIDOS Y NOMBRES],Tabla14[[#This Row],[APELLIDOS Y NOMBRES]],Tabla14[HORAS]) -> 10
A19: 3A | B19: GESTIÓN DEL TALENTO HUMANO | C19: MERO CHAVEZ ULISES FEDERICO | D19: =(48+16)/16 -> 4 | F19: MALLA 2024NS | G19: TC | H19: =SUMIF(Tabla14[APELLIDOS Y NOMBRES],Tabla14[[#This Row],[APELLIDOS Y NOMBRES]],Tabla14[HORAS]) -> 8
A20: 3A | B20: ESTADISTICA | C20: PALACIOS BRIONES NURI LUPITA | D20: 4 | F20: MALLA 2024NS | G20: TC | H20: =SUMIF(Tabla14[APELLIDOS Y NOMBRES],Tabla14[[#This Row],[APELLIDOS Y NOMBRES]],Tabla14[HORAS]) -> 11
A21: 3B | B21: REDACCIÓN PUBLICITARIA | C21: MEJIA VÁSQUEZ PERICLES RAMÓN | D21: 5 | F21: MALLA 2024NS | G21: TC | H21: =SUMIF(Tabla14[APELLIDOS Y NOMBRES],Tabla14[[#This Row],[APELLIDOS Y NOMBRES]],Tabla14[HORAS]) -> 20
A22: 3B | B22: POLÍTICA Y FIJACIÓN DE PRECIOS | C22: LOOR MOREIRA ALEXANDRA JACQUELINE | D22: 5 | F22: MALLA 2024NS | G22: TC | H22: =SUMIF(Tabla14[APELLIDOS Y NOMBRES],Tabla14[[#This Row],[APELLIDOS Y NOMBRES]],Tabla14[HORAS]) -> 20
A23: 3B | B23: MATEMÁTICAS FINANCIERA | C23: MOLINA CEDEÑO JIMMY WILMER | D23: 5 | F23: MALLA 2024NS | G23: TC | H23: =SUMIF(Tabla14[APELLIDOS Y NOMBRES],Tabla14[[#This Row],[APELLIDOS Y NOMBRES]],Tabla14[HORAS]) -> 10
A24: 3B | B24: GESTIÓN DEL TALENTO HUMANO | C24: MERO CHAVEZ ULISES FEDERICO | D24: =(48+16)/16 -> 4 | F24: MALLA 2024NS | G24: TC | H24: =SUMIF(Tabla14[APELLIDOS Y NOMBRES],Tabla14[[#This Row],[APELLIDOS Y NOMBRES]],Tabla14[HORAS]) -> 8
A25: 3B | B25: ESTADISTICA | C25: PALACIOS BRIONES NURI LUPITA | D25: 4 | F25: MALLA 2024NS | G25: TC | H25: =SUMIF(Tabla14[APELLIDOS Y NOMBRES],Tabla14[[#This Row],[APELLIDOS Y NOMBRES]],Tabla14[HORAS]) -> 11
A26: 4A | B26: TÉCNICAS DE VENTAS | C26: JACOME SANTOS XAVIER IVAN | D26: 5 | F26: MALLA 2024NS | G26: TC | H26: =SUMIF(Tabla14[APELLIDOS Y NOMBRES],Tabla14[[#This Row],[APELLIDOS Y NOMBRES]],Tabla14[HORAS]) -> 15
A27: 4A | B27: MERCHANDISING AND WINDOW DRESSING | C27: MOLINA QUIROZ CLAUDIA ANALIA | D27: =(48+16)/16 -> 4 | F27: MALLA 2024NS | G27: TC | H27: =SUMIF(Tabla14[APELLIDOS Y NOMBRES],Tabla14[[#This Row],[APELLIDOS Y NOMBRES]],Tabla14[HORAS]) -> 16
A28: 4A | B28: INVESTIGACIÓN DE MERCADOS | C28: LOOR CHAVEZ TEMISTOCLES DEODATO | D28: 5 | F28: MALLA 2024NS | G28: TC | H28: =SUMIF(Tabla14[APELLIDOS Y NOMBRES],Tabla14[[#This Row],[APELLIDOS Y NOMBRES]],Tabla14[HORAS]) -> 14
A29: 4A | B29: GESTIÓN FINANCIERA | C29: PINARGOTE MONTENEGRO KAREN GISELA | D29: 5 | F29: MALLA 2024NS | G29: TC | H29: =SUMIF(Tabla14[APELLIDOS Y NOMBRES],Tabla14[[#This Row],[APELLIDOS Y NOMBRES]],Tabla14[HORAS]) -> 15
A30: 4A | B30: BUSINESS ENGLISH | C30: VILLAFUERTE MUÑOZ WAGNER OSWALDO | D30: =(48+16)/16 -> 4 | F30: MALLA 2024NS | G30: TC | H30: =SUMIF(Tabla14[APELLIDOS Y NOMBRES],Tabla14[[#This Row],[APELLIDOS Y NOMBRES]],Tabla14[HORAS]) -> 4
A31: 4B | B31: TÉCNICAS DE VENTAS | C31: ARIAS ARIAS ANA ELENA | D31: 5 | F31: MALLA 2024NS | G31: TC | H31: =SUMIF(Tabla14[APELLIDOS Y NOMBRES],Tabla14[[#This Row],[APELLIDOS Y NOMBRES]],Tabla14[HORAS]) -> 18
A32: 4B | B32: MERCHANDISING AND WINDOW DRESSING | C32: MOLINA QUIROZ CLAUDIA ANALIA | D32: =(48+16)/16 -> 4 | F32: MALLA 2024NS | G32: TC | H32: =SUMIF(Tabla14[APELLIDOS Y NOMBRES],Tabla14[[#This Row],[APELLIDOS Y NOMBRES]],Tabla14[HORAS]) -> 16
A33: 4B | B33: INVESTIGACIÓN DE MERCADOS | C33: LOOR CHAVEZ TEMISTOCLES DEODATO | D33: 5 | F33: MALLA 2024NS | G33: TC | H33: =SUMIF(Tabla14[APELLIDOS Y NOMBRES],Tabla14[[#This Row],[APELLIDOS Y NOMBRES]],Tabla14[HORAS]) -> 14
A34: 4B | B34: GESTIÓN FINANCIERA | C34: PINARGOTE MONTENEGRO KAREN GISELA | D34: 5 | F34: MALLA 2024NS | G34: TC | H34: =SUMIF(Tabla14[APELLIDOS Y NOMBRES],Tabla14[[#This Row],[APELLIDOS Y NOMBRES]],Tabla14[HORAS]) -> 15
A35: 4B | B35: BUSINESS ENGLISH | C35: COVEÑA MENÉNDEZ JONATHAN KLEBER | D35: =(48+16)/16 -> 4 | F35: MALLA 2024NS | G35: TC | H35: =SUMIF(Tabla14[APELLIDOS Y NOMBRES],Tabla14[[#This Row],[APELLIDOS Y NOMBRES]],Tabla14[HORAS]) -> 4
A36: 5A | B36: SUPPLY CHAIN ​​MANAGEMENT | C36: CARREÑO VILLAVICENCIO DIANEXY VIVIANA | D36: 4 | F36: MALLA 2024NS | G36: TC | H36: =SUMIF(Tabla14[APELLIDOS Y NOMBRES],Tabla14[[#This Row],[APELLIDOS Y NOMBRES]],Tabla14[HORAS]) -> 18
A37: 5A | B37: PSYCHOLOGY AND CONSUMER BEHAVIOR | C37: MOLINA QUIROZ CLAUDIA ANALIA | D37: 4 | F37: MALLA 2024NS | G37: TC | H37: =SUMIF(Tabla14[APELLIDOS Y NOMBRES],Tabla14[[#This Row],[APELLIDOS Y NOMBRES]],Tabla14[HORAS]) -> 16
A38: 5A | B38: MARKETING ESTRATÉGICO Y OPERATIVO | C38: ZAMBRANO PEÑARRIETA JOSSELYN JAMILETH | D38: 5 | F38: MALLA 2024NS | G38: TC | H38: =SUMIF(Tabla14[APELLIDOS Y NOMBRES],Tabla14[[#This Row],[APELLIDOS Y NOMBRES]],Tabla14[HORAS]) -> 13
A39: 5A | B39: INTELIGENCIA DE MERCADOS | C39: MORÁN QUIÑONEZ CARLOS JULIO | D39: 5 | F39: MALLA 2024NS | G39: TC | H39: =SUMIF(Tabla14[APELLIDOS Y NOMBRES],Tabla14[[#This Row],[APELLIDOS Y NOMBRES]],Tabla14[HORAS]) -> 18 | J39: INGLES
A40: 5A | B40: DESIGN OF PRODUCTS AND PACKAGING | C40: MEJIA VÁSQUEZ PERICLES RAMÓN | D40: 5 | F40: MALLA 2024NS | G40: TC | H40: =SUMIF(Tabla14[APELLIDOS Y NOMBRES],Tabla14[[#This Row],[APELLIDOS Y NOMBRES]],Tabla14[HORAS]) -> 20
A41: 5B | B41: SUPPLY CHAIN ​​MANAGEMENT | C41: CARREÑO VILLAVICENCIO DIANEXY VIVIANA | D41: 4 | F41: MALLA 2024NS | G41: TC | H41: =SUMIF(Tabla14[APELLIDOS Y NOMBRES],Tabla14[[#This Row],[APELLIDOS Y NOMBRES]],Tabla14[HORAS]) -> 18
A42: 5B | B42: PSYCHOLOGY AND CONSUMER BEHAVIOR | C42: MOLINA QUIROZ CLAUDIA ANALIA | D42: 4 | F42: MALLA 2024NS | G42: TC | H42: =SUMIF(Tabla14[APELLIDOS Y NOMBRES],Tabla14[[#This Row],[APELLIDOS Y NOMBRES]],Tabla14[HORAS]) -> 16
...

Sheet REPARTO HORAS
A1: DOCENTES | B1: H.PRESENCIALES
A2: ARIAS ARIAS ANA ELENA | B2: 18
A3: COMUNICACIÓN INTEGRAL DE LA MERCADOTECNIA | B3: 4
A4: 2A | B4: 4
A5: TÉCNICAS DE VENTAS | B5: 5
A6: 4B | B6: 5
A7: GERENCIA DE MERCADOTECNIA | B7: 6
A8: 9A | B8: 3
A9: 9B | B9: 3
A10: GESTIÓN ADMINISTRATIVA | B10: 3
A11: 1A | B11: 3
A12: BADUY MOLINA AAROM LEONEL | B12: 16
A13: TRADE MARKETING | B13: 8
... A25: 6B | B25: 5
A26: COVEÑA MENÉNDEZ JONATHAN KLEBER | B26: 4 | C26: *
A27: BUSINESS ENGLISH | B27: 4
A28: 4B | B28: 4
A29: CRUZ MERA RAFER HENRY | B29: 5 | C29: *
A30: CÁLCULO PARA LA GESTIÓN EMPRESARIAL | B30: 5
A31: 2A | B31: 5
A32: GRANDA GARCÍA MARCO IVÁN | B32: 20
A33: TOURISM MARKETING AND SERVICES | B33: 10
A34: 6A | B34: 5
A35: 6B | B35: 5
A36: DIGITAL MARKETING | B36: 10
A37: 7A | B37: 5
A38: 7B | B38: 5
A39: HEREDIA COPPIANO GENESIS ESTEFANÍA | B39: 4 | C39: *
A40: MACRO Y MICRO ECONOMÍA | B40: 4
A41: 2A | B41: 4
A42: HORMAZA VILLAFUERTE SANDY LISBETH | B42: 20
A43: TRADE MARKETING | B43: 10
A44: 7A | B44: 5
A45: 7B | B45: 5
A46: BRAND MANAGEMENT | B46: 10
A47: 6A | B47: 5
A48: 6B | B48: 5
A49: JACOME SANTOS XAVIER IVAN | B49: 15
A50: TÉCNICAS DE VENTAS | B50: 5
A51: 4A | B51: 5
...

Sheet MATRIZ F4 V1
O4: MATRIZ-F4
A5: PLANIFICACIÓN ACADÉMICA
A6: PERÍODO ACADÉMICO: 2026 Periodo 1 | G6: UNIDAD ACADÉMICA: CIENCIAS ADMINISTRATIVAS, CONTABLES Y COMERCIO - CARRERA MERCADOTECNIA
A7: Nº | B7: Cédula | C7: Apellidos y Nombres | D7: Sexo | E7: Unidad Orgánica | F7: Titular | G7: Categoría | H7: Título de tercer nivel | I7: Título de cuarto nivel | J7: Carrera o Tipo de Actividad | K7: Asignatura o Actividad | L7: Grado de afinidad | M7: Horas | N7: Paralelos | O7: Total Horas | P7: Carga Horaria
A8: 1 | B8: 1306260959 | C8: ARIAS ARIAS ANA ELENA | D8: Femenino | E8: CIENCIAS ADMINISTRATIVAS, CONTABLES Y COMERCIO | G8: PROFESOR AGREGADO 1 TIEMPO COMPLETO | H8: LICENCIADO EN COMUNICACION ESPECIALIDAD RELACIONES PUBLICAS. | I8: MAGISTER EN MARKETING. | J8: MERCADOTECNIA O MARKETING -NS- 2026 | K8: COMUNICACIÓN INTEGRAL DE LA MERCADOTECNIA (2A) | L8: 02 - Título de maestría/especialidad médica afín al área de conocimiento | M8: 4 | N8: 1 | O8: =+M8*N8 -> 4 | P8: =SUM(O8:O17) -> 40 | Q8: =SUM(O8:O11) -> 18
H9: LICENCIADA EN SECRETARIADO EJECUTIVO. | I9: ESPECIALISTA EN GERENCIA ESTRATEGICA DE LA COMUNICACION ORGANIZACIONAL. | J9: MERCADOTECNIA O MARKETING -NS- 2026 | K9: TÉCNICAS DE VENTAS (4B) | L9: 02 - Título de maestría/especialidad médica afín al área de conocimiento | M9: 5 | N9: 1 | O9: =+M9*N9 -> 5
J10: MERCADOTECNIA O MARKETING -NS- 2026 | K10: GESTIÓN ADMINISTRATIVA (1A) | M10: 3 | N10: 1 | O10: =+M10*N10 -> 3
J11: MERCADOTECNIA 2017 | K11: GERENCIA DE MERCADOTECNIA (9A-9B) | M11: 3 | N11: 2 | O11: =+M11*N11 -> 6
J12: 1. Docencia - Clases | K12: AD11 Tutorías de inclusión | O12: 2
J13: MERCADOTECNIA 2017 | K13: AD1 Dirección y tutorías de titulación (FASE DESARROLLO TRABAJO TITULACIÓN*NO VIGENTE) | L13: 02 - Título de maestría/especialidad médica afín al área de conocimiento | O13: 6
J14: 1. Docencia - Clases | K14: AD5 Elaboración y calificación de evaluaciones | O14: 5
J15: 1. Docencia - Clases | K15: AD6 Orientación a través de Tutorías | O15: 4
J16: 1. Docencia - Clases | K16: AD4 Preparación de Clases | O16: 4
J17: 1. Docencia - Clases | K17: AD8 Participación en colectivos académicos sobre docencia | O17: 1
A18: 2 | B18: 1310640097 | C18: BADUY MOLINA AARON LEONEL | D18: Masculino | E18: CIENCIAS ADMINISTRATIVAS, CONTABLES Y COMERCIO | G18: PROFESOR AUXILIAR TIEMPO COMPLETO | H18: INGENIERO EN MARKETING. | I18: MAGISTER EN MARKETING. | J18: MERCADOTECNIA 2017 | K18: TRADE MARKETING (9A-9B) | L18: 02 - Título de maestría/especialidad médica afín al área de conocimiento | M18: 4 | N18: 2 | O18: =+M18*N18 -> 8 | P18: =SUM(O18:O27) -> 40 | Q18: =+O19+O18+O20 -> 18
J19: MERCADOTECNIA O MARKETING -NS- 2026 | K19: ÉTICA Y RESPONSABILIDAD SOCIAL EMPRESARIAL (6A-6B) | L19: 02 - Título de maestría/especialidad médica afín al área de conocimiento | M19: 4 | N19: 2 | O19: =+M19*N19 -> 8
J20: CONTABILIDAD Y AUDITORÍA - 2024 NS | K20: ADMINISTRACIÓN | M20: 2 | N20: 1 | O20: =+M20*N20 -> 2
J21: MERCADOTECNIA O MARKETING -NS- 2026 | K21: UIC (FASE PLANIFICACIÓN TRABAJO TITULACIÓN*VIGENTE) | O21: 2
J22: MERCADOTECNIA 2017 | K22: AD1 Dirección y tutorías de titulación (FASE DESARROLLO TRABAJO TITULACIÓN*NO VIGENTE) | L22: 02 - Título de maestría/especialidad médica afín al área de conocimiento | O22: 4
J23: 3. Docencia - Prácticas | K23: AVS1 Dirección, tutorias, seguimiento y evaluación de prácticas y pasantías preprofesionales | N23: Práctica 2 Paralelo C | O23: 4 | Q23: =60/12 -> 5 | R23: =+O23*Q23 -> 20 | S23: alumnos
J24: 1. Docencia - Clases | K24: AD5 Elaboración y calificación de evaluaciones | O24: 5
J25: 1. Docencia - Clases | K25: AD6 Orientación a través de Tutorías | O25: 3
J26: 1. Docencia - Clases | K26: AD4 Preparación de Clases | O26: 3
J27: 1. Docencia - Clases | K27: AD8 Participación en colectivos académicos sobre docencia | O27: 1
A28: 3 | B28: 1309746871 | C28: CARREÑO VILLAVICENCIO DIANEXY VIVIANA | D28: Femenino | E28: CIENCIAS ADMINISTRATIVAS, CONTABLES Y COMERCIO | G28: DIRECTOR DE EDUCACION VIRTUAL | H28: LICENCIADA EN SECRETARIADO EJECUTIVO. | I28: DOCTORA EN CIENCIAS ADMINISTRATIVAS. | J28: MERCADOTECNIA O MARKETING -NS- 2026 | K28: SUPPLY CHAIN ​​MANAGEMENT (5A-5B) | M28: 4 | N28: 2 | O28: =+M28*N28 -> 8 | P28: =SUM(O28:O36) -> 40 | Q28: =+O29+O28 -> 18
J29: MERCADOTECNIA O MARKETING -NS- 2026 | K29: NEUROMARKETING (6A-6B) | M29: 5 | N29: 2 | O29: =+M29*N29 -> 10
J30: MERCADOTECNIA O MARKETING -NS- 2026 | K30: AI2 Ejecución de proyectos de investigación, Básica, Aplicada a la tecnología | O30: 4
J31: 1. Docencia - Clases | K31: AD11 Tutorías de inclusión | O31: 3
J32: MERCADOTECNIA O MARKETING -NS- 2026 | K32: UIC (FASE PLANIFICACIÓN TRABAJO TITULACIÓN*VIGENTE) | O32: 6
J33: 1. Docencia - Clases | K33: AD5 Elaboración y calificación de evaluaciones | O33: 4
J34: 1. Docencia - Clases | K34: AD6 Orientación a través de Tutorías | O34: 2
J35: 1. Docencia - Clases | K35: AD4 Preparación de Clases | O35: 2
J36: 1. Docencia - Clases | K36: AD8 Participación en colectivos académicos sobre docencia | O36: 1
A37: 4 | B37: 0910619543 | C37: GRANDA GARCIA MARCO IVÁN | D37: Masculino | E37: CIENCIAS ADMINISTRATIVAS, CONTABLES Y COMERCIO | G37: PROFESOR AGREGADO 1 TIEMPO COMPLETO | H37: INGENIERO EN CIENCIAS EMPRESARIALES CON ESPECIALIZACION EN GESTION EMPRESARIAL. | I37: MASTER UNIVERSITARIO EN INFORMACION DIGITAL, ESPECIALIDAD EN BUSCADORES: MARKETING ONLINE (SEM) Y POSICIONAMIENTO WEB (SEO). | J37: MERCADOTECNIA O MARKETING -NS- 2026 | K37: TOURISM MARKETING AND SERVICES (6A-6B) | L37: 02 - Título de maestría/especialidad médica afín al área de conocimiento | M37: 5 | N37: 2 | O37: =+M37*N37 -> 10 | P37: =SUM(O37:O46) -> 40 | Q37: =+O37+O38 -> 20
H38: TECNICO SUPERIOR ESPECIALIZACION GESTION EMPRESARIAL. | I38: DIPLOMA SUPERIOR EN EDUCACION UNIVERSITARIA POR COMPETENCIAS. | J38: MERCADOTECNIA O MARKETING -NS- 2026 | K38: DIGITAL MARKETING (7A-7B) | L38: 02 - Título de maestría/especialidad médica afín al área de conocimiento | M38: 5 | N38: 2 | O38: =+M38*N38 -> 10
J39: 6. Investigación | K39: IC Miembro Académico de Comité o Consejo Académico de Revista Científica | O39: 4
J40: 1. Docencia - Clases | K40: AD5 Elaboración y calificación de evaluaciones | O40: 4
J41: 1. Docencia - Clases | K41: AD6 Orientación a través de Tutorías | O41: 2
J42: 1. Docencia - Clases | K42: AD4 Preparación de Clases | O42: 2
J43: 1. Docencia - Clases | K43: AD8 Participación en colectivos académicos sobre docencia | O43: 1
...

Sheet ASIGNACIÓN CURSOS
A2: FCACC
A3: Carrera Mercadotecnia
A4: PERIODO ACADÉMICO 2025 (2)
A5: AULAS CLASES
A6: No. | B6: AULA | C6: NIVEL M (08H00-12H00) | D6: NIVEL T (13H00 - 17H00) | E6: NIVEL N (17H00 - 21H00)
A7: 1 | B7: 107- Auditoria | C7: 1a | D7: 7a | E7: 7b
A8: 2 | B8: 301- Administración | C8: 2a | D8: 2b
A9: 3 | B9: 401- Administración | C9: 3a | D9: 3b
A10: 4 | B10: 210-Auditoria | C10: 4a | D10: 4b | E10: 4c
A11: 5 | B11: 302-Administración | C11: 5a | D11: 5b
A12: 6 | B12: 204-Auditoria | C12: INGLÉS | D12: 6a | E12: 6b
A13: 7 | B13: Juan Montalvo 1 | E13: 9b | F13: LUNES, MARTES Y JUEVES DE 15H00 A 20H00 /MIERCOLES Y VIERNES DE 16H00 A 20H00
A14: 8 | B14: Juan Montalvo 2 | E14: 8a | F14: LUNES Y MIERCOLES DE 16H00 A 20H00 / MARTES, JUEVES Y VIERNES DE 15H00 A 20H00
A15: 9 | B15: Juan Montalvo 3 | E15: 8b | F15: LUNES Y MIERCOLES DE 15H00 A 20H00 / MARTES Y JUEVES DE 16H00 A 20H00
A16: 10 | B16: Juan Montalvo 4 | E16: 9a | F16: MARTES, JUEVES Y VIERNES DE 15H00 A 20H00 / LUNES Y MIERCOLES DE 16H00 A 20H00

Sheet CAPACIDADES ESPECIALES
B1: 2026-1
B2: ID | C2: APELLIDOS Y NOMBRES | D2: CARRERA | E2: CONDICIÓN | F2: INFORMES ADJUNTOS | G2: NIVEL | H2: PARALELO
B3: 1 | C3: BARBERAN SORNOZA MARIASOL | D3: MERCADOTECNIA | E3: INTELECTUAL 34% | G3: 1 | H3: A
B4: =+B3+1 -> 2 | C4: CEVALLOS VALENCIA JESUS DAVID | D4: MERCADOTECNIA | E4: 0 | G4: 1 | H4: A
B5: =+B4+1 -> 3 | C5: FALCONES CEVALLOS MATTEO ALESSANDRO | D5: MERCADOTECNIA | E5: PSICOSOCIAL 70% | G5: 1 | H5: A
B6: =+B5+1 -> 4 | C6: VERA CHALEN FARDY YANDEL | D6: MERCADOTECNIA | E6: FISICA 55% | G6: 1 | H6: A
B7: =+B6+1 -> 5 | C7: FRANCO FRANCO YANDRI STEVEN | D7: MERCADOTECNIA | E7: DISCAPACIDAD FÍSICA 30% | F7: INFORME DE VICERECTORADO | G7: 8 | H7: A
B8: =+B7+1 -> 6 | C8: MOREIRA TIZON DANIEL EMMANUEL | D8: MERCADOTECNIA | E8: DISCAPACIDAD FÍSICA LENGUAJE 56% | F8: INFORME DE VICERECTORADO | G8: 6 | H8: A
B9: =+B8+1 -> 7 | C9: FAUBLA CEVALLOS VIANCA INES | D9: MERCADOTECNIA | E9: LINFOMA - ENFERMEDAD CATASTRÓFICA | F9: INFORME DE VICERECTORADO | G9: 9 | H9: B
B10: =+B9+1 -> 8 | C10: ZAMBRANO BALCAZAR ANTONIO DAVID | D10: MERCADOTECNIA | E10: S/C | F10: INFORME DE VICERECTORADO | G10: 9 | H10: B
B11: =+B10+1 -> 9 | C11: PAZMIÑO BRIONES EMILIA | D11: MERCADOTECNIA | E11: TRANSTORNO ESQUIZOAFECTIVO DEPRESIVO / TRANSTORNO DE ADAPTACIÓN | F11: INFORME PSICOLÓGICO | G11: 3
B12: =+B11+1 -> 10 | C12: MERO VÉLEZ CHRISTY SOLANGE | D12: MERCADOTECNIA | E12: ANSIEDAD NO ESPECIFICA | F12: CONSTANCIA DE ATENCIÓN MÉDICA | G12: 3 | H12: A
B13: =+B12+1 -> 11 | C13: GONZALES CASTILLO FIORELLA DANIELA | D13: MERCADOTECNIA | E13: TRANSTORNO LÍMITE DE LA PERSONALIDAD | F13: INFORME PISCOLÓGICO | G13: 9 | H13: GRADUADA
B14: =+B13+1 -> 12 | C14: PINARGOTE ALCIVAR JUAN GABRIEL | D14: MERCADOTECNIA | E14: PROBLEMAS RELACIONADOS CON LA MUERTE DE UN FAMILIAR | F14: INFORME TÉCNICO DE PSICOLOGÍA | G14: 9 | H14: GRADUADO
B15: =+B14+1 -> 13 | C15: CHÁVEZ MACÍAS MARÍA LOURDES | D15: MERCADOTECNIA | E15: PROBLEMAS EPILPETICOS | F15: INFORME SOCIOECONÓMICO | G15: 8 | H15: A
