Workbook

Sheet DET_ASIG
A1: ID_ASIG_CAM_DET | B1: ID_CARRERA | C1: NOMBRE_CARRERA | D1: NIVEL | E1: ASIGNATURA | F1: ID_ASIG | G1: DETALLADO | H1: ID_DETALLADO
A2: 1 | B2: FCACC-CO-AD | C2: =_xlfn.XLOOKUP(TAB_H_ASIG_CON_DET[[#This Row],[ID_CARRERA]],MAE_CARRERA[ID_CARRERA],MAE_CARRERA[NOMBRE_CARRERA],"Seleccione ID Carrera") -> CONTABILIDAD Y AUDITORÍA 2024 NS | D2: 1 | E2: MATEMÁTICA | F2: =_xlfn.XLOOKUP(TAB_H_ASIG_CON_DET[[#This Row],[ASIGNATURA]],MAE_ASIGNATURA[NOM_ASIG],MAE_ASIGNATURA[ID_ASIG],"Seleccione Asignatura") -> FCACC-CO-EX-NI-1-MATEM | G2: UNIDAD BASICA | H2: =_xlfn.XLOOKUP(TAB_H_ASIG_CON_DET[[#This Row],[DETALLADO]],MAE_CONOCIMIENTO[CAMPO_DETALLADO],MAE_CONOCIMIENTO[ID_DDETALLADO],"Seleccione Campo Detallado") -> F-C-D-UNI-BAS
A3: 2 | B3: FCACC-CO-AD | C3: =_xlfn.XLOOKUP(TAB_H_ASIG_CON_DET[[#This Row],[ID_CARRERA]],MAE_CARRERA[ID_CARRERA],MAE_CARRERA[NOMBRE_CARRERA],"Seleccione ID Carrera") -> CONTABILIDAD Y AUDITORÍA 2024 NS | D3: 1 | E3: CONTABILIDAD BÁSICA | F3: =_xlfn.XLOOKUP(TAB_H_ASIG_CON_DET[[#This Row],[ASIGNATURA]],MAE_ASIGNATURA[NOM_ASIG],MAE_ASIGNATURA[ID_ASIG],"Seleccione Asignatura") -> FCACC-CO-AD-NI-1-CONTA-BÁS | G3: UNIDAD BASICA | H3: =_xlfn.XLOOKUP(TAB_H_ASIG_CON_DET[[#This Row],[DETALLADO]],MAE_CONOCIMIENTO[CAMPO_DETALLADO],MAE_CONOCIMIENTO[ID_DDETALLADO],"Seleccione Campo Detallado") -> F-C-D-UNI-BAS
A4: 3 | B4: FCACC-CO-AD | C4: =_xlfn.XLOOKUP(TAB_H_ASIG_CON_DET[[#This Row],[ID_CARRERA]],MAE_CARRERA[ID_CARRERA],MAE_CARRERA[NOMBRE_CARRERA],"Seleccione ID Carrera") -> CONTABILIDAD Y AUDITORÍA 2024 NS | D4: 1 | E4: METODOLOGÍA DE LA INVESTIGACIÓN | F4: =_xlfn.XLOOKUP(TAB_H_ASIG_CON_DET[[#This Row],[ASIGNATURA]],MAE_ASIGNATURA[NOM_ASIG],MAE_ASIGNATURA[ID_ASIG],"Seleccione Asignatura") -> FCACC-AD-EM-NI-1-METOD-DE -LA | G4: UNIDAD BASICA | H4: =_xlfn.XLOOKUP(TAB_H_ASIG_CON_DET[[#This Row],[DETALLADO]],MAE_CONOCIMIENTO[CAMPO_DETALLADO],MAE_CONOCIMIENTO[ID_DDETALLADO],"Seleccione Campo Detallado") -> F-C-D-UNI-BAS
A5: 4 | B5: FCACC-CO-AD | C5: =_xlfn.XLOOKUP(TAB_H_ASIG_CON_DET[[#This Row],[ID_CARRERA]],MAE_CARRERA[ID_CARRERA],MAE_CARRERA[NOMBRE_CARRERA],"Seleccione ID Carrera") -> CONTABILIDAD Y AUDITORÍA 2024 NS | D5: 1 | E5: ADMINISTRACIÓN | F5: =_xlfn.XLOOKUP(TAB_H_ASIG_CON_DET[[#This Row],[ASIGNATURA]],MAE_ASIGNATURA[NOM_ASIG],MAE_ASIGNATURA[ID_ASIG],"Seleccione Asignatura") -> FCACC-CO-AD-NI-1-ADMIN | G5: UNIDAD BASICA | H5: =_xlfn.XLOOKUP(TAB_H_ASIG_CON_DET[[#This Row],[DETALLADO]],MAE_CONOCIMIENTO[CAMPO_DETALLADO],MAE_CONOCIMIENTO[ID_DDETALLADO],"Seleccione Campo Detallado") -> F-C-D-UNI-BAS
A6: 5 | B6: FCACC-CO-AD | C6: =_xlfn.XLOOKUP(TAB_H_ASIG_CON_DET[[#This Row],[ID_CARRERA]],MAE_CARRERA[ID_CARRERA],MAE_CARRERA[NOMBRE_CARRERA],"Seleccione ID Carrera") -> CONTABILIDAD Y AUDITORÍA 2024 NS | D6: 1 | E6: MACROECONOMÍA | F6: =_xlfn.XLOOKUP(TAB_H_ASIG_CON_DET[[#This Row],[ASIGNATURA]],MAE_ASIGNATURA[NOM_ASIG],MAE_ASIGNATURA[ID_ASIG],"Seleccione Asignatura") -> FCACC-AD-EM-NI-2-MACRO | G6: UNIDAD BASICA | H6: =_xlfn.XLOOKUP(TAB_H_ASIG_CON_DET[[#This Row],[DETALLADO]],MAE_CONOCIMIENTO[CAMPO_DETALLADO],MAE_CONOCIMIENTO[ID_DDETALLADO],"Seleccione Campo Detallado") -> F-C-D-UNI-BAS
A7: 6 | B7: FCACC-CO-AD | C7: =_xlfn.XLOOKUP(TAB_H_ASIG_CON_DET[[#This Row],[ID_CARRERA]],MAE_CARRERA[ID_CARRERA],MAE_CARRERA[NOMBRE_CARRERA],"Seleccione ID Carrera") -> CONTABILIDAD Y AUDITORÍA 2024 NS | D7: 2 | E7: LEGISLACIÓN LABORAL | F7: =_xlfn.XLOOKUP(TAB_H_ASIG_CON_DET[[#This Row],[ASIGNATURA]],MAE_ASIGNATURA[NOM_ASIG],MAE_ASIGNATURA[ID_ASIG],"Seleccione Asignatura") -> FCACC-AU-CO-GE-NI-2-LEGIS-LAB | G7: UNIDAD BASICA | H7: =_xlfn.XLOOKUP(TAB_H_ASIG_CON_DET[[#This Row],[DETALLADO]],MAE_CONOCIMIENTO[CAMPO_DETALLADO],MAE_CONOCIMIENTO[ID_DDETALLADO],"Seleccione Campo Detallado") -> F-C-D-UNI-BAS
A8: 7 | B8: FCACC-CO-AD | C8: =_xlfn.XLOOKUP(TAB_H_ASIG_CON_DET[[#This Row],[ID_CARRERA]],MAE_CARRERA[ID_CARRERA],MAE_CARRERA[NOMBRE_CARRERA],"Seleccione ID Carrera") -> CONTABILIDAD Y AUDITORÍA 2024 NS | D8: 2 | E8: LEGISLACIÓN MERCANTIL Y SOCIETARIA | F8: =_xlfn.XLOOKUP(TAB_H_ASIG_CON_DET[[#This Row],[ASIGNATURA]],MAE_ASIGNATURA[NOM_ASIG],MAE_ASIGNATURA[ID_ASIG],"Seleccione Asignatura") -> FCACC-CO-AD-NI-2-LEGIS-MER-Y | G8: UNIDAD BASICA | H8: =_xlfn.XLOOKUP(TAB_H_ASIG_CON_DET[[#This Row],[DETALLADO]],MAE_CONOCIMIENTO[CAMPO_DETALLADO],MAE_CONOCIMIENTO[ID_DDETALLADO],"Seleccione Campo Detallado") -> F-C-D-UNI-BAS
A9: 8 | B9: FCACC-CO-AD | C9: =_xlfn.XLOOKUP(TAB_H_ASIG_CON_DET[[#This Row],[ID_CARRERA]],MAE_CARRERA[ID_CARRERA],MAE_CARRERA[NOMBRE_CARRERA],"Seleccione ID Carrera") -> CONTABILIDAD Y AUDITORÍA 2024 NS | D9: 2 | E9: CONTABILIDAD INTERMEDIA | F9: =_xlfn.XLOOKUP(TAB_H_ASIG_CON_DET[[#This Row],[ASIGNATURA]],MAE_ASIGNATURA[NOM_ASIG],MAE_ASIGNATURA[ID_ASIG],"Seleccione Asignatura") -> FCACC-CO-AD-NI-2-CONTA-INT | G9: UNIDAD BASICA | H9: =_xlfn.XLOOKUP(TAB_H_ASIG_CON_DET[[#This Row],[DETALLADO]],MAE_CONOCIMIENTO[CAMPO_DETALLADO],MAE_CONOCIMIENTO[ID_DDETALLADO],"Seleccione Campo Detallado") -> F-C-D-UNI-BAS
A10: 9 | B10: FCACC-CO-AD | C10: =_xlfn.XLOOKUP(TAB_H_ASIG_CON_DET[[#This Row],[ID_CARRERA]],MAE_CARRERA[ID_CARRERA],MAE_CARRERA[NOMBRE_CARRERA],"Seleccione ID Carrera") -> CONTABILIDAD Y AUDITORÍA 2024 NS | D10: 2 | E10: MATEMÁTICA FINANCIERA | F10: =_xlfn.XLOOKUP(TAB_H_ASIG_CON_DET[[#This Row],[ASIGNATURA]],MAE_ASIGNATURA[NOM_ASIG],MAE_ASIGNATURA[ID_ASIG],"Seleccione Asignatura") -> FCACC-AD-EM-NI-2-MATEM-FIN | G10: UNIDAD BASICA | H10: =_xlfn.XLOOKUP(TAB_H_ASIG_CON_DET[[#This Row],[DETALLADO]],MAE_CONOCIMIENTO[CAMPO_DETALLADO],MAE_CONOCIMIENTO[ID_DDETALLADO],"Seleccione Campo Detallado") -> F-C-D-UNI-BAS
A11: 10 | B11: FCACC-CO-AD | C11: =_xlfn.XLOOKUP(TAB_H_ASIG_CON_DET[[#This Row],[ID_CARRERA]],MAE_CARRERA[ID_CARRERA],MAE_CARRERA[NOMBRE_CARRERA],"Seleccione ID Carrera") -> CONTABILIDAD Y AUDITORÍA 2024 NS | D11: 2 | E11: ESTADÍSTICA DESCRIPTIVA | F11: =_xlfn.XLOOKUP(TAB_H_ASIG_CON_DET[[#This Row],[ASIGNATURA]],MAE_ASIGNATURA[NOM_ASIG],MAE_ASIGNATURA[ID_ASIG],"Seleccione Asignatura") -> FCACC-AU-CO-GE-NI-1-ESTAD-DES | G11: UNIDAD BASICA | H11: =_xlfn.XLOOKUP(TAB_H_ASIG_CON_DET[[#This Row],[DETALLADO]],MAE_CONOCIMIENTO[CAMPO_DETALLADO],MAE_CONOCIMIENTO[ID_DDETALLADO],"Seleccione Campo Detallado") -> F-C-D-UNI-BAS
A12: 11 | B12: FCACC-CO-AD | C12: =_xlfn.XLOOKUP(TAB_H_ASIG_CON_DET[[#This Row],[ID_CARRERA]],MAE_CARRERA[ID_CARRERA],MAE_CARRERA[NOMBRE_CARRERA],"Seleccione ID Carrera") -> CONTABILIDAD Y AUDITORÍA 2024 NS | D12: 3 | E12: ESTADÍSTICA APLICADA | F12: =_xlfn.XLOOKUP(TAB_H_ASIG_CON_DET[[#This Row],[ASIGNATURA]],MAE_ASIGNATURA[NOM_ASIG],MAE_ASIGNATURA[ID_ASIG],"Seleccione Asignatura") -> FCACC-CO-AD-NI-3-ESTAD-APL | G12: UNIDAD BASICA | H12: =_xlfn.XLOOKUP(TAB_H_ASIG_CON_DET[[#This Row],[DETALLADO]],MAE_CONOCIMIENTO[CAMPO_DETALLADO],MAE_CONOCIMIENTO[ID_DDETALLADO],"Seleccione Campo Detallado") -> F-C-D-UNI-BAS
A13: 12 | B13: FCACC-CO-AD | C13: =_xlfn.XLOOKUP(TAB_H_ASIG_CON_DET[[#This Row],[ID_CARRERA]],MAE_CARRERA[ID_CARRERA],MAE_CARRERA[NOMBRE_CARRERA],"Seleccione ID Carrera") -> CONTABILIDAD Y AUDITORÍA 2024 NS | D13: 3 | E13: CONTABILIDAD AVANZADA | F13: =_xlfn.XLOOKUP(TAB_H_ASIG_CON_DET[[#This Row],[ASIGNATURA]],MAE_ASIGNATURA[NOM_ASIG],MAE_ASIGNATURA[ID_ASIG],"Seleccione Asignatura") -> FCACC-CO-AD-NI-3-CONTA-AVA | G13: UNIDAD BASICA | H13: =_xlfn.XLOOKUP(TAB_H_ASIG_CON_DET[[#This Row],[DETALLADO]],MAE_CONOCIMIENTO[CAMPO_DETALLADO],MAE_CONOCIMIENTO[ID_DDETALLADO],"Seleccione Campo Detallado") -> F-C-D-UNI-BAS
... A45: 59 | B45: FCACC-CO-AD | C45: =_xlfn.XLOOKUP(TAB_H_ASIG_CON_DET[[#This Row],[ID_CARRERA]],MAE_CARRERA[ID_CARRERA],MAE_CARRERA[NOMBRE_CARRERA],"Seleccione ID Carrera") -> CONTABILIDAD Y AUDITORÍA 2024 NS | D45: 6 | E45: INVESTIGACIÓN OPERATIVA | F45: =_xlfn.XLOOKUP(TAB_H_ASIG_CON_DET[[#This Row],[ASIGNATURA]],MAE_ASIGNATURA[NOM_ASIG],MAE_ASIGNATURA[ID_ASIG],"Seleccione Asignatura") -> FCACC-CO-EX-NI-4-INVES-OPE | G45: NEGOCIOS INTERNACIONALES | H45: =_xlfn.XLOOKUP(TAB_H_ASIG_CON_DET[[#This Row],[DETALLADO]],MAE_CONOCIMIENTO[CAMPO_DETALLADO],MAE_CONOCIMIENTO[ID_DDETALLADO],"Seleccione Campo Detallado") -> F-C-D-NEG-INT
A46: 60 | B46: FCACC-CO-AD | C46: =_xlfn.XLOOKUP(TAB_H_ASIG_CON_DET[[#This Row],[ID_CARRERA]],MAE_CARRERA[ID_CARRERA],MAE_CARRERA[NOMBRE_CARRERA],"Seleccione ID Carrera") -> CONTABILIDAD Y AUDITORÍA 2024 NS | D46: 7 | E46: AUDITORÍA TRIBUTARIA | F46: =_xlfn.XLOOKUP(TAB_H_ASIG_CON_DET[[#This Row],[ASIGNATURA]],MAE_ASIGNATURA[NOM_ASIG],MAE_ASIGNATURA[ID_ASIG],"Seleccione Asignatura") -> FCACC-AU-CO-GE-NI-6-AUDIT-TRI | H46: =_xlfn.XLOOKUP(TAB_H_ASIG_CON_DET[[#This Row],[DETALLADO]],MAE_CONOCIMIENTO[CAMPO_DETALLADO],MAE_CONOCIMIENTO[ID_DDETALLADO],"Seleccione Campo Detallado") -> F-C-D-
A47: 61 | B47: FCACC-CO-AD | C47: =_xlfn.XLOOKUP(TAB_H_ASIG_CON_DET[[#This Row],[ID_CARRERA]],MAE_CARRERA[ID_CARRERA],MAE_CARRERA[NOMBRE_CARRERA],"Seleccione ID Carrera") -> CONTABILIDAD Y AUDITORÍA 2024 NS | D47: 7 | E47: AUDITORÍA DE CALIDAD | F47: =_xlfn.XLOOKUP(TAB_H_ASIG_CON_DET[[#This Row],[ASIGNATURA]],MAE_ASIGNATURA[NOM_ASIG],MAE_ASIGNATURA[ID_ASIG],"Seleccione Asignatura") -> FCACC-CO-AD-NI-7-AUDIT-DE -CAL | H47: =_xlfn.XLOOKUP(TAB_H_ASIG_CON_DET[[#This Row],[DETALLADO]],MAE_CONOCIMIENTO[CAMPO_DETALLADO],MAE_CONOCIMIENTO[ID_DDETALLADO],"Seleccione Campo Detallado") -> F-C-D-
A48: 62 | B48: FCACC-CO-AD | C48: =_xlfn.XLOOKUP(TAB_H_ASIG_CON_DET[[#This Row],[ID_CARRERA]],MAE_CARRERA[ID_CARRERA],MAE_CARRERA[NOMBRE_CARRERA],"Seleccione ID Carrera") -> CONTABILIDAD Y AUDITORÍA 2024 NS | D48: 7 | E48: AUDITORÍA GUBERNAMENTAL | F48: =_xlfn.XLOOKUP(TAB_H_ASIG_CON_DET[[#This Row],[ASIGNATURA]],MAE_ASIGNATURA[NOM_ASIG],MAE_ASIGNATURA[ID_ASIG],"Seleccione Asignatura") -> FCACC-CO-AD-NI-7-AUDIT-GUB | H48: =_xlfn.XLOOKUP(TAB_H_ASIG_CON_DET[[#This Row],[DETALLADO]],MAE_CONOCIMIENTO[CAMPO_DETALLADO],MAE_CONOCIMIENTO[ID_DDETALLADO],"Seleccione Campo Detallado") -> F-C-D-
A49: 63 | B49: FCACC-CO-AD | C49: =_xlfn.XLOOKUP(TAB_H_ASIG_CON_DET[[#This Row],[ID_CARRERA]],MAE_CARRERA[ID_CARRERA],MAE_CARRERA[NOMBRE_CARRERA],"Seleccione ID Carrera") -> CONTABILIDAD Y AUDITORÍA 2024 NS | D49: 8 | E49: EVALUACIÓN DE PROYECTOS SOCIALES Y PRODUACTIVOS | F49: =_xlfn.XLOOKUP(TAB_H_ASIG_CON_DET[[#This Row],[ASIGNATURA]],MAE_ASIGNATURA[NOM_ASIG],MAE_ASIGNATURA[ID_ASIG],"Seleccione Asignatura") -> FCACC-CO-AD-NI-7-EVALU-DE -PRO | H49: =_xlfn.XLOOKUP(TAB_H_ASIG_CON_DET[[#This Row],[DETALLADO]],MAE_CONOCIMIENTO[CAMPO_DETALLADO],MAE_CONOCIMIENTO[ID_DDETALLADO],"Seleccione Campo Detallado") -> F-C-D-
A50: 64 | B50: FCACC-CO-AD | C50: =_xlfn.XLOOKUP(TAB_H_ASIG_CON_DET[[#This Row],[ID_CARRERA]],MAE_CARRERA[ID_CARRERA],MAE_CARRERA[NOMBRE_CARRERA],"Seleccione ID Carrera") -> CONTABILIDAD Y AUDITORÍA 2024 NS | D50: 7 | E50: EVALUACIÓN DE PROYECTOS SOCIALES Y PRODUACTIVOS | F50: =_xlfn.XLOOKUP(TAB_H_ASIG_CON_DET[[#This Row],[ASIGNATURA]],MAE_ASIGNATURA[NOM_ASIG],MAE_ASIGNATURA[ID_ASIG],"Seleccione Asignatura") -> FCACC-CO-AD-NI-7-EVALU-DE -PRO | H50: =_xlfn.XLOOKUP(TAB_H_ASIG_CON_DET[[#This Row],[DETALLADO]],MAE_CONOCIMIENTO[CAMPO_DETALLADO],MAE_CONOCIMIENTO[ID_DDETALLADO],"Seleccione Campo Detallado") -> F-C-D-
A51: 65 | B51: FCACC-8-TITU | C51: =_xlfn.XLOOKUP(TAB_H_ASIG_CON_DET[[#This Row],[ID_CARRERA]],MAE_CARRERA[ID_CARRERA],MAE_CARRERA[NOMBRE_CARRERA],"Seleccione ID Carrera") -> Titulación | D51: 7 | E51: Trabajo de integración curricular: Fase de diseño CA-24 | F51: =_xlfn.XLOOKUP(TAB_H_ASIG_CON_DET[[#This Row],[ASIGNATURA]],MAE_ASIGNATURA[NOM_ASIG],MAE_ASIGNATURA[ID_ASIG],"Seleccione Asignatura") -> FCACC-8-TITU-NI-7-Traba-de -int | G51: CONTABILIDAD Y AUDITORÍA | H51: =_xlfn.XLOOKUP(TAB_H_ASIG_CON_DET[[#This Row],[DETALLADO]],MAE_CONOCIMIENTO[CAMPO_DETALLADO],MAE_CONOCIMIENTO[ID_DDETALLADO],"Seleccione Campo Detallado") -> F-C-D-CON-Y A-AUD
A52: 66 | B52: FCACC-8-TITU | C52: =_xlfn.XLOOKUP(TAB_H_ASIG_CON_DET[[#This Row],[ID_CARRERA]],MAE_CARRERA[ID_CARRERA],MAE_CARRERA[NOMBRE_CARRERA],"Seleccione ID Carrera") -> Titulación | D52: 7 | E52: Trabajo de integración curricular: Fase de diseño CA-24 | F52: =_xlfn.XLOOKUP(TAB_H_ASIG_CON_DET[[#This Row],[ASIGNATURA]],MAE_ASIGNATURA[NOM_ASIG],MAE_ASIGNATURA[ID_ASIG],"Seleccione Asignatura") -> FCACC-8-TITU-NI-7-Traba-de -int | G52: GESTIÓN FINANCIERA | H52: =_xlfn.XLOOKUP(TAB_H_ASIG_CON_DET[[#This Row],[DETALLADO]],MAE_CONOCIMIENTO[CAMPO_DETALLADO],MAE_CONOCIMIENTO[ID_DDETALLADO],"Seleccione Campo Detallado") -> F-C-D-GES-FIN
A53: 67 | B53: FCACC-8-TITU | C53: =_xlfn.XLOOKUP(TAB_H_ASIG_CON_DET[[#This Row],[ID_CARRERA]],MAE_CARRERA[ID_CARRERA],MAE_CARRERA[NOMBRE_CARRERA],"Seleccione ID Carrera") -> Titulación | D53: 7 | E53: Trabajo de integración curricular: Fase de diseño CA-24 | F53: =_xlfn.XLOOKUP(TAB_H_ASIG_CON_DET[[#This Row],[ASIGNATURA]],MAE_ASIGNATURA[NOM_ASIG],MAE_ASIGNATURA[ID_ASIG],"Seleccione Asignatura") -> FCACC-8-TITU-NI-7-Traba-de -int | G53: ADMINISTRACIÓN | H53: =_xlfn.XLOOKUP(TAB_H_ASIG_CON_DET[[#This Row],[DETALLADO]],MAE_CONOCIMIENTO[CAMPO_DETALLADO],MAE_CONOCIMIENTO[ID_DDETALLADO],"Seleccione Campo Detallado") -> F-C-D-ADM
A54: 68 | B54: FCACC-8-TITU | C54: =_xlfn.XLOOKUP(TAB_H_ASIG_CON_DET[[#This Row],[ID_CARRERA]],MAE_CARRERA[ID_CARRERA],MAE_CARRERA[NOMBRE_CARRERA],"Seleccione ID Carrera") -> Titulación | D54: 7 | E54: Trabajo de integración curricular: Fase de diseño CA-22 | F54: =_xlfn.XLOOKUP(TAB_H_ASIG_CON_DET[[#This Row],[ASIGNATURA]],MAE_ASIGNATURA[NOM_ASIG],MAE_ASIGNATURA[ID_ASIG],"Seleccione Asignatura") -> FCACC-8-TITU-NI-7-Traba-de -int | G54: CONTABILIDAD Y AUDITORÍA | H54: =_xlfn.XLOOKUP(TAB_H_ASIG_CON_DET[[#This Row],[DETALLADO]],MAE_CONOCIMIENTO[CAMPO_DETALLADO],MAE_CONOCIMIENTO[ID_DDETALLADO],"Seleccione Campo Detallado") -> F-C-D-CON-Y A-AUD
A55: 69 | B55: FCACC-8-TITU | C55: =_xlfn.XLOOKUP(TAB_H_ASIG_CON_DET[[#This Row],[ID_CARRERA]],MAE_CARRERA[ID_CARRERA],MAE_CARRERA[NOMBRE_CARRERA],"Seleccione ID Carrera") -> Titulación | D55: 7 | E55: Trabajo de integración curricular: Fase de diseño CA-22 | F55: =_xlfn.XLOOKUP(TAB_H_ASIG_CON_DET[[#This Row],[ASIGNATURA]],MAE_ASIGNATURA[NOM_ASIG],MAE_ASIGNATURA[ID_ASIG],"Seleccione Asignatura") -> FCACC-8-TITU-NI-7-Traba-de -int | G55: GESTIÓN FINANCIERA | H55: =_xlfn.XLOOKUP(TAB_H_ASIG_CON_DET[[#This Row],[DETALLADO]],MAE_CONOCIMIENTO[CAMPO_DETALLADO],MAE_CONOCIMIENTO[ID_DDETALLADO],"Seleccione Campo Detallado") -> F-C-D-GES-FIN
A56: 70 | B56: FCACC-8-TITU | C56: =_xlfn.XLOOKUP(TAB_H_ASIG_CON_DET[[#This Row],[ID_CARRERA]],MAE_CARRERA[ID_CARRERA],MAE_CARRERA[NOMBRE_CARRERA],"Seleccione ID Carrera") -> Titulación | D56: 7 | E56: Trabajo de integración curricular: Fase de diseño CA-22 | F56: =_xlfn.XLOOKUP(TAB_H_ASIG_CON_DET[[#This Row],[ASIGNATURA]],MAE_ASIGNATURA[NOM_ASIG],MAE_ASIGNATURA[ID_ASIG],"Seleccione Asignatura") -> FCACC-8-TITU-NI-7-Traba-de -int | G56: ADMINISTRACIÓN | H56: =_xlfn.XLOOKUP(TAB_H_ASIG_CON_DET[[#This Row],[DETALLADO]],MAE_CONOCIMIENTO[CAMPO_DETALLADO],MAE_CONOCIMIENTO[ID_DDETALLADO],"Seleccione Campo Detallado") -> F-C-D-ADM
A57: 71 | B57: FCACC-CO-AD | C57: =_xlfn.XLOOKUP(TAB_H_ASIG_CON_DET[[#This Row],[ID_CARRERA]],MAE_CARRERA[ID_CARRERA],MAE_CARRERA[NOMBRE_CARRERA],"Seleccione ID Carrera") -> CONTABILIDAD Y AUDITORÍA 2024 NS | D57: 8 | E57: AUDITORÍA FORENSE | F57: =_xlfn.XLOOKUP(TAB_H_ASIG_CON_DET[[#This Row],[ASIGNATURA]],MAE_ASIGNATURA[NOM_ASIG],MAE_ASIGNATURA[ID_ASIG],"Seleccione Asignatura") -> FCACC-AU-CO-GE-NI-8-AUDIT-FOR | G57: CONTABILIDAD Y AUDITORÍA | H57: =_xlfn.XLOOKUP(TAB_H_ASIG_CON_DET[[#This Row],[DETALLADO]],MAE_CONOCIMIENTO[CAMPO_DETALLADO],MAE_CONOCIMIENTO[ID_DDETALLADO],"Seleccione Campo Detallado") -> F-C-D-CON-Y A-AUD
A58: 72 | B58: FCACC-CO-AD | C58: =_xlfn.XLOOKUP(TAB_H_ASIG_CON_DET[[#This Row],[ID_CARRERA]],MAE_CARRERA[ID_CARRERA],MAE_CARRERA[NOMBRE_CARRERA],"Seleccione ID Carrera") -> CONTABILIDAD Y AUDITORÍA 2024 NS | D58: 8 | E58: AUDITORÍA DE GESTIÓN | F58: =_xlfn.XLOOKUP(TAB_H_ASIG_CON_DET[[#This Row],[ASIGNATURA]],MAE_ASIGNATURA[NOM_ASIG],MAE_ASIGNATURA[ID_ASIG],"Seleccione Asignatura") -> FCACC-AU-CO-GE-NI-6-AUDIT-DE -GES | G58: CONTABILIDAD Y AUDITORÍA | H58: =_xlfn.XLOOKUP(TAB_H_ASIG_CON_DET[[#This Row],[DETALLADO]],MAE_CONOCIMIENTO[CAMPO_DETALLADO],MAE_CONOCIMIENTO[ID_DDETALLADO],"Seleccione Campo Detallado") -> F-C-D-CON-Y A-AUD
A59: 73 | B59: FCACC-CO-AD | C59: =_xlfn.XLOOKUP(TAB_H_ASIG_CON_DET[[#This Row],[ID_CARRERA]],MAE_CARRERA[ID_CARRERA],MAE_CARRERA[NOMBRE_CARRERA],"Seleccione ID Carrera") -> CONTABILIDAD Y AUDITORÍA 2024 NS | D59: 8 | E59: PROCESO DE CONTRATACIÓN PÚBLICA | F59: =_xlfn.XLOOKUP(TAB_H_ASIG_CON_DET[[#This Row],[ASIGNATURA]],MAE_ASIGNATURA[NOM_ASIG],MAE_ASIGNATURA[ID_ASIG],"Seleccione Asignatura") -> FCACC-AU-CO-GE-NI-6-PROCE-DE -CON | G59: CONTABILIDAD Y AUDITORÍA | H59: =_xlfn.XLOOKUP(TAB_H_ASIG_CON_DET[[#This Row],[DETALLADO]],MAE_CONOCIMIENTO[CAMPO_DETALLADO],MAE_CONOCIMIENTO[ID_DDETALLADO],"Seleccione Campo Detallado") -> F-C-D-CON-Y A-AUD
A60: 74 | B60: FCACC-CO-AD | C60: =_xlfn.XLOOKUP(TAB_H_ASIG_CON_DET[[#This Row],[ID_CARRERA]],MAE_CARRERA[ID_CARRERA],MAE_CARRERA[NOMBRE_CARRERA],"Seleccione ID Carrera") -> CONTABILIDAD Y AUDITORÍA 2024 NS | D60: 8 | E60: PROCESO DE CONTRATACIÓN PÚBLICA | F60: =_xlfn.XLOOKUP(TAB_H_ASIG_CON_DET[[#This Row],[ASIGNATURA]],MAE_ASIGNATURA[NOM_ASIG],MAE_ASIGNATURA[ID_ASIG],"Seleccione Asignatura") -> FCACC-AU-CO-GE-NI-6-PROCE-DE -CON | G60: ADMINISTRACIÓN | H60: =_xlfn.XLOOKUP(TAB_H_ASIG_CON_DET[[#This Row],[DETALLADO]],MAE_CONOCIMIENTO[CAMPO_DETALLADO],MAE_CONOCIMIENTO[ID_DDETALLADO],"Seleccione Campo Detallado") -> F-C-D-ADM
A61: 75 | B61: FCACC-CO-AD | C61: =_xlfn.XLOOKUP(TAB_H_ASIG_CON_DET[[#This Row],[ID_CARRERA]],MAE_CARRERA[ID_CARRERA],MAE_CARRERA[NOMBRE_CARRERA],"Seleccione ID Carrera") -> CONTABILIDAD Y AUDITORÍA 2024 NS | D61: 8 | E61: AUDITORÍA INFORMÁTICA | F61: =_xlfn.XLOOKUP(TAB_H_ASIG_CON_DET[[#This Row],[ASIGNATURA]],MAE_ASIGNATURA[NOM_ASIG],MAE_ASIGNATURA[ID_ASIG],"Seleccione Asignatura") -> FCACC-CO-AD-NI-8-AUDIT-INF | G61: CONTABILIDAD Y AUDITORÍA | H61: =_xlfn.XLOOKUP(TAB_H_ASIG_CON_DET[[#This Row],[DETALLADO]],MAE_CONOCIMIENTO[CAMPO_DETALLADO],MAE_CONOCIMIENTO[ID_DDETALLADO],"Seleccione Campo Detallado") -> F-C-D-CON-Y A-AUD
A62: 76 | B62: FCACC-CO-AD | C62: =_xlfn.XLOOKUP(TAB_H_ASIG_CON_DET[[#This Row],[ID_CARRERA]],MAE_CARRERA[ID_CARRERA],MAE_CARRERA[NOMBRE_CARRERA],"Seleccione ID Carrera") -> CONTABILIDAD Y AUDITORÍA 2024 NS | D62: 8 | E62: AUDITORÍA AMBIENTAL | F62: =_xlfn.XLOOKUP(TAB_H_ASIG_CON_DET[[#This Row],[ASIGNATURA]],MAE_ASIGNATURA[NOM_ASIG],MAE_ASIGNATURA[ID_ASIG],"Seleccione Asignatura") -> FCACC-CO-AD-NI-8-AUDIT-AMB | G62: CONTABILIDAD Y AUDITORÍA | H62: =_xlfn.XLOOKUP(TAB_H_ASIG_CON_DET[[#This Row],[DETALLADO]],MAE_CONOCIMIENTO[CAMPO_DETALLADO],MAE_CONOCIMIENTO[ID_DDETALLADO],"Seleccione Campo Detallado") -> F-C-D-CON-Y A-AUD
... A250: 265 | B250: FCACC-8-TITU | C250: =_xlfn.XLOOKUP(TAB_H_ASIG_CON_DET[[#This Row],[ID_CARRERA]],MAE_CARRERA[ID_CARRERA],MAE_CARRERA[NOMBRE_CARRERA],"Seleccione ID Carrera") -> Titulación | D250: 8 | E250: Trabajo de integración curricular: Fase de resultados e informe F-24 | F250: =_xlfn.XLOOKUP(TAB_H_ASIG_CON_DET[[#This Row],[ASIGNATURA]],MAE_ASIGNATURA[NOM_ASIG],MAE_ASIGNATURA[ID_ASIG],"Seleccione Asignatura") -> FCACC-8-TITU-NI-8-Traba-de -int | G250: ADMINISTRACIÓN | H250: =_xlfn.XLOOKUP(TAB_H_ASIG_CON_DET[[#This Row],[DETALLADO]],MAE_CONOCIMIENTO[CAMPO_DETALLADO],MAE_CONOCIMIENTO[ID_DDETALLADO],"Seleccione Campo Detallado") -> F-C-D-ADM
A251: 266 | C251: ADMINISTRACIÓN DE EMPRESAS 2024 NS | F251: =_xlfn.XLOOKUP(TAB_H_ASIG_CON_DET[[#This Row],[ASIGNATURA]],MAE_ASIGNATURA[NOM_ASIG],MAE_ASIGNATURA[ID_ASIG],"Seleccione Asignatura") -> Seleccione Asignatura | H251: =_xlfn.XLOOKUP(TAB_H_ASIG_CON_DET[[#This Row],[DETALLADO]],MAE_CONOCIMIENTO[CAMPO_DETALLADO],MAE_CONOCIMIENTO[ID_DDETALLADO],"Seleccione Campo Detallado") -> F-C-D-
A252: 267 | C252: =_xlfn.XLOOKUP(TAB_H_ASIG_CON_DET[[#This Row],[ID_CARRERA]],MAE_CARRERA[ID_CARRERA],MAE_CARRERA[NOMBRE_CARRERA],"Seleccione ID Carrera") -> Seleccione ID Carrera | F252: =_xlfn.XLOOKUP(TAB_H_ASIG_CON_DET[[#This Row],[ASIGNATURA]],MAE_ASIGNATURA[NOM_ASIG],MAE_ASIGNATURA[ID_ASIG],"Seleccione Asignatura") -> Seleccione Asignatura | H252: =_xlfn.XLOOKUP(TAB_H_ASIG_CON_DET[[#This Row],[DETALLADO]],MAE_CONOCIMIENTO[CAMPO_DETALLADO],MAE_CONOCIMIENTO[ID_DDETALLADO],"Seleccione Campo Detallado") -> F-C-D-
A253: 268 | C253: =_xlfn.XLOOKUP(TAB_H_ASIG_CON_DET[[#This Row],[ID_CARRERA]],MAE_CARRERA[ID_CARRERA],MAE_CARRERA[NOMBRE_CARRERA],"Seleccione ID Carrera") -> Seleccione ID Carrera | F253: =_xlfn.XLOOKUP(TAB_H_ASIG_CON_DET[[#This Row],[ASIGNATURA]],MAE_ASIGNATURA[NOM_ASIG],MAE_ASIGNATURA[ID_ASIG],"Seleccione Asignatura") -> Seleccione Asignatura | H253: =_xlfn.XLOOKUP(TAB_H_ASIG_CON_DET[[#This Row],[DETALLADO]],MAE_CONOCIMIENTO[CAMPO_DETALLADO],MAE_CONOCIMIENTO[ID_DDETALLADO],"Seleccione Campo Detallado") -> F-C-D-
A254: 269 | C254: =_xlfn.XLOOKUP(TAB_H_ASIG_CON_DET[[#This Row],[ID_CARRERA]],MAE_CARRERA[ID_CARRERA],MAE_CARRERA[NOMBRE_CARRERA],"Seleccione ID Carrera") -> Seleccione ID Carrera | F254: =_xlfn.XLOOKUP(TAB_H_ASIG_CON_DET[[#This Row],[ASIGNATURA]],MAE_ASIGNATURA[NOM_ASIG],MAE_ASIGNATURA[ID_ASIG],"Seleccione Asignatura") -> Seleccione Asignatura | H254: =_xlfn.XLOOKUP(TAB_H_ASIG_CON_DET[[#This Row],[DETALLADO]],MAE_CONOCIMIENTO[CAMPO_DETALLADO],MAE_CONOCIMIENTO[ID_DDETALLADO],"Seleccione Campo Detallado") -> F-C-D-
A255: 270 | C255: =_xlfn.XLOOKUP(TAB_H_ASIG_CON_DET[[#This Row],[ID_CARRERA]],MAE_CARRERA[ID_CARRERA],MAE_CARRERA[NOMBRE_CARRERA],"Seleccione ID Carrera") -> Seleccione ID Carrera | F255: =_xlfn.XLOOKUP(TAB_H_ASIG_CON_DET[[#This Row],[ASIGNATURA]],MAE_ASIGNATURA[NOM_ASIG],MAE_ASIGNATURA[ID_ASIG],"Seleccione Asignatura") -> Seleccione Asignatura | H255: =_xlfn.XLOOKUP(TAB_H_ASIG_CON_DET[[#This Row],[DETALLADO]],MAE_CONOCIMIENTO[CAMPO_DETALLADO],MAE_CONOCIMIENTO[ID_DDETALLADO],"Seleccione Campo Detallado") -> F-C-D-
A256: 271 | C256: =_xlfn.XLOOKUP(TAB_H_ASIG_CON_DET[[#This Row],[ID_CARRERA]],MAE_CARRERA[ID_CARRERA],MAE_CARRERA[NOMBRE_CARRERA],"Seleccione ID Carrera") -> Seleccione ID Carrera | F256: =_xlfn.XLOOKUP(TAB_H_ASIG_CON_DET[[#This Row],[ASIGNATURA]],MAE_ASIGNATURA[NOM_ASIG],MAE_ASIGNATURA[ID_ASIG],"Seleccione Asignatura") -> Seleccione Asignatura | H256: =_xlfn.XLOOKUP(TAB_H_ASIG_CON_DET[[#This Row],[DETALLADO]],MAE_CONOCIMIENTO[CAMPO_DETALLADO],MAE_CONOCIMIENTO[ID_DDETALLADO],"Seleccione Campo Detallado") -> F-C-D-
A257: 272 | C257: =_xlfn.XLOOKUP(TAB_H_ASIG_CON_DET[[#This Row],[ID_CARRERA]],MAE_CARRERA[ID_CARRERA],MAE_CARRERA[NOMBRE_CARRERA],"Seleccione ID Carrera") -> Seleccione ID Carrera | F257: =_xlfn.XLOOKUP(TAB_H_ASIG_CON_DET[[#This Row],[ASIGNATURA]],MAE_ASIGNATURA[NOM_ASIG],MAE_ASIGNATURA[ID_ASIG],"Seleccione Asignatura") -> Seleccione Asignatura | H257: =_xlfn.XLOOKUP(TAB_H_ASIG_CON_DET[[#This Row],[DETALLADO]],MAE_CONOCIMIENTO[CAMPO_DETALLADO],MAE_CONOCIMIENTO[ID_DDETALLADO],"Seleccione Campo Detallado") -> F-C-D-
A258: 273 | C258: =_xlfn.XLOOKUP(TAB_H_ASIG_CON_DET[[#This Row],[ID_CARRERA]],MAE_CARRERA[ID_CARRERA],MAE_CARRERA[NOMBRE_CARRERA],"Seleccione ID Carrera") -> Seleccione ID Carrera | F258: =_xlfn.XLOOKUP(TAB_H_ASIG_CON_DET[[#This Row],[ASIGNATURA]],MAE_ASIGNATURA[NOM_ASIG],MAE_ASIGNATURA[ID_ASIG],"Seleccione Asignatura") -> Seleccione Asignatura | H258: =_xlfn.XLOOKUP(TAB_H_ASIG_CON_DET[[#This Row],[DETALLADO]],MAE_CONOCIMIENTO[CAMPO_DETALLADO],MAE_CONOCIMIENTO[ID_DDETALLADO],"Seleccione Campo Detallado") -> F-C-D-
...

Sheet Hoja1
A1: NIVEL | O1: ASIGNATURA
A2: {=TRANSPOSE(_xlfn.UNIQUE(_xlfn._xlws.FILTER(MAE_ASIGNATURA[ID_NIVEL],MAE_ASIGNATURA[ID_CARRERA]=DET_ASIG!$B2,"No existe información")))} -> 1 | B2: 2 | C2: 3 | D2: 4 | E2: 5 | F2: 6 | G2: 7 | H2: 8 | O2: {=TRANSPOSE(_xlfn.UNIQUE(_xlfn._xlws.FILTER(MAE_ASIGNATURA[NOM_ASIG],(MAE_ASIGNATURA[ID_NIVEL]=DET_ASIG!$D2)*(MAE_ASIGNATURA[ID_CARRERA]=DET_ASIG!$B2),"No existe información")))} -> CONTABILIDAD BÁSICA | P2: MATEMÁTICA | Q2: METODOLOGÍA DE LA INVESTIGACIÓN | R2: ADMINISTRACIÓN | S2: MACROECONOMÍA
A3: {=TRANSPOSE(_xlfn.UNIQUE(_xlfn._xlws.FILTER(MAE_ASIGNATURA[ID_NIVEL],MAE_ASIGNATURA[ID_CARRERA]=DET_ASIG!$B3,"No existe información")))} -> 1 | B3: 2 | C3: 3 | D3: 4 | E3: 5 | F3: 6 | G3: 7 | H3: 8 | O3: {=TRANSPOSE(_xlfn.UNIQUE(_xlfn._xlws.FILTER(MAE_ASIGNATURA[NOM_ASIG],(MAE_ASIGNATURA[ID_NIVEL]=DET_ASIG!$D3)*(MAE_ASIGNATURA[ID_CARRERA]=DET_ASIG!$B3),"No existe información")))} -> CONTABILIDAD BÁSICA | P3: MATEMÁTICA | Q3: METODOLOGÍA DE LA INVESTIGACIÓN | R3: ADMINISTRACIÓN | S3: MACROECONOMÍA
A4: {=TRANSPOSE(_xlfn.UNIQUE(_xlfn._xlws.FILTER(MAE_ASIGNATURA[ID_NIVEL],MAE_ASIGNATURA[ID_CARRERA]=DET_ASIG!$B4,"No existe información")))} -> 1 | B4: 2 | C4: 3 | D4: 4 | E4: 5 | F4: 6 | G4: 7 | H4: 8 | O4: {=TRANSPOSE(_xlfn.UNIQUE(_xlfn._xlws.FILTER(MAE_ASIGNATURA[NOM_ASIG],(MAE_ASIGNATURA[ID_NIVEL]=DET_ASIG!$D4)*(MAE_ASIGNATURA[ID_CARRERA]=DET_ASIG!$B4),"No existe información")))} -> CONTABILIDAD BÁSICA | P4: MATEMÁTICA | Q4: METODOLOGÍA DE LA INVESTIGACIÓN | R4: ADMINISTRACIÓN | S4: MACROECONOMÍA
A5: {=TRANSPOSE(_xlfn.UNIQUE(_xlfn._xlws.FILTER(MAE_ASIGNATURA[ID_NIVEL],MAE_ASIGNATURA[ID_CARRERA]=DET_ASIG!$B5,"No existe información")))} -> 1 | B5: 2 | C5: 3 | D5: 4 | E5: 5 | F5: 6 | G5: 7 | H5: 8 | O5: {=TRANSPOSE(_xlfn.UNIQUE(_xlfn._xlws.FILTER(MAE_ASIGNATURA[NOM_ASIG],(MAE_ASIGNATURA[ID_NIVEL]=DET_ASIG!$D5)*(MAE_ASIGNATURA[ID_CARRERA]=DET_ASIG!$B5),"No existe información")))} -> CONTABILIDAD BÁSICA | P5: MATEMÁTICA | Q5: METODOLOGÍA DE LA INVESTIGACIÓN | R5: ADMINISTRACIÓN | S5: MACROECONOMÍA
A6: {=TRANSPOSE(_xlfn.UNIQUE(_xlfn._xlws.FILTER(MAE_ASIGNATURA[ID_NIVEL],MAE_ASIGNATURA[ID_CARRERA]=DET_ASIG!$B6,"No existe información")))} -> 1 | B6: 2 | C6: 3 | D6: 4 | E6: 5 | F6: 6 | G6: 7 | H6: 8 | O6: {=TRANSPOSE(_xlfn.UNIQUE(_xlfn._xlws.FILTER(MAE_ASIGNATURA[NOM_ASIG],(MAE_ASIGNATURA[ID_NIVEL]=DET_ASIG!$D6)*(MAE_ASIGNATURA[ID_CARRERA]=DET_ASIG!$B6),"No existe información")))} -> CONTABILIDAD BÁSICA | P6: MATEMÁTICA | Q6: METODOLOGÍA DE LA INVESTIGACIÓN | R6: ADMINISTRACIÓN | S6: MACROECONOMÍA
A7: {=TRANSPOSE(_xlfn.UNIQUE(_xlfn._xlws.FILTER(MAE_ASIGNATURA[ID_NIVEL],MAE_ASIGNATURA[ID_CARRERA]=DET_ASIG!$B7,"No existe información")))} -> 1 | B7: 2 | C7: 3 | D7: 4 | E7: 5 | F7: 6 | G7: 7 | H7: 8 | O7: {=TRANSPOSE(_xlfn.UNIQUE(_xlfn._xlws.FILTER(MAE_ASIGNATURA[NOM_ASIG],(MAE_ASIGNATURA[ID_NIVEL]=DET_ASIG!$D7)*(MAE_ASIGNATURA[ID_CARRERA]=DET_ASIG!$B7),"No existe información")))} -> LEGISLACIÓN LABORAL | P7: CONTABILIDAD INTERMEDIA | Q7: ESTADÍSTICA DESCRIPTIVA | R7: LEGISLACIÓN MERCANTIL Y SOCIETARIA | S7: MATEMÁTICA FINANCIERA
A8: {=TRANSPOSE(_xlfn.UNIQUE(_xlfn._xlws.FILTER(MAE_ASIGNATURA[ID_NIVEL],MAE_ASIGNATURA[ID_CARRERA]=DET_ASIG!$B8,"No existe información")))} -> 1 | B8: 2 | C8: 3 | D8: 4 | E8: 5 | F8: 6 | G8: 7 | H8: 8 | O8: {=TRANSPOSE(_xlfn.UNIQUE(_xlfn._xlws.FILTER(MAE_ASIGNATURA[NOM_ASIG],(MAE_ASIGNATURA[ID_NIVEL]=DET_ASIG!$D8)*(MAE_ASIGNATURA[ID_CARRERA]=DET_ASIG!$B8),"No existe información")))} -> LEGISLACIÓN LABORAL | P8: CONTABILIDAD INTERMEDIA | Q8: ESTADÍSTICA DESCRIPTIVA | R8: LEGISLACIÓN MERCANTIL Y SOCIETARIA | S8: MATEMÁTICA FINANCIERA
A9: {=TRANSPOSE(_xlfn.UNIQUE(_xlfn._xlws.FILTER(MAE_ASIGNATURA[ID_NIVEL],MAE_ASIGNATURA[ID_CARRERA]=DET_ASIG!$B9,"No existe información")))} -> 1 | B9: 2 | C9: 3 | D9: 4 | E9: 5 | F9: 6 | G9: 7 | H9: 8 | O9: {=TRANSPOSE(_xlfn.UNIQUE(_xlfn._xlws.FILTER(MAE_ASIGNATURA[NOM_ASIG],(MAE_ASIGNATURA[ID_NIVEL]=DET_ASIG!$D9)*(MAE_ASIGNATURA[ID_CARRERA]=DET_ASIG!$B9),"No existe información")))} -> LEGISLACIÓN LABORAL | P9: CONTABILIDAD INTERMEDIA | Q9: ESTADÍSTICA DESCRIPTIVA | R9: LEGISLACIÓN MERCANTIL Y SOCIETARIA | S9: MATEMÁTICA FINANCIERA
A10: {=TRANSPOSE(_xlfn.UNIQUE(_xlfn._xlws.FILTER(MAE_ASIGNATURA[ID_NIVEL],MAE_ASIGNATURA[ID_CARRERA]=DET_ASIG!$B10,"No existe información")))} -> 1 | B10: 2 | C10: 3 | D10: 4 | E10: 5 | F10: 6 | G10: 7 | H10: 8 | O10: {=TRANSPOSE(_xlfn.UNIQUE(_xlfn._xlws.FILTER(MAE_ASIGNATURA[NOM_ASIG],(MAE_ASIGNATURA[ID_NIVEL]=DET_ASIG!$D10)*(MAE_ASIGNATURA[ID_CARRERA]=DET_ASIG!$B10),"No existe información")))} -> LEGISLACIÓN LABORAL | P10: CONTABILIDAD INTERMEDIA | Q10: ESTADÍSTICA DESCRIPTIVA | R10: LEGISLACIÓN MERCANTIL Y SOCIETARIA | S10: MATEMÁTICA FINANCIERA
A11: {=TRANSPOSE(_xlfn.UNIQUE(_xlfn._xlws.FILTER(MAE_ASIGNATURA[ID_NIVEL],MAE_ASIGNATURA[ID_CARRERA]=DET_ASIG!$B11,"No existe información")))} -> 1 | B11: 2 | C11: 3 | D11: 4 | E11: 5 | F11: 6 | G11: 7 | H11: 8 | O11: {=TRANSPOSE(_xlfn.UNIQUE(_xlfn._xlws.FILTER(MAE_ASIGNATURA[NOM_ASIG],(MAE_ASIGNATURA[ID_NIVEL]=DET_ASIG!$D11)*(MAE_ASIGNATURA[ID_CARRERA]=DET_ASIG!$B11),"No existe información")))} -> LEGISLACIÓN LABORAL | P11: CONTABILIDAD INTERMEDIA | Q11: ESTADÍSTICA DESCRIPTIVA | R11: LEGISLACIÓN MERCANTIL Y SOCIETARIA | S11: MATEMÁTICA FINANCIERA
A12: {=TRANSPOSE(_xlfn.UNIQUE(_xlfn._xlws.FILTER(MAE_ASIGNATURA[ID_NIVEL],MAE_ASIGNATURA[ID_CARRERA]=DET_ASIG!$B12,"No existe información")))} -> 1 | B12: 2 | C12: 3 | D12: 4 | E12: 5 | F12: 6 | G12: 7 | H12: 8 | O12: {=TRANSPOSE(_xlfn.UNIQUE(_xlfn._xlws.FILTER(MAE_ASIGNATURA[NOM_ASIG],(MAE_ASIGNATURA[ID_NIVEL]=DET_ASIG!$D12)*(MAE_ASIGNATURA[ID_CARRERA]=DET_ASIG!$B12),"No existe información")))} -> CONTABILIDAD AVANZADA | P12: FUNDAMENTOS DE AUDITORÍA | Q12: ESTADÍSTICA APLICADA | R12: LEGISLACIÓN TRIBUTARIA | S12: SISTEMATIZACIÓN CONTABLE Y FINANCIERA | T12: PROCESO Y CONTROL DEL TALENTO HUMANO
A13: {=TRANSPOSE(_xlfn.UNIQUE(_xlfn._xlws.FILTER(MAE_ASIGNATURA[ID_NIVEL],MAE_ASIGNATURA[ID_CARRERA]=DET_ASIG!$B13,"No existe información")))} -> 1 | B13: 2 | C13: 3 | D13: 4 | E13: 5 | F13: 6 | G13: 7 | H13: 8 | O13: {=TRANSPOSE(_xlfn.UNIQUE(_xlfn._xlws.FILTER(MAE_ASIGNATURA[NOM_ASIG],(MAE_ASIGNATURA[ID_NIVEL]=DET_ASIG!$D13)*(MAE_ASIGNATURA[ID_CARRERA]=DET_ASIG!$B13),"No existe información")))} -> CONTABILIDAD AVANZADA | P13: FUNDAMENTOS DE AUDITORÍA | Q13: ESTADÍSTICA APLICADA | R13: LEGISLACIÓN TRIBUTARIA | S13: SISTEMATIZACIÓN CONTABLE Y FINANCIERA | T13: PROCESO Y CONTROL DEL TALENTO HUMANO
A14: {=TRANSPOSE(_xlfn.UNIQUE(_xlfn._xlws.FILTER(MAE_ASIGNATURA[ID_NIVEL],MAE_ASIGNATURA[ID_CARRERA]=DET_ASIG!$B14,"No existe información")))} -> 1 | B14: 2 | C14: 3 | D14: 4 | E14: 5 | F14: 6 | G14: 7 | H14: 8 | O14: {=TRANSPOSE(_xlfn.UNIQUE(_xlfn._xlws.FILTER(MAE_ASIGNATURA[NOM_ASIG],(MAE_ASIGNATURA[ID_NIVEL]=DET_ASIG!$D14)*(MAE_ASIGNATURA[ID_CARRERA]=DET_ASIG!$B14),"No existe información")))} -> CONTABILIDAD AVANZADA | P14: FUNDAMENTOS DE AUDITORÍA | Q14: ESTADÍSTICA APLICADA | R14: LEGISLACIÓN TRIBUTARIA | S14: SISTEMATIZACIÓN CONTABLE Y FINANCIERA | T14: PROCESO Y CONTROL DEL TALENTO HUMANO
A15: {=TRANSPOSE(_xlfn.UNIQUE(_xlfn._xlws.FILTER(MAE_ASIGNATURA[ID_NIVEL],MAE_ASIGNATURA[ID_CARRERA]=DET_ASIG!$B15,"No existe información")))} -> 1 | B15: 2 | C15: 3 | D15: 4 | E15: 5 | F15: 6 | G15: 7 | H15: 8 | O15: {=TRANSPOSE(_xlfn.UNIQUE(_xlfn._xlws.FILTER(MAE_ASIGNATURA[NOM_ASIG],(MAE_ASIGNATURA[ID_NIVEL]=DET_ASIG!$D15)*(MAE_ASIGNATURA[ID_CARRERA]=DET_ASIG!$B15),"No existe información")))} -> CONTABILIDAD AVANZADA | P15: FUNDAMENTOS DE AUDITORÍA | Q15: ESTADÍSTICA APLICADA | R15: LEGISLACIÓN TRIBUTARIA | S15: SISTEMATIZACIÓN CONTABLE Y FINANCIERA | T15: PROCESO Y CONTROL DEL TALENTO HUMANO
A16: {=TRANSPOSE(_xlfn.UNIQUE(_xlfn._xlws.FILTER(MAE_ASIGNATURA[ID_NIVEL],MAE_ASIGNATURA[ID_CARRERA]=DET_ASIG!$B16,"No existe información")))} -> 1 | B16: 2 | C16: 3 | D16: 4 | E16: 5 | F16: 6 | G16: 7 | H16: 8 | O16: {=TRANSPOSE(_xlfn.UNIQUE(_xlfn._xlws.FILTER(MAE_ASIGNATURA[NOM_ASIG],(MAE_ASIGNATURA[ID_NIVEL]=DET_ASIG!$D16)*(MAE_ASIGNATURA[ID_CARRERA]=DET_ASIG!$B16),"No existe información")))} -> CONTABILIDAD AVANZADA | P16: FUNDAMENTOS DE AUDITORÍA | Q16: ESTADÍSTICA APLICADA | R16: LEGISLACIÓN TRIBUTARIA | S16: SISTEMATIZACIÓN CONTABLE Y FINANCIERA | T16: PROCESO Y CONTROL DEL TALENTO HUMANO
A17: {=TRANSPOSE(_xlfn.UNIQUE(_xlfn._xlws.FILTER(MAE_ASIGNATURA[ID_NIVEL],MAE_ASIGNATURA[ID_CARRERA]=DET_ASIG!#REF!,"No existe información")))} -> #REF! | O17: {=TRANSPOSE(_xlfn.UNIQUE(_xlfn._xlws.FILTER(MAE_ASIGNATURA[NOM_ASIG],(MAE_ASIGNATURA[ID_NIVEL]=DET_ASIG!#REF!)*(MAE_ASIGNATURA[ID_CARRERA]=DET_ASIG!#REF!),"No existe información")))} -> #REF!
A18: {=TRANSPOSE(_xlfn.UNIQUE(_xlfn._xlws.FILTER(MAE_ASIGNATURA[ID_NIVEL],MAE_ASIGNATURA[ID_CARRERA]=DET_ASIG!#REF!,"No existe información")))} -> #REF! | O18: {=TRANSPOSE(_xlfn.UNIQUE(_xlfn._xlws.FILTER(MAE_ASIGNATURA[NOM_ASIG],(MAE_ASIGNATURA[ID_NIVEL]=DET_ASIG!#REF!)*(MAE_ASIGNATURA[ID_CARRERA]=DET_ASIG!#REF!),"No existe información")))} -> #REF!
A19: {=TRANSPOSE(_xlfn.UNIQUE(_xlfn._xlws.FILTER(MAE_ASIGNATURA[ID_NIVEL],MAE_ASIGNATURA[ID_CARRERA]=DET_ASIG!#REF!,"No existe información")))} -> #REF! | O19: {=TRANSPOSE(_xlfn.UNIQUE(_xlfn._xlws.FILTER(MAE_ASIGNATURA[NOM_ASIG],(MAE_ASIGNATURA[ID_NIVEL]=DET_ASIG!#REF!)*(MAE_ASIGNATURA[ID_CARRERA]=DET_ASIG!#REF!),"No existe información")))} -> #REF!
A20: {=TRANSPOSE(_xlfn.UNIQUE(_xlfn._xlws.FILTER(MAE_ASIGNATURA[ID_NIVEL],MAE_ASIGNATURA[ID_CARRERA]=DET_ASIG!#REF!,"No existe información")))} -> #REF! | O20: {=TRANSPOSE(_xlfn.UNIQUE(_xlfn._xlws.FILTER(MAE_ASIGNATURA[NOM_ASIG],(MAE_ASIGNATURA[ID_NIVEL]=DET_ASIG!#REF!)*(MAE_ASIGNATURA[ID_CARRERA]=DET_ASIG!#REF!),"No existe información")))} -> #REF!
A21: {=TRANSPOSE(_xlfn.UNIQUE(_xlfn._xlws.FILTER(MAE_ASIGNATURA[ID_NIVEL],MAE_ASIGNATURA[ID_CARRERA]=DET_ASIG!#REF!,"No existe información")))} -> #REF! | O21: {=TRANSPOSE(_xlfn.UNIQUE(_xlfn._xlws.FILTER(MAE_ASIGNATURA[NOM_ASIG],(MAE_ASIGNATURA[ID_NIVEL]=DET_ASIG!#REF!)*(MAE_ASIGNATURA[ID_CARRERA]=DET_ASIG!#REF!),"No existe información")))} -> #REF!
A22: {=TRANSPOSE(_xlfn.UNIQUE(_xlfn._xlws.FILTER(MAE_ASIGNATURA[ID_NIVEL],MAE_ASIGNATURA[ID_CARRERA]=DET_ASIG!#REF!,"No existe información")))} -> #REF! | O22: {=TRANSPOSE(_xlfn.UNIQUE(_xlfn._xlws.FILTER(MAE_ASIGNATURA[NOM_ASIG],(MAE_ASIGNATURA[ID_NIVEL]=DET_ASIG!#REF!)*(MAE_ASIGNATURA[ID_CARRERA]=DET_ASIG!#REF!),"No existe información")))} -> #REF!
A23: {=TRANSPOSE(_xlfn.UNIQUE(_xlfn._xlws.FILTER(MAE_ASIGNATURA[ID_NIVEL],MAE_ASIGNATURA[ID_CARRERA]=DET_ASIG!#REF!,"No existe información")))} -> #REF! | O23: {=TRANSPOSE(_xlfn.UNIQUE(_xlfn._xlws.FILTER(MAE_ASIGNATURA[NOM_ASIG],(MAE_ASIGNATURA[ID_NIVEL]=DET_ASIG!#REF!)*(MAE_ASIGNATURA[ID_CARRERA]=DET_ASIG!#REF!),"No existe información")))} -> #REF!
A24: {=TRANSPOSE(_xlfn.UNIQUE(_xlfn._xlws.FILTER(MAE_ASIGNATURA[ID_NIVEL],MAE_ASIGNATURA[ID_CARRERA]=DET_ASIG!#REF!,"No existe información")))} -> #REF! | O24: {=TRANSPOSE(_xlfn.UNIQUE(_xlfn._xlws.FILTER(MAE_ASIGNATURA[NOM_ASIG],(MAE_ASIGNATURA[ID_NIVEL]=DET_ASIG!#REF!)*(MAE_ASIGNATURA[ID_CARRERA]=DET_ASIG!#REF!),"No existe información")))} -> #REF!
A25: {=TRANSPOSE(_xlfn.UNIQUE(_xlfn._xlws.FILTER(MAE_ASIGNATURA[ID_NIVEL],MAE_ASIGNATURA[ID_CARRERA]=DET_ASIG!#REF!,"No existe información")))} -> #REF! | O25: {=TRANSPOSE(_xlfn.UNIQUE(_xlfn._xlws.FILTER(MAE_ASIGNATURA[NOM_ASIG],(MAE_ASIGNATURA[ID_NIVEL]=DET_ASIG!#REF!)*(MAE_ASIGNATURA[ID_CARRERA]=DET_ASIG!#REF!),"No existe información")))} -> #REF!
A26: {=TRANSPOSE(_xlfn.UNIQUE(_xlfn._xlws.FILTER(MAE_ASIGNATURA[ID_NIVEL],MAE_ASIGNATURA[ID_CARRERA]=DET_ASIG!#REF!,"No existe información")))} -> #REF! | O26: {=TRANSPOSE(_xlfn.UNIQUE(_xlfn._xlws.FILTER(MAE_ASIGNATURA[NOM_ASIG],(MAE_ASIGNATURA[ID_NIVEL]=DET_ASIG!#REF!)*(MAE_ASIGNATURA[ID_CARRERA]=DET_ASIG!#REF!),"No existe información")))} -> #REF!
A27: {=TRANSPOSE(_xlfn.UNIQUE(_xlfn._xlws.FILTER(MAE_ASIGNATURA[ID_NIVEL],MAE_ASIGNATURA[ID_CARRERA]=DET_ASIG!#REF!,"No existe información")))} -> #REF! | O27: {=TRANSPOSE(_xlfn.UNIQUE(_xlfn._xlws.FILTER(MAE_ASIGNATURA[NOM_ASIG],(MAE_ASIGNATURA[ID_NIVEL]=DET_ASIG!#REF!)*(MAE_ASIGNATURA[ID_CARRERA]=DET_ASIG!#REF!),"No existe información")))} -> #REF!
A28: {=TRANSPOSE(_xlfn.UNIQUE(_xlfn._xlws.FILTER(MAE_ASIGNATURA[ID_NIVEL],MAE_ASIGNATURA[ID_CARRERA]=DET_ASIG!#REF!,"No existe información")))} -> #REF! | O28: {=TRANSPOSE(_xlfn.UNIQUE(_xlfn._xlws.FILTER(MAE_ASIGNATURA[NOM_ASIG],(MAE_ASIGNATURA[ID_NIVEL]=DET_ASIG!#REF!)*(MAE_ASIGNATURA[ID_CARRERA]=DET_ASIG!#REF!),"No existe información")))} -> #REF!
... A31: {=TRANSPOSE(_xlfn.UNIQUE(_xlfn._xlws.FILTER(MAE_ASIGNATURA[ID_NIVEL],MAE_ASIGNATURA[ID_CARRERA]=DET_ASIG!#REF!,"No existe información")))} -> #REF! | O31: {=TRANSPOSE(_xlfn.UNIQUE(_xlfn._xlws.FILTER(MAE_ASIGNATURA[NOM_ASIG],(MAE_ASIGNATURA[ID_NIVEL]=DET_ASIG!#REF!)*(MAE_ASIGNATURA[ID_CARRERA]=DET_ASIG!#REF!),"No existe información")))} -> #REF!
A32: {=TRANSPOSE(_xlfn.UNIQUE(_xlfn._xlws.FILTER(MAE_ASIGNATURA[ID_NIVEL],MAE_ASIGNATURA[ID_CARRERA]=DET_ASIG!$B17,"No existe información")))} -> 1 | B32: 2 | C32: 3 | D32: 4 | E32: 5 | F32: 6 | G32: 7 | H32: 8 | O32: {=TRANSPOSE(_xlfn.UNIQUE(_xlfn._xlws.FILTER(MAE_ASIGNATURA[NOM_ASIG],(MAE_ASIGNATURA[ID_NIVEL]=DET_ASIG!$D17)*(MAE_ASIGNATURA[ID_CARRERA]=DET_ASIG!$B17),"No existe información")))} -> CONTABILIDAD AVANZADA | P32: FUNDAMENTOS DE AUDITORÍA | Q32: ESTADÍSTICA APLICADA | R32: LEGISLACIÓN TRIBUTARIA | S32: SISTEMATIZACIÓN CONTABLE Y FINANCIERA | T32: PROCESO Y CONTROL DEL TALENTO HUMANO
A33: {=TRANSPOSE(_xlfn.UNIQUE(_xlfn._xlws.FILTER(MAE_ASIGNATURA[ID_NIVEL],MAE_ASIGNATURA[ID_CARRERA]=DET_ASIG!$B18,"No existe información")))} -> 1 | B33: 2 | C33: 3 | D33: 4 | E33: 5 | F33: 6 | G33: 7 | H33: 8 | O33: {=TRANSPOSE(_xlfn.UNIQUE(_xlfn._xlws.FILTER(MAE_ASIGNATURA[NOM_ASIG],(MAE_ASIGNATURA[ID_NIVEL]=DET_ASIG!$D18)*(MAE_ASIGNATURA[ID_CARRERA]=DET_ASIG!$B18),"No existe información")))} -> ADMINISTRACIÓN FINANCIERA | P33: CONTABILIDAD SUPERIOR | Q33: PLANIFICACIÓN Y DIRECCIÓN ESTRATÉGICA | R33: PLANIFICACIÓN DE AUDITORÍA | S33: TRIBUTACIÓN APLICADA
A34: {=TRANSPOSE(_xlfn.UNIQUE(_xlfn._xlws.FILTER(MAE_ASIGNATURA[ID_NIVEL],MAE_ASIGNATURA[ID_CARRERA]=DET_ASIG!$B19,"No existe información")))} -> 1 | B34: 2 | C34: 3 | D34: 4 | E34: 5 | F34: 6 | G34: 7 | H34: 8 | O34: {=TRANSPOSE(_xlfn.UNIQUE(_xlfn._xlws.FILTER(MAE_ASIGNATURA[NOM_ASIG],(MAE_ASIGNATURA[ID_NIVEL]=DET_ASIG!$D19)*(MAE_ASIGNATURA[ID_CARRERA]=DET_ASIG!$B19),"No existe información")))} -> ADMINISTRACIÓN FINANCIERA | P34: CONTABILIDAD SUPERIOR | Q34: PLANIFICACIÓN Y DIRECCIÓN ESTRATÉGICA | R34: PLANIFICACIÓN DE AUDITORÍA | S34: TRIBUTACIÓN APLICADA
A35: {=TRANSPOSE(_xlfn.UNIQUE(_xlfn._xlws.FILTER(MAE_ASIGNATURA[ID_NIVEL],MAE_ASIGNATURA[ID_CARRERA]=DET_ASIG!$B20,"No existe información")))} -> 1 | B35: 2 | C35: 3 | D35: 4 | E35: 5 | F35: 6 | G35: 7 | H35: 8 | O35: {=TRANSPOSE(_xlfn.UNIQUE(_xlfn._xlws.FILTER(MAE_ASIGNATURA[NOM_ASIG],(MAE_ASIGNATURA[ID_NIVEL]=DET_ASIG!$D20)*(MAE_ASIGNATURA[ID_CARRERA]=DET_ASIG!$B20),"No existe información")))} -> ADMINISTRACIÓN FINANCIERA | P35: CONTABILIDAD SUPERIOR | Q35: PLANIFICACIÓN Y DIRECCIÓN ESTRATÉGICA | R35: PLANIFICACIÓN DE AUDITORÍA | S35: TRIBUTACIÓN APLICADA
A36: {=TRANSPOSE(_xlfn.UNIQUE(_xlfn._xlws.FILTER(MAE_ASIGNATURA[ID_NIVEL],MAE_ASIGNATURA[ID_CARRERA]=DET_ASIG!$B21,"No existe información")))} -> 1 | B36: 2 | C36: 3 | D36: 4 | E36: 5 | F36: 6 | G36: 7 | H36: 8 | O36: {=TRANSPOSE(_xlfn.UNIQUE(_xlfn._xlws.FILTER(MAE_ASIGNATURA[NOM_ASIG],(MAE_ASIGNATURA[ID_NIVEL]=DET_ASIG!$D21)*(MAE_ASIGNATURA[ID_CARRERA]=DET_ASIG!$B21),"No existe información")))} -> ADMINISTRACIÓN FINANCIERA | P36: CONTABILIDAD SUPERIOR | Q36: PLANIFICACIÓN Y DIRECCIÓN ESTRATÉGICA | R36: PLANIFICACIÓN DE AUDITORÍA | S36: TRIBUTACIÓN APLICADA
A37: {=TRANSPOSE(_xlfn.UNIQUE(_xlfn._xlws.FILTER(MAE_ASIGNATURA[ID_NIVEL],MAE_ASIGNATURA[ID_CARRERA]=DET_ASIG!$B22,"No existe información")))} -> 1 | B37: 2 | C37: 3 | D37: 4 | E37: 5 | F37: 6 | G37: 7 | H37: 8 | O37: {=TRANSPOSE(_xlfn.UNIQUE(_xlfn._xlws.FILTER(MAE_ASIGNATURA[NOM_ASIG],(MAE_ASIGNATURA[ID_NIVEL]=DET_ASIG!$D22)*(MAE_ASIGNATURA[ID_CARRERA]=DET_ASIG!$B22),"No existe información")))} -> ADMINISTRACIÓN FINANCIERA | P37: CONTABILIDAD SUPERIOR | Q37: PLANIFICACIÓN Y DIRECCIÓN ESTRATÉGICA | R37: PLANIFICACIÓN DE AUDITORÍA | S37: TRIBUTACIÓN APLICADA
A38: {=TRANSPOSE(_xlfn.UNIQUE(_xlfn._xlws.FILTER(MAE_ASIGNATURA[ID_NIVEL],MAE_ASIGNATURA[ID_CARRERA]=DET_ASIG!$B23,"No existe información")))} -> 1 | B38: 2 | C38: 3 | D38: 4 | E38: 5 | F38: 6 | G38: 7 | H38: 8 | O38: {=TRANSPOSE(_xlfn.UNIQUE(_xlfn._xlws.FILTER(MAE_ASIGNATURA[NOM_ASIG],(MAE_ASIGNATURA[ID_NIVEL]=DET_ASIG!$D23)*(MAE_ASIGNATURA[ID_CARRERA]=DET_ASIG!$B23),"No existe información")))} -> ADMINISTRACIÓN FINANCIERA | P38: CONTABILIDAD SUPERIOR | Q38: PLANIFICACIÓN Y DIRECCIÓN ESTRATÉGICA | R38: PLANIFICACIÓN DE AUDITORÍA | S38: TRIBUTACIÓN APLICADA
A39: {=TRANSPOSE(_xlfn.UNIQUE(_xlfn._xlws.FILTER(MAE_ASIGNATURA[ID_NIVEL],MAE_ASIGNATURA[ID_CARRERA]=DET_ASIG!$B24,"No existe información")))} -> 1 | B39: 2 | C39: 3 | D39: 4 | E39: 5 | F39: 6 | G39: 7 | H39: 8 | O39: {=TRANSPOSE(_xlfn.UNIQUE(_xlfn._xlws.FILTER(MAE_ASIGNATURA[NOM_ASIG],(MAE_ASIGNATURA[ID_NIVEL]=DET_ASIG!$D24)*(MAE_ASIGNATURA[ID_CARRERA]=DET_ASIG!$B24),"No existe información")))} -> ADMINISTRACIÓN FINANCIERA | P39: CONTABILIDAD SUPERIOR | Q39: PLANIFICACIÓN Y DIRECCIÓN ESTRATÉGICA | R39: PLANIFICACIÓN DE AUDITORÍA | S39: TRIBUTACIÓN APLICADA
A40: {=TRANSPOSE(_xlfn.UNIQUE(_xlfn._xlws.FILTER(MAE_ASIGNATURA[ID_NIVEL],MAE_ASIGNATURA[ID_CARRERA]=DET_ASIG!$B25,"No existe información")))} -> 1 | B40: 2 | C40: 3 | D40: 4 | E40: 5 | F40: 6 | G40: 7 | H40: 8 | O40: {=TRANSPOSE(_xlfn.UNIQUE(_xlfn._xlws.FILTER(MAE_ASIGNATURA[NOM_ASIG],(MAE_ASIGNATURA[ID_NIVEL]=DET_ASIG!$D25)*(MAE_ASIGNATURA[ID_CARRERA]=DET_ASIG!$B25),"No existe información")))} -> CONTABILIDAD DE COSTOS | P40: CONTABILIDAD ESPECIALIZADA | Q40: AUDITORÍA FINANCIERA | R40: ORGANIZACIÓN Y MÉTODOS | S40: PRESUPUESTO
A41: {=TRANSPOSE(_xlfn.UNIQUE(_xlfn._xlws.FILTER(MAE_ASIGNATURA[ID_NIVEL],MAE_ASIGNATURA[ID_CARRERA]=DET_ASIG!$B26,"No existe información")))} -> 1 | B41: 2 | C41: 3 | D41: 4 | E41: 5 | F41: 6 | G41: 7 | H41: 8 | O41: {=TRANSPOSE(_xlfn.UNIQUE(_xlfn._xlws.FILTER(MAE_ASIGNATURA[NOM_ASIG],(MAE_ASIGNATURA[ID_NIVEL]=DET_ASIG!$D26)*(MAE_ASIGNATURA[ID_CARRERA]=DET_ASIG!$B26),"No existe información")))} -> CONTABILIDAD DE COSTOS | P41: CONTABILIDAD ESPECIALIZADA | Q41: AUDITORÍA FINANCIERA | R41: ORGANIZACIÓN Y MÉTODOS | S41: PRESUPUESTO
A42: {=TRANSPOSE(_xlfn.UNIQUE(_xlfn._xlws.FILTER(MAE_ASIGNATURA[ID_NIVEL],MAE_ASIGNATURA[ID_CARRERA]=DET_ASIG!$B27,"No existe información")))} -> 1 | B42: 2 | C42: 3 | D42: 4 | E42: 5 | F42: 6 | G42: 7 | H42: 8 | O42: {=TRANSPOSE(_xlfn.UNIQUE(_xlfn._xlws.FILTER(MAE_ASIGNATURA[NOM_ASIG],(MAE_ASIGNATURA[ID_NIVEL]=DET_ASIG!$D27)*(MAE_ASIGNATURA[ID_CARRERA]=DET_ASIG!$B27),"No existe información")))} -> CONTABILIDAD DE COSTOS | P42: CONTABILIDAD ESPECIALIZADA | Q42: AUDITORÍA FINANCIERA | R42: ORGANIZACIÓN Y MÉTODOS | S42: PRESUPUESTO
...

Sheet MAE_CARRERA
A1: ID_CARRERA | B1: NOMBRE_CARRERA | C1: SEMANAS | D1: TOTAL HORAS | E1: FECHA_INICIO | F1: FECHA_FIN | G1: ESTADO
A2: FCACC-AD-EM | B2: ADMINISTRACIÓN DE EMPRESAS | C2: 16 | D2: 240 | E2: 43831 | F2: 51501 | G2: Vigente
A3: FCACC-AU-CO-GE | B3: AUDITORÍA Y CONTROL DE GESTIÓN 2024 NS | C3: 16 | D3: 240 | E3: 43831 | F3: 51501 | G3: Vigente
A4: FCACC-BI-RA | B4: BIENES RAICES | C4: 16 | D4: 240 | E4: 43831 | F4: 51501 | G4: Vigente
A5: FCACC-CO-EX | B5: COMERCIO EXTERIOR | C5: 16 | D5: 240 | E5: 43831 | F5: 51501 | G5: Vigente
A6: FCACC-CO-AD | B6: CONTABILIDAD Y AUDITORÍA 2024 NS | C6: 16 | D6: 240 | E6: 43831 | F6: 51501 | G6: Vigente
A7: FCACC-FINA | B7: FINANZAS 2024 NS | C7: 16 | D7: 240 | E7: 43831 | F7: 51501 | G7: Vigente
A8: FCACC-GE-IN-GE | B8: GESTION DE LA INFORMACIÓN GERENCIA - 2024 | C8: 16 | D8: 240 | E8: 43831 | F8: 51501 | G8: Vigente
A9: FCACC-GE-TA-HU | B9: GESTIÓN DEL TALENTO HUMANO | C9: 16 | D9: 240 | E9: 43831 | F9: 51501 | G9: Vigente
A10: FCACC-MA | B10: MARKETING | C10: 16 | D10: 240 | E10: 43831 | F10: 51501 | G10: Vigente
A11: FCACC-1-DO-CL | B11: 1. Docencia - Clases | C11: 1 | D11: 1 | E11: 43831 | F11: 51501 | G11: Vigente
A12: FCACC-5-DO-PE-IN | B12: 5. Docencia - Uso pedagógico de la investigación | C12: 1 | D12: 1 | E12: 43831 | F12: 51501 | G12: Vigente
A13: FCACC-4-DO-TU-TI | B13: 4. Docencia - Tutoría de titulación | C13: 1 | D13: 1 | E13: 43831 | F13: 51501 | G13: Vigente
... A18: FCACC-8-TITU | B18: Titulación | C18: 1 | D18: 1 | E18: 43831 | F18: 51501 | G18: Vigente

Sheet MAE_ASIGNATURA
A1: ID_ASIG | B1: NOM_ASIG | C1: HORAS | D1: semanas | E1: ID_CARRERA | F1: NOMBRE_CARRERA | G1: ID_NIVEL
A2: FCACC-AD-EM-NI-1-CONTA-DE -COS | B2: CONTABILIDAD DE COSTOS | C2: 4 | D2: 16 | E2: FCACC-AD-EM | F2: ADMINISTRACIÓN DE EMPRESAS | G2: 1
A3: FCACC-AD-EM-NI-1-MATEM-APL-A L | B3: MATEMÁTICA APLICADA A LA ADMINISTRACIÓN | C3: 4 | D3: 16 | E3: FCACC-AD-EM | F3: ADMINISTRACIÓN DE EMPRESAS | G3: 1
A4: FCACC-AD-EM-NI-1-ADMIN-PAR-LOS | B4: ADMINISTRACIÓN PARA LOS NEGOCIOS | C4: 4 | D4: 16 | E4: FCACC-AD-EM | F4: ADMINISTRACIÓN DE EMPRESAS | G4: 1
A5: FCACC-AD-EM-NI-1-METOD-DE -LA | B5: METODOLOGÍA DE LA INVESTIGACIÓN | C5: 4 | D5: 16 | E5: FCACC-AD-EM | F5: ADMINISTRACIÓN DE EMPRESAS | G5: 1
A6: FCACC-AD-EM-NI-1-MICRO | B6: MICROECONOMÍA | C6: 4 | D6: 16 | E6: FCACC-AD-EM | F6: ADMINISTRACIÓN DE EMPRESAS | G6: 1
A7: FCACC-AD-EM-NI-2-CONTA-FIN | B7: CONTABILIDAD FINANCIERA | C7: 3 | D7: 16 | E7: FCACC-AD-EM | F7: ADMINISTRACIÓN DE EMPRESAS | G7: 2
A8: FCACC-AD-EM-NI-2-MATEM-FIN | B8: MATEMÁTICA FINANCIERA | C8: 4 | D8: 16 | E8: FCACC-AD-EM | F8: ADMINISTRACIÓN DE EMPRESAS | G8: 2
A9: FCACC-AD-EM-NI-2-ADMIN-EST | B9: ADMINISTRACIÓN ESTRATÉGICA | C9: 4 | D9: 16 | E9: FCACC-AD-EM | F9: ADMINISTRACIÓN DE EMPRESAS | G9: 2
A10: FCACC-AD-EM-NI-2-ESTAD-APL-A | B10: ESTADÍSTICA APLICADA A LA ADMINISTRACIÓN | C10: 3 | D10: 16 | E10: FCACC-AD-EM | F10: ADMINISTRACIÓN DE EMPRESAS | G10: 2
A11: FCACC-AD-EM-NI-2-MACRO | B11: MACROECONOMÍA | C11: 3 | D11: 16 | E11: FCACC-AD-EM | F11: ADMINISTRACIÓN DE EMPRESAS | G11: 2
A12: FCACC-AD-EM-NI-2-DEREC-MER-Y S | B12: DERECHO MERCANTIL Y SOCIETARIO | C12: 3 | D12: 16 | E12: FCACC-AD-EM | F12: ADMINISTRACIÓN DE EMPRESAS | G12: 2
A13: FCACC-AD-EM-NI-3-CREAT-E I-INN | B13: CREATIVIDAD E INNOVACIÓN EMPRESARIAL | C13: 4 | D13: 16 | E13: FCACC-AD-EM | F13: ADMINISTRACIÓN DE EMPRESAS | G13: 3
... A353: FCACC-8-TITU-NI-8-Traba-de -int | B353: Trabajo de integración curricular: Fase de resultados e informe CA-22 | C353: 1 | D353: 16 | E353: FCACC-8-TITU | F353: Titulación | G353: 8

Sheet MAE_CONOCIMIENTO
A1: ID_DDETALLADO | B1: CAMPO_DETALLADO
A2: F-C-D-ADM | B2: ADMINISTRACIÓN
A3: F-C-D-ADM-EN -E-C | B3: ADMINISTRACIÓN EN E-COMMERCE
A4: F-C-D-AUD-DE -TEC | B4: AUDITORÍA DE TECNOLOGÍAS
A5: F-C-D-BIB-DOC | B5: BIBLIOTECOLOGÍA, DOCUMENTACIÓN Y ARCHIVOLOGÍA
A6: F-C-D-CIE-COM | B6: CIENCIAS COMPUTACIONALES
A7: F-C-D-CIE-DEL-MED | B7: CIENCIAS DEL MEDIO AMBIENTE
A8: F-C-D-CIE-POL | B8: CIENCIAS POLÍTICAS
A9: F-C-D-COM | B9: COMERCIO
A10: F-C-D-COM-Y N-NEG | B10: COMERCIO Y NEGOCIOS INTERNACIONAL
A11: F-C-D-COM-LAB | B11: COMPETENCIAS LABORALES
A12: F-C-D-CON-Y A-AUD | B12: CONTABILIDAD Y AUDITORÍA
... A34: F-C-D-GES-DE -LA | B34: GESTIÓN DE LA CIENCIA Y LA TECNOLOGÍA
A35: F-C-D-
A36: F-C-D-
A37: F-C-D-
A38: F-C-D-
A39: F-C-D-
A40: F-C-D-
A41: F-C-D-
A42: F-C-D-
A43: F-C-D-
A44: F-C-D-
