Workbook

Sheet ASIGNACION
A1: N° | B1: CARRERA | C1: ID_CARRERA | D1: NIVEL | E1: PARALELO | F1: ASIGNATURA | G1: ID_ASIG_CAM_DET | H1: CAMPO | I1: AFINIDAD/DOCENCIA | J1: HORAS | K1: CALCULAR HORA | L1: TOTAL | M1: NOMBRE_DOCENT | N1: TIPO DOCENTE | O1: ESTUDIO DOCENTE | P1: TOTAL ASIGNATURA | Q1: HORAS NO AFINIDAD | R1: HORAS UNIDAD BASICA | S1: HORAS ACTIVIDAD | T1: HORAS AFINIDAD | U1: TOTAL HORAS CLASES | V1: TOTAL HORAS | W1: CEDULA_DOCENTE
A2: 1 | B2: CONTABILIDAD Y AUDITORÍA 2024 NS | C2: =_xlfn.XLOOKUP(Tabla1[[#This Row],[CARRERA]],MAE_CARRERA[NOMBRE_CARRERA],MAE_CARRERA[ID_CARRERA],"Seleccione Carrera") -> FCACC-CO-AD | D2: 1 | E2: A | F2: CONTABILIDAD BÁSICA | G2: =_xlfn.XLOOKUP(Tabla1[[#This Row],[ASIGNATURA]],MAE_ASIGNATURA[NOM_ASIG],MAE_ASIGNATURA[ID_ASIG],"Seleccione Asignatura") -> FCACC-CO-AD-NI-1-CONTA-BÁS | H2: {=_xlfn.TEXTJOIN("; ",TRUE,TRANSPOSE(_xlfn.UNIQUE(_xlfn._xlws.FILTER(DET_ASIG[DETALLADO],(DET_ASIG[NIVEL]=ASIGNACION!$D2)*(DET_ASIG[ID_CARRERA]=ASIGNACION!$C2)*(DET_ASIG[ID_ASIG]=ASIGNACION!$G2),"No existe información"))))} -> UNIDAD BASICA | I2: NO | J2: =_xlfn.XLOOKUP(Tabla1[[#This Row],[ID_ASIG_CAM_DET]],MAE_ASIGNATURA[ID_ASIG],MAE_ASIGNATURA[HORAS],0) -> 7 | K2: 1 | L2: =+Tabla1[[#This Row],[CALCULAR HORA]]*Tabla1[[#This Row],[HORAS]] -> 7 | M2: CACERES LARREATEGUI ALBA LUCIA | N2: =_xlfn.XLOOKUP(Tabla1[[#This Row],[NOMBRE_DOCENT]],MDOCENTES[DATOS_DOCENTE],MDOCENTES[DEDICACION],"Seleccione Docente") -> TC | O2: =_xlfn.XLOOKUP(Tabla1[[#This Row],[NOMBRE_DOCENT]],MDOCENTES[DATOS_DOCENTE],MDOCENTES[ESTUDIO],"Seleccione Docente") -> MAESTRÍA | P2: =COUNTIFS($M:$M, M2, $H:$H, "<>ACTIVIDAD") -> 4 | Q2: =SUMIFS($L:$L, $M:$M, M2, $I:$I, "NO",$H:$H,"<>UNIDAD BASICA") -> 0 | R2: =SUMIFS($L:$L, $M:$M, M2, $H:$H, "UNIDAD BASICA",$I:$I,"NO") -> 16 | S2: =SUMIFS($L:$L, $M:$M, M2, $I:$I, "ACTIVIDAD") -> 9 | T2: =SUMIFS($L:$L, $M:$M, M2, $I:$I, "SI") -> 0 | U2: =Tabla1[[#This Row],[HORAS NO AFINIDAD]]+Tabla1[[#This Row],[HORAS UNIDAD BASICA]]+Tabla1[[#This Row],[HORAS AFINIDAD]] -> 16 | V2: =+Tabla1[[#This Row],[HORAS AFINIDAD]]+Tabla1[[#This Row],[HORAS ACTIVIDAD]]+Tabla1[[#This Row],[HORAS UNIDAD BASICA]]+Tabla1[[#This Row],[HORAS NO AFINIDAD]] -> 25 | W2: =_xlfn.XLOOKUP(Tabla1[[#This Row],[NOMBRE_DOCENT]],EDU_DOCENTE[NOMBRE_DOCENTE],EDU_DOCENTE[IDENTIFICACION],"Seleccione Docente") -> Seleccione Docente
A3: 2 | B3: CONTABILIDAD Y AUDITORÍA 2024 NS | C3: =_xlfn.XLOOKUP(Tabla1[[#This Row],[CARRERA]],MAE_CARRERA[NOMBRE_CARRERA],MAE_CARRERA[ID_CARRERA],"Seleccione Carrera") -> FCACC-CO-AD | D3: 1 | E3: A | F3: METODOLOGÍA DE LA INVESTIGACIÓN | G3: =_xlfn.XLOOKUP(Tabla1[[#This Row],[ASIGNATURA]],MAE_ASIGNATURA[NOM_ASIG],MAE_ASIGNATURA[ID_ASIG],"Seleccione Asignatura") -> FCACC-AD-EM-NI-1-METOD-DE -LA | H3: {=_xlfn.TEXTJOIN("; ",TRUE,TRANSPOSE(_xlfn.UNIQUE(_xlfn._xlws.FILTER(DET_ASIG[DETALLADO],(DET_ASIG[NIVEL]=ASIGNACION!$D3)*(DET_ASIG[ID_CARRERA]=ASIGNACION!$C3)*(DET_ASIG[ID_ASIG]=ASIGNACION!$G3),"No existe información"))))} -> UNIDAD BASICA | I3: NO | J3: =_xlfn.XLOOKUP(Tabla1[[#This Row],[ID_ASIG_CAM_DET]],MAE_ASIGNATURA[ID_ASIG],MAE_ASIGNATURA[HORAS],0) -> 4 | K3: 1 | L3: =+Tabla1[[#This Row],[CALCULAR HORA]]*Tabla1[[#This Row],[HORAS]] -> 4 | M3: CARRILLO PICO FEDERICO AVELINO | N3: =_xlfn.XLOOKUP(Tabla1[[#This Row],[NOMBRE_DOCENT]],MDOCENTES[DATOS_DOCENTE],MDOCENTES[DEDICACION],"Seleccione Docente") -> TC | O3: =_xlfn.XLOOKUP(Tabla1[[#This Row],[NOMBRE_DOCENT]],MDOCENTES[DATOS_DOCENTE],MDOCENTES[ESTUDIO],"Seleccione Docente") -> MAESTRÍA | P3: =COUNTIFS($M:$M, M3, $H:$H, "<>ACTIVIDAD") -> 2 | Q3: =SUMIFS($L:$L, $M:$M, M3, $I:$I, "NO",$H:$H,"<>UNIDAD BASICA") -> 0 | R3: =SUMIFS($L:$L, $M:$M, M3, $H:$H, "UNIDAD BASICA",$I:$I,"NO") -> 8 | S3: =SUMIFS($L:$L, $M:$M, M3, $I:$I, "ACTIVIDAD") -> 0 | T3: =SUMIFS($L:$L, $M:$M, M3, $I:$I, "SI") -> 0 | U3: =Tabla1[[#This Row],[HORAS NO AFINIDAD]]+Tabla1[[#This Row],[HORAS UNIDAD BASICA]]+Tabla1[[#This Row],[HORAS AFINIDAD]] -> 8 | V3: =+Tabla1[[#This Row],[HORAS AFINIDAD]]+Tabla1[[#This Row],[HORAS ACTIVIDAD]]+Tabla1[[#This Row],[HORAS UNIDAD BASICA]]+Tabla1[[#This Row],[HORAS NO AFINIDAD]] -> 8 | W3: =_xlfn.XLOOKUP(Tabla1[[#This Row],[NOMBRE_DOCENT]],EDU_DOCENTE[NOMBRE_DOCENTE],EDU_DOCENTE[IDENTIFICACION],"Seleccione Docente") -> Seleccione Docente
A4: 3 | B4: CONTABILIDAD Y AUDITORÍA 2024 NS | C4: =_xlfn.XLOOKUP(Tabla1[[#This Row],[CARRERA]],MAE_CARRERA[NOMBRE_CARRERA],MAE_CARRERA[ID_CARRERA],"Seleccione Carrera") -> FCACC-CO-AD | D4: 1 | E4: A | F4: ADMINISTRACIÓN | G4: =_xlfn.XLOOKUP(Tabla1[[#This Row],[ASIGNATURA]],MAE_ASIGNATURA[NOM_ASIG],MAE_ASIGNATURA[ID_ASIG],"Seleccione Asignatura") -> FCACC-CO-AD-NI-1-ADMIN | H4: {=_xlfn.TEXTJOIN("; ",TRUE,TRANSPOSE(_xlfn.UNIQUE(_xlfn._xlws.FILTER(DET_ASIG[DETALLADO],(DET_ASIG[NIVEL]=ASIGNACION!$D4)*(DET_ASIG[ID_CARRERA]=ASIGNACION!$C4)*(DET_ASIG[ID_ASIG]=ASIGNACION!$G4),"No existe información"))))} -> UNIDAD BASICA | I4: NO | J4: =_xlfn.XLOOKUP(Tabla1[[#This Row],[ID_ASIG_CAM_DET]],MAE_ASIGNATURA[ID_ASIG],MAE_ASIGNATURA[HORAS],0) -> 2 | K4: 1 | L4: =+Tabla1[[#This Row],[CALCULAR HORA]]*Tabla1[[#This Row],[HORAS]] -> 2 | M4: CACERES LARREATEGUI ALBA LUCIA | N4: =_xlfn.XLOOKUP(Tabla1[[#This Row],[NOMBRE_DOCENT]],MDOCENTES[DATOS_DOCENTE],MDOCENTES[DEDICACION],"Seleccione Docente") -> TC | O4: =_xlfn.XLOOKUP(Tabla1[[#This Row],[NOMBRE_DOCENT]],MDOCENTES[DATOS_DOCENTE],MDOCENTES[ESTUDIO],"Seleccione Docente") -> MAESTRÍA | P4: =COUNTIFS($M:$M, M4, $H:$H, "<>ACTIVIDAD") -> 4 | Q4: =SUMIFS($L:$L, $M:$M, M4, $I:$I, "NO",$H:$H,"<>UNIDAD BASICA") -> 0 | R4: =SUMIFS($L:$L, $M:$M, M4, $H:$H, "UNIDAD BASICA",$I:$I,"NO") -> 16 | S4: =SUMIFS($L:$L, $M:$M, M4, $I:$I, "ACTIVIDAD") -> 9 | T4: =SUMIFS($L:$L, $M:$M, M4, $I:$I, "SI") -> 0 | U4: =Tabla1[[#This Row],[HORAS NO AFINIDAD]]+Tabla1[[#This Row],[HORAS UNIDAD BASICA]]+Tabla1[[#This Row],[HORAS AFINIDAD]] -> 16 | V4: =+Tabla1[[#This Row],[HORAS AFINIDAD]]+Tabla1[[#This Row],[HORAS ACTIVIDAD]]+Tabla1[[#This Row],[HORAS UNIDAD BASICA]]+Tabla1[[#This Row],[HORAS NO AFINIDAD]] -> 25 | W4: =_xlfn.XLOOKUP(Tabla1[[#This Row],[NOMBRE_DOCENT]],EDU_DOCENTE[NOMBRE_DOCENTE],EDU_DOCENTE[IDENTIFICACION],"Seleccione Docente") -> Seleccione Docente
A5: 4 | B5: CONTABILIDAD Y AUDITORÍA 2024 NS | C5: =_xlfn.XLOOKUP(Tabla1[[#This Row],[CARRERA]],MAE_CARRERA[NOMBRE_CARRERA],MAE_CARRERA[ID_CARRERA],"Seleccione Carrera") -> FCACC-CO-AD | D5: 1 | E5: B | F5: ADMINISTRACIÓN | G5: =_xlfn.XLOOKUP(Tabla1[[#This Row],[ASIGNATURA]],MAE_ASIGNATURA[NOM_ASIG],MAE_ASIGNATURA[ID_ASIG],"Seleccione Asignatura") -> FCACC-CO-AD-NI-1-ADMIN | H5: {=_xlfn.TEXTJOIN("; ",TRUE,TRANSPOSE(_xlfn.UNIQUE(_xlfn._xlws.FILTER(DET_ASIG[DETALLADO],(DET_ASIG[NIVEL]=ASIGNACION!$D5)*(DET_ASIG[ID_CARRERA]=ASIGNACION!$C5)*(DET_ASIG[ID_ASIG]=ASIGNACION!$G5),"No existe información"))))} -> UNIDAD BASICA | I5: NO | J5: =_xlfn.XLOOKUP(Tabla1[[#This Row],[ID_ASIG_CAM_DET]],MAE_ASIGNATURA[ID_ASIG],MAE_ASIGNATURA[HORAS],0) -> 2 | K5: 1 | L5: =+Tabla1[[#This Row],[CALCULAR HORA]]*Tabla1[[#This Row],[HORAS]] -> 2 | M5: CACERES LARREATEGUI ALBA LUCIA | N5: =_xlfn.XLOOKUP(Tabla1[[#This Row],[NOMBRE_DOCENT]],MDOCENTES[DATOS_DOCENTE],MDOCENTES[DEDICACION],"Seleccione Docente") -> TC | O5: =_xlfn.XLOOKUP(Tabla1[[#This Row],[NOMBRE_DOCENT]],MDOCENTES[DATOS_DOCENTE],MDOCENTES[ESTUDIO],"Seleccione Docente") -> MAESTRÍA | P5: =COUNTIFS($M:$M, M5, $H:$H, "<>ACTIVIDAD") -> 4 | Q5: =SUMIFS($L:$L, $M:$M, M5, $I:$I, "NO",$H:$H,"<>UNIDAD BASICA") -> 0 | R5: =SUMIFS($L:$L, $M:$M, M5, $H:$H, "UNIDAD BASICA",$I:$I,"NO") -> 16 | S5: =SUMIFS($L:$L, $M:$M, M5, $I:$I, "ACTIVIDAD") -> 9 | T5: =SUMIFS($L:$L, $M:$M, M5, $I:$I, "SI") -> 0 | U5: =Tabla1[[#This Row],[HORAS NO AFINIDAD]]+Tabla1[[#This Row],[HORAS UNIDAD BASICA]]+Tabla1[[#This Row],[HORAS AFINIDAD]] -> 16 | V5: =+Tabla1[[#This Row],[HORAS AFINIDAD]]+Tabla1[[#This Row],[HORAS ACTIVIDAD]]+Tabla1[[#This Row],[HORAS UNIDAD BASICA]]+Tabla1[[#This Row],[HORAS NO AFINIDAD]] -> 25 | W5: =_xlfn.XLOOKUP(Tabla1[[#This Row],[NOMBRE_DOCENT]],EDU_DOCENTE[NOMBRE_DOCENTE],EDU_DOCENTE[IDENTIFICACION],"Seleccione Docente") -> Seleccione Docente
A6: 5 | B6: CONTABILIDAD Y AUDITORÍA 2024 NS | C6: =_xlfn.XLOOKUP(Tabla1[[#This Row],[CARRERA]],MAE_CARRERA[NOMBRE_CARRERA],MAE_CARRERA[ID_CARRERA],"Seleccione Carrera") -> FCACC-CO-AD | D6: 1 | E6: B | F6: MATEMÁTICA | G6: =_xlfn.XLOOKUP(Tabla1[[#This Row],[ASIGNATURA]],MAE_ASIGNATURA[NOM_ASIG],MAE_ASIGNATURA[ID_ASIG],"Seleccione Asignatura") -> FCACC-CO-EX-NI-1-MATEM | H6: {=_xlfn.TEXTJOIN("; ",TRUE,TRANSPOSE(_xlfn.UNIQUE(_xlfn._xlws.FILTER(DET_ASIG[DETALLADO],(DET_ASIG[NIVEL]=ASIGNACION!$D6)*(DET_ASIG[ID_CARRERA]=ASIGNACION!$C6)*(DET_ASIG[ID_ASIG]=ASIGNACION!$G6),"No existe información"))))} -> UNIDAD BASICA | I6: NO | J6: =_xlfn.XLOOKUP(Tabla1[[#This Row],[ID_ASIG_CAM_DET]],MAE_ASIGNATURA[ID_ASIG],MAE_ASIGNATURA[HORAS],0) -> 5 | K6: 1 | L6: =+Tabla1[[#This Row],[CALCULAR HORA]]*Tabla1[[#This Row],[HORAS]] -> 5 | M6: CACERES LARREATEGUI ALBA LUCIA | N6: =_xlfn.XLOOKUP(Tabla1[[#This Row],[NOMBRE_DOCENT]],MDOCENTES[DATOS_DOCENTE],MDOCENTES[DEDICACION],"Seleccione Docente") -> TC | O6: =_xlfn.XLOOKUP(Tabla1[[#This Row],[NOMBRE_DOCENT]],MDOCENTES[DATOS_DOCENTE],MDOCENTES[ESTUDIO],"Seleccione Docente") -> MAESTRÍA | P6: =COUNTIFS($M:$M, M6, $H:$H, "<>ACTIVIDAD") -> 4 | Q6: =SUMIFS($L:$L, $M:$M, M6, $I:$I, "NO",$H:$H,"<>UNIDAD BASICA") -> 0 | R6: =SUMIFS($L:$L, $M:$M, M6, $H:$H, "UNIDAD BASICA",$I:$I,"NO") -> 16 | S6: =SUMIFS($L:$L, $M:$M, M6, $I:$I, "ACTIVIDAD") -> 9 | T6: =SUMIFS($L:$L, $M:$M, M6, $I:$I, "SI") -> 0 | U6: =Tabla1[[#This Row],[HORAS NO AFINIDAD]]+Tabla1[[#This Row],[HORAS UNIDAD BASICA]]+Tabla1[[#This Row],[HORAS AFINIDAD]] -> 16 | V6: =+Tabla1[[#This Row],[HORAS AFINIDAD]]+Tabla1[[#This Row],[HORAS ACTIVIDAD]]+Tabla1[[#This Row],[HORAS UNIDAD BASICA]]+Tabla1[[#This Row],[HORAS NO AFINIDAD]] -> 25 | W6: =_xlfn.XLOOKUP(Tabla1[[#This Row],[NOMBRE_DOCENT]],EDU_DOCENTE[NOMBRE_DOCENTE],EDU_DOCENTE[IDENTIFICACION],"Seleccione Docente") -> Seleccione Docente
A7: 6 | B7: CONTABILIDAD Y AUDITORÍA 2024 NS | C7: =_xlfn.XLOOKUP(Tabla1[[#This Row],[CARRERA]],MAE_CARRERA[NOMBRE_CARRERA],MAE_CARRERA[ID_CARRERA],"Seleccione Carrera") -> FCACC-CO-AD | D7: 1 | E7: A | F7: METODOLOGÍA DE LA INVESTIGACIÓN | G7: =_xlfn.XLOOKUP(Tabla1[[#This Row],[ASIGNATURA]],MAE_ASIGNATURA[NOM_ASIG],MAE_ASIGNATURA[ID_ASIG],"Seleccione Asignatura") -> FCACC-AD-EM-NI-1-METOD-DE -LA | H7: {=_xlfn.TEXTJOIN("; ",TRUE,TRANSPOSE(_xlfn.UNIQUE(_xlfn._xlws.FILTER(DET_ASIG[DETALLADO],(DET_ASIG[NIVEL]=ASIGNACION!$D7)*(DET_ASIG[ID_CARRERA]=ASIGNACION!$C7)*(DET_ASIG[ID_ASIG]=ASIGNACION!$G7),"No existe información"))))} -> UNIDAD BASICA | I7: NO | J7: =_xlfn.XLOOKUP(Tabla1[[#This Row],[ID_ASIG_CAM_DET]],MAE_ASIGNATURA[ID_ASIG],MAE_ASIGNATURA[HORAS],0) -> 4 | K7: 1 | L7: =+Tabla1[[#This Row],[CALCULAR HORA]]*Tabla1[[#This Row],[HORAS]] -> 4 | M7: CARRILLO PICO FEDERICO AVELINO | N7: =_xlfn.XLOOKUP(Tabla1[[#This Row],[NOMBRE_DOCENT]],MDOCENTES[DATOS_DOCENTE],MDOCENTES[DEDICACION],"Seleccione Docente") -> TC | O7: =_xlfn.XLOOKUP(Tabla1[[#This Row],[NOMBRE_DOCENT]],MDOCENTES[DATOS_DOCENTE],MDOCENTES[ESTUDIO],"Seleccione Docente") -> MAESTRÍA | P7: =COUNTIFS($M:$M, M7, $H:$H, "<>ACTIVIDAD") -> 2 | Q7: =SUMIFS($L:$L, $M:$M, M7, $I:$I, "NO",$H:$H,"<>UNIDAD BASICA") -> 0 | R7: =SUMIFS($L:$L, $M:$M, M7, $H:$H, "UNIDAD BASICA",$I:$I,"NO") -> 8 | S7: =SUMIFS($L:$L, $M:$M, M7, $I:$I, "ACTIVIDAD") -> 0 | T7: =SUMIFS($L:$L, $M:$M, M7, $I:$I, "SI") -> 0 | U7: =Tabla1[[#This Row],[HORAS NO AFINIDAD]]+Tabla1[[#This Row],[HORAS UNIDAD BASICA]]+Tabla1[[#This Row],[HORAS AFINIDAD]] -> 8 | V7: =+Tabla1[[#This Row],[HORAS AFINIDAD]]+Tabla1[[#This Row],[HORAS ACTIVIDAD]]+Tabla1[[#This Row],[HORAS UNIDAD BASICA]]+Tabla1[[#This Row],[HORAS NO AFINIDAD]] -> 8 | W7: =_xlfn.XLOOKUP(Tabla1[[#This Row],[NOMBRE_DOCENT]],EDU_DOCENTE[NOMBRE_DOCENTE],EDU_DOCENTE[IDENTIFICACION],"Seleccione Docente") -> Seleccione Docente
A8: 7 | B8: 1. Docencia - Clases | C8: =_xlfn.XLOOKUP(Tabla1[[#This Row],[CARRERA]],MAE_CARRERA[NOMBRE_CARRERA],MAE_CARRERA[ID_CARRERA],"Seleccione Carrera") -> FCACC-1-DO-CL | D8: 0 | F8: AD4 Preparación de Clases | G8: =_xlfn.XLOOKUP(Tabla1[[#This Row],[ASIGNATURA]],MAE_ASIGNATURA[NOM_ASIG],MAE_ASIGNATURA[ID_ASIG],"Seleccione Asignatura") -> FCACC-1-DO-CL-NI-0-AD4 P-Pre-de | H8: {=_xlfn.TEXTJOIN("; ",TRUE,TRANSPOSE(_xlfn.UNIQUE(_xlfn._xlws.FILTER(DET_ASIG[DETALLADO],(DET_ASIG[NIVEL]=ASIGNACION!$D8)*(DET_ASIG[ID_CARRERA]=ASIGNACION!$C8)*(DET_ASIG[ID_ASIG]=ASIGNACION!$G8),"No existe información"))))} -> ACTIVIDAD | I8: ACTIVIDAD | J8: =_xlfn.XLOOKUP(Tabla1[[#This Row],[ID_ASIG_CAM_DET]],MAE_ASIGNATURA[ID_ASIG],MAE_ASIGNATURA[HORAS],0) -> 1 | K8: 3 | L8: =+Tabla1[[#This Row],[CALCULAR HORA]]*Tabla1[[#This Row],[HORAS]] -> 3 | M8: CACERES LARREATEGUI ALBA LUCIA | N8: =_xlfn.XLOOKUP(Tabla1[[#This Row],[NOMBRE_DOCENT]],MDOCENTES[DATOS_DOCENTE],MDOCENTES[DEDICACION],"Seleccione Docente") -> TC | O8: =_xlfn.XLOOKUP(Tabla1[[#This Row],[NOMBRE_DOCENT]],MDOCENTES[DATOS_DOCENTE],MDOCENTES[ESTUDIO],"Seleccione Docente") -> MAESTRÍA | P8: =COUNTIFS($M:$M, M8, $H:$H, "<>ACTIVIDAD") -> 4 | Q8: =SUMIFS($L:$L, $M:$M, M8, $I:$I, "NO",$H:$H,"<>UNIDAD BASICA") -> 0 | R8: =SUMIFS($L:$L, $M:$M, M8, $H:$H, "UNIDAD BASICA",$I:$I,"NO") -> 16 | S8: =SUMIFS($L:$L, $M:$M, M8, $I:$I, "ACTIVIDAD") -> 9 | T8: =SUMIFS($L:$L, $M:$M, M8, $I:$I, "SI") -> 0 | U8: =Tabla1[[#This Row],[HORAS NO AFINIDAD]]+Tabla1[[#This Row],[HORAS UNIDAD BASICA]]+Tabla1[[#This Row],[HORAS AFINIDAD]] -> 16 | V8: =+Tabla1[[#This Row],[HORAS AFINIDAD]]+Tabla1[[#This Row],[HORAS ACTIVIDAD]]+Tabla1[[#This Row],[HORAS UNIDAD BASICA]]+Tabla1[[#This Row],[HORAS NO AFINIDAD]] -> 25 | W8: =_xlfn.XLOOKUP(Tabla1[[#This Row],[NOMBRE_DOCENT]],EDU_DOCENTE[NOMBRE_DOCENTE],EDU_DOCENTE[IDENTIFICACION],"Seleccione Docente") -> Seleccione Docente
A9: 8 | B9: 1. Docencia - Clases | C9: =_xlfn.XLOOKUP(Tabla1[[#This Row],[CARRERA]],MAE_CARRERA[NOMBRE_CARRERA],MAE_CARRERA[ID_CARRERA],"Seleccione Carrera") -> FCACC-1-DO-CL | D9: 0 | F9: AD5 Elaboración y calificación de evaluaciones | G9: =_xlfn.XLOOKUP(Tabla1[[#This Row],[ASIGNATURA]],MAE_ASIGNATURA[NOM_ASIG],MAE_ASIGNATURA[ID_ASIG],"Seleccione Asignatura") -> FCACC-1-DO-CL-NI-0-AD5 E-Ela-y c | H9: {=_xlfn.TEXTJOIN("; ",TRUE,TRANSPOSE(_xlfn.UNIQUE(_xlfn._xlws.FILTER(DET_ASIG[DETALLADO],(DET_ASIG[NIVEL]=ASIGNACION!$D9)*(DET_ASIG[ID_CARRERA]=ASIGNACION!$C9)*(DET_ASIG[ID_ASIG]=ASIGNACION!$G9),"No existe información"))))} -> ACTIVIDAD | I9: ACTIVIDAD | J9: =_xlfn.XLOOKUP(Tabla1[[#This Row],[ID_ASIG_CAM_DET]],MAE_ASIGNATURA[ID_ASIG],MAE_ASIGNATURA[HORAS],0) -> 1 | K9: 3 | L9: =+Tabla1[[#This Row],[CALCULAR HORA]]*Tabla1[[#This Row],[HORAS]] -> 3 | M9: CACERES LARREATEGUI ALBA LUCIA | N9: =_xlfn.XLOOKUP(Tabla1[[#This Row],[NOMBRE_DOCENT]],MDOCENTES[DATOS_DOCENTE],MDOCENTES[DEDICACION],"Seleccione Docente") -> TC | O9: =_xlfn.XLOOKUP(Tabla1[[#This Row],[NOMBRE_DOCENT]],MDOCENTES[DATOS_DOCENTE],MDOCENTES[ESTUDIO],"Seleccione Docente") -> MAESTRÍA | P9: =COUNTIFS($M:$M, M9, $H:$H, "<>ACTIVIDAD") -> 4 | Q9: =SUMIFS($L:$L, $M:$M, M9, $I:$I, "NO",$H:$H,"<>UNIDAD BASICA") -> 0 | R9: =SUMIFS($L:$L, $M:$M, M9, $H:$H, "UNIDAD BASICA",$I:$I,"NO") -> 16 | S9: =SUMIFS($L:$L, $M:$M, M9, $I:$I, "ACTIVIDAD") -> 9 | T9: =SUMIFS($L:$L, $M:$M, M9, $I:$I, "SI") -> 0 | U9: =Tabla1[[#This Row],[HORAS NO AFINIDAD]]+Tabla1[[#This Row],[HORAS UNIDAD BASICA]]+Tabla1[[#This Row],[HORAS AFINIDAD]] -> 16 | V9: =+Tabla1[[#This Row],[HORAS AFINIDAD]]+Tabla1[[#This Row],[HORAS ACTIVIDAD]]+Tabla1[[#This Row],[HORAS UNIDAD BASICA]]+Tabla1[[#This Row],[HORAS NO AFINIDAD]] -> 25
A10: 9 | B10: 1. Docencia - Clases | C10: =_xlfn.XLOOKUP(Tabla1[[#This Row],[CARRERA]],MAE_CARRERA[NOMBRE_CARRERA],MAE_CARRERA[ID_CARRERA],"Seleccione Carrera") -> FCACC-1-DO-CL | D10: 0 | F10: AD6 Orientación a través de Tutorías | G10: =_xlfn.XLOOKUP(Tabla1[[#This Row],[ASIGNATURA]],MAE_ASIGNATURA[NOM_ASIG],MAE_ASIGNATURA[ID_ASIG],"Seleccione Asignatura") -> FCACC-1-DO-CL-NI-0-AD6 O-Ori-a t | H10: {=_xlfn.TEXTJOIN("; ",TRUE,TRANSPOSE(_xlfn.UNIQUE(_xlfn._xlws.FILTER(DET_ASIG[DETALLADO],(DET_ASIG[NIVEL]=ASIGNACION!$D10)*(DET_ASIG[ID_CARRERA]=ASIGNACION!$C10)*(DET_ASIG[ID_ASIG]=ASIGNACION!$G10),"No existe información"))))} -> ACTIVIDAD | I10: ACTIVIDAD | J10: =_xlfn.XLOOKUP(Tabla1[[#This Row],[ID_ASIG_CAM_DET]],MAE_ASIGNATURA[ID_ASIG],MAE_ASIGNATURA[HORAS],0) -> 1 | K10: 3 | L10: =+Tabla1[[#This Row],[CALCULAR HORA]]*Tabla1[[#This Row],[HORAS]] -> 3 | M10: CACERES LARREATEGUI ALBA LUCIA | N10: =_xlfn.XLOOKUP(Tabla1[[#This Row],[NOMBRE_DOCENT]],MDOCENTES[DATOS_DOCENTE],MDOCENTES[DEDICACION],"Seleccione Docente") -> TC | O10: =_xlfn.XLOOKUP(Tabla1[[#This Row],[NOMBRE_DOCENT]],MDOCENTES[DATOS_DOCENTE],MDOCENTES[ESTUDIO],"Seleccione Docente") -> MAESTRÍA | P10: =COUNTIFS($M:$M, M10, $H:$H, "<>ACTIVIDAD") -> 4 | Q10: =SUMIFS($L:$L, $M:$M, M10, $I:$I, "NO",$H:$H,"<>UNIDAD BASICA") -> 0 | R10: =SUMIFS($L:$L, $M:$M, M10, $H:$H, "UNIDAD BASICA",$I:$I,"NO") -> 16 | S10: =SUMIFS($L:$L, $M:$M, M10, $I:$I, "ACTIVIDAD") -> 9 | T10: =SUMIFS($L:$L, $M:$M, M10, $I:$I, "SI") -> 0 | U10: =Tabla1[[#This Row],[HORAS NO AFINIDAD]]+Tabla1[[#This Row],[HORAS UNIDAD BASICA]]+Tabla1[[#This Row],[HORAS AFINIDAD]] -> 16 | V10: =+Tabla1[[#This Row],[HORAS AFINIDAD]]+Tabla1[[#This Row],[HORAS ACTIVIDAD]]+Tabla1[[#This Row],[HORAS UNIDAD BASICA]]+Tabla1[[#This Row],[HORAS NO AFINIDAD]] -> 25
A11: 10 | B11: CONTABILIDAD Y AUDITORÍA 2024 NS | C11: =_xlfn.XLOOKUP(Tabla1[[#This Row],[CARRERA]],MAE_CARRERA[NOMBRE_CARRERA],MAE_CARRERA[ID_CARRERA],"Seleccione Carrera") -> FCACC-CO-AD | D11: 2 | F11: ESTADÍSTICA DESCRIPTIVA | G11: =_xlfn.XLOOKUP(Tabla1[[#This Row],[ASIGNATURA]],MAE_ASIGNATURA[NOM_ASIG],MAE_ASIGNATURA[ID_ASIG],"Seleccione Asignatura") -> FCACC-AU-CO-GE-NI-1-ESTAD-DES | H11: {=_xlfn.TEXTJOIN("; ",TRUE,TRANSPOSE(_xlfn.UNIQUE(_xlfn._xlws.FILTER(DET_ASIG[DETALLADO],(DET_ASIG[NIVEL]=ASIGNACION!$D11)*(DET_ASIG[ID_CARRERA]=ASIGNACION!$C11)*(DET_ASIG[ID_ASIG]=ASIGNACION!$G11),"No existe información"))))} -> UNIDAD BASICA | I11: NO | J11: =_xlfn.XLOOKUP(Tabla1[[#This Row],[ID_ASIG_CAM_DET]],MAE_ASIGNATURA[ID_ASIG],MAE_ASIGNATURA[HORAS],0) -> 2 | K11: 8 | L11: =+Tabla1[[#This Row],[CALCULAR HORA]]*Tabla1[[#This Row],[HORAS]] -> 16 | M11: ARAUZ CHAVEZ MARIO ROBERTO | N11: =_xlfn.XLOOKUP(Tabla1[[#This Row],[NOMBRE_DOCENT]],MDOCENTES[DATOS_DOCENTE],MDOCENTES[DEDICACION],"Seleccione Docente") -> TC | O11: =_xlfn.XLOOKUP(Tabla1[[#This Row],[NOMBRE_DOCENT]],MDOCENTES[DATOS_DOCENTE],MDOCENTES[ESTUDIO],"Seleccione Docente") -> MAESTRÍA | P11: =COUNTIFS($M:$M, M11, $H:$H, "<>ACTIVIDAD") -> 1 | Q11: =SUMIFS($L:$L, $M:$M, M11, $I:$I, "NO",$H:$H,"<>UNIDAD BASICA") -> 0 | R11: =SUMIFS($L:$L, $M:$M, M11, $H:$H, "UNIDAD BASICA",$I:$I,"NO") -> 16 | S11: =SUMIFS($L:$L, $M:$M, M11, $I:$I, "ACTIVIDAD") -> 0 | T11: =SUMIFS($L:$L, $M:$M, M11, $I:$I, "SI") -> 0 | U11: =Tabla1[[#This Row],[HORAS NO AFINIDAD]]+Tabla1[[#This Row],[HORAS UNIDAD BASICA]]+Tabla1[[#This Row],[HORAS AFINIDAD]] -> 16 | V11: =+Tabla1[[#This Row],[HORAS AFINIDAD]]+Tabla1[[#This Row],[HORAS ACTIVIDAD]]+Tabla1[[#This Row],[HORAS UNIDAD BASICA]]+Tabla1[[#This Row],[HORAS NO AFINIDAD]] -> 16
A12: 11 | C12: =_xlfn.XLOOKUP(Tabla1[[#This Row],[CARRERA]],MAE_CARRERA[NOMBRE_CARRERA],MAE_CARRERA[ID_CARRERA],"Seleccione Carrera") -> Seleccione Carrera | G12: =_xlfn.XLOOKUP(Tabla1[[#This Row],[ASIGNATURA]],MAE_ASIGNATURA[NOM_ASIG],MAE_ASIGNATURA[ID_ASIG],"Seleccione Asignatura") -> Seleccione Asignatura | H12: {=_xlfn.TEXTJOIN("; ",TRUE,TRANSPOSE(_xlfn.UNIQUE(_xlfn._xlws.FILTER(DET_ASIG[DETALLADO],(DET_ASIG[NIVEL]=ASIGNACION!$D12)*(DET_ASIG[ID_CARRERA]=ASIGNACION!$C12)*(DET_ASIG[ID_ASIG]=ASIGNACION!$G12),"No existe información"))))} -> No existe información | J12: =_xlfn.XLOOKUP(Tabla1[[#This Row],[ID_ASIG_CAM_DET]],MAE_ASIGNATURA[ID_ASIG],MAE_ASIGNATURA[HORAS],0) -> 0 | K12: 4 | L12: =+Tabla1[[#This Row],[CALCULAR HORA]]*Tabla1[[#This Row],[HORAS]] -> 0 | N12: =_xlfn.XLOOKUP(Tabla1[[#This Row],[NOMBRE_DOCENT]],MDOCENTES[DATOS_DOCENTE],MDOCENTES[DEDICACION],"Seleccione Docente") -> Seleccione Docente | O12: =_xlfn.XLOOKUP(Tabla1[[#This Row],[NOMBRE_DOCENT]],MDOCENTES[DATOS_DOCENTE],MDOCENTES[ESTUDIO],"Seleccione Docente") -> Seleccione Docente | P12: =COUNTIFS($M:$M, M12, $H:$H, "<>ACTIVIDAD") -> 0 | Q12: =SUMIFS($L:$L, $M:$M, M12, $I:$I, "NO",$H:$H,"<>UNIDAD BASICA") -> 0 | R12: =SUMIFS($L:$L, $M:$M, M12, $H:$H, "UNIDAD BASICA",$I:$I,"NO") -> 0 | S12: =SUMIFS($L:$L, $M:$M, M12, $I:$I, "ACTIVIDAD") -> 0 | T12: =SUMIFS($L:$L, $M:$M, M12, $I:$I, "SI") -> 0 | U12: =Tabla1[[#This Row],[HORAS NO AFINIDAD]]+Tabla1[[#This Row],[HORAS UNIDAD BASICA]]+Tabla1[[#This Row],[HORAS AFINIDAD]] -> 0 | V12: =+Tabla1[[#This Row],[HORAS AFINIDAD]]+Tabla1[[#This Row],[HORAS ACTIVIDAD]]+Tabla1[[#This Row],[HORAS UNIDAD BASICA]]+Tabla1[[#This Row],[HORAS NO AFINIDAD]] -> 0
A13: 12 | C13: =_xlfn.XLOOKUP(Tabla1[[#This Row],[CARRERA]],MAE_CARRERA[NOMBRE_CARRERA],MAE_CARRERA[ID_CARRERA],"Seleccione Carrera") -> Seleccione Carrera | G13: =_xlfn.XLOOKUP(Tabla1[[#This Row],[ASIGNATURA]],MAE_ASIGNATURA[NOM_ASIG],MAE_ASIGNATURA[ID_ASIG],"Seleccione Asignatura") -> Seleccione Asignatura | H13: {=_xlfn.TEXTJOIN("; ",TRUE,TRANSPOSE(_xlfn.UNIQUE(_xlfn._xlws.FILTER(DET_ASIG[DETALLADO],(DET_ASIG[NIVEL]=ASIGNACION!$D13)*(DET_ASIG[ID_CARRERA]=ASIGNACION!$C13)*(DET_ASIG[ID_ASIG]=ASIGNACION!$G13),"No existe información"))))} -> No existe información | J13: =_xlfn.XLOOKUP(Tabla1[[#This Row],[ID_ASIG_CAM_DET]],MAE_ASIGNATURA[ID_ASIG],MAE_ASIGNATURA[HORAS],0) -> 0 | K13: 4 | L13: =+Tabla1[[#This Row],[CALCULAR HORA]]*Tabla1[[#This Row],[HORAS]] -> 0 | N13: =_xlfn.XLOOKUP(Tabla1[[#This Row],[NOMBRE_DOCENT]],MDOCENTES[DATOS_DOCENTE],MDOCENTES[DEDICACION],"Seleccione Docente") -> Seleccione Docente | O13: =_xlfn.XLOOKUP(Tabla1[[#This Row],[NOMBRE_DOCENT]],MDOCENTES[DATOS_DOCENTE],MDOCENTES[ESTUDIO],"Seleccione Docente") -> Seleccione Docente | P13: =COUNTIFS($M:$M, M13, $H:$H, "<>ACTIVIDAD") -> 0 | Q13: =SUMIFS($L:$L, $M:$M, M13, $I:$I, "NO",$H:$H,"<>UNIDAD BASICA") -> 0 | R13: =SUMIFS($L:$L, $M:$M, M13, $H:$H, "UNIDAD BASICA",$I:$I,"NO") -> 0 | S13: =SUMIFS($L:$L, $M:$M, M13, $I:$I, "ACTIVIDAD") -> 0 | T13: =SUMIFS($L:$L, $M:$M, M13, $I:$I, "SI") -> 0 | U13: =Tabla1[[#This Row],[HORAS NO AFINIDAD]]+Tabla1[[#This Row],[HORAS UNIDAD BASICA]]+Tabla1[[#This Row],[HORAS AFINIDAD]] -> 0 | V13: =+Tabla1[[#This Row],[HORAS AFINIDAD]]+Tabla1[[#This Row],[HORAS ACTIVIDAD]]+Tabla1[[#This Row],[HORAS UNIDAD BASICA]]+Tabla1[[#This Row],[HORAS NO AFINIDAD]] -> 0
A14: 13 | C14: =_xlfn.XLOOKUP(Tabla1[[#This Row],[CARRERA]],MAE_CARRERA[NOMBRE_CARRERA],MAE_CARRERA[ID_CARRERA],"Seleccione Carrera") -> Seleccione Carrera | G14: =_xlfn.XLOOKUP(Tabla1[[#This Row],[ASIGNATURA]],MAE_ASIGNATURA[NOM_ASIG],MAE_ASIGNATURA[ID_ASIG],"Seleccione Asignatura") -> Seleccione Asignatura | H14: {=_xlfn.TEXTJOIN("; ",TRUE,TRANSPOSE(_xlfn.UNIQUE(_xlfn._xlws.FILTER(DET_ASIG[DETALLADO],(DET_ASIG[NIVEL]=ASIGNACION!$D14)*(DET_ASIG[ID_CARRERA]=ASIGNACION!$C14)*(DET_ASIG[ID_ASIG]=ASIGNACION!$G14),"No existe información"))))} -> No existe información | J14: =_xlfn.XLOOKUP(Tabla1[[#This Row],[ID_ASIG_CAM_DET]],MAE_ASIGNATURA[ID_ASIG],MAE_ASIGNATURA[HORAS],0) -> 0 | K14: 4 | L14: =+Tabla1[[#This Row],[CALCULAR HORA]]*Tabla1[[#This Row],[HORAS]] -> 0 | N14: =_xlfn.XLOOKUP(Tabla1[[#This Row],[NOMBRE_DOCENT]],MDOCENTES[DATOS_DOCENTE],MDOCENTES[DEDICACION],"Seleccione Docente") -> Seleccione Docente | O14: =_xlfn.XLOOKUP(Tabla1[[#This Row],[NOMBRE_DOCENT]],MDOCENTES[DATOS_DOCENTE],MDOCENTES[ESTUDIO],"Seleccione Docente") -> Seleccione Docente | P14: =COUNTIFS($M:$M, M14, $H:$H, "<>ACTIVIDAD") -> 0 | Q14: =SUMIFS($L:$L, $M:$M, M14, $I:$I, "NO",$H:$H,"<>UNIDAD BASICA") -> 0 | R14: =SUMIFS($L:$L, $M:$M, M14, $H:$H, "UNIDAD BASICA",$I:$I,"NO") -> 0 | S14: =SUMIFS($L:$L, $M:$M, M14, $I:$I, "ACTIVIDAD") -> 0 | T14: =SUMIFS($L:$L, $M:$M, M14, $I:$I, "SI") -> 0 | U14: =Tabla1[[#This Row],[HORAS NO AFINIDAD]]+Tabla1[[#This Row],[HORAS UNIDAD BASICA]]+Tabla1[[#This Row],[HORAS AFINIDAD]] -> 0 | V14: =+Tabla1[[#This Row],[HORAS AFINIDAD]]+Tabla1[[#This Row],[HORAS ACTIVIDAD]]+Tabla1[[#This Row],[HORAS UNIDAD BASICA]]+Tabla1[[#This Row],[HORAS NO AFINIDAD]] -> 0
A15: 14 | C15: =_xlfn.XLOOKUP(Tabla1[[#This Row],[CARRERA]],MAE_CARRERA[NOMBRE_CARRERA],MAE_CARRERA[ID_CARRERA],"Seleccione Carrera") -> Seleccione Carrera | G15: =_xlfn.XLOOKUP(Tabla1[[#This Row],[ASIGNATURA]],MAE_ASIGNATURA[NOM_ASIG],MAE_ASIGNATURA[ID_ASIG],"Seleccione Asignatura") -> Seleccione Asignatura | H15: {=_xlfn.TEXTJOIN("; ",TRUE,TRANSPOSE(_xlfn.UNIQUE(_xlfn._xlws.FILTER(DET_ASIG[DETALLADO],(DET_ASIG[NIVEL]=ASIGNACION!$D15)*(DET_ASIG[ID_CARRERA]=ASIGNACION!$C15)*(DET_ASIG[ID_ASIG]=ASIGNACION!$G15),"No existe información"))))} -> No existe información | J15: =_xlfn.XLOOKUP(Tabla1[[#This Row],[ID_ASIG_CAM_DET]],MAE_ASIGNATURA[ID_ASIG],MAE_ASIGNATURA[HORAS],0) -> 0 | K15: 4 | L15: =+Tabla1[[#This Row],[CALCULAR HORA]]*Tabla1[[#This Row],[HORAS]] -> 0 | N15: =_xlfn.XLOOKUP(Tabla1[[#This Row],[NOMBRE_DOCENT]],MDOCENTES[DATOS_DOCENTE],MDOCENTES[DEDICACION],"Seleccione Docente") -> Seleccione Docente | O15: =_xlfn.XLOOKUP(Tabla1[[#This Row],[NOMBRE_DOCENT]],MDOCENTES[DATOS_DOCENTE],MDOCENTES[ESTUDIO],"Seleccione Docente") -> Seleccione Docente | P15: =COUNTIFS($M:$M, M15, $H:$H, "<>ACTIVIDAD") -> 0 | Q15: =SUMIFS($L:$L, $M:$M, M15, $I:$I, "NO",$H:$H,"<>UNIDAD BASICA") -> 0 | R15: =SUMIFS($L:$L, $M:$M, M15, $H:$H, "UNIDAD BASICA",$I:$I,"NO") -> 0 | S15: =SUMIFS($L:$L, $M:$M, M15, $I:$I, "ACTIVIDAD") -> 0 | T15: =SUMIFS($L:$L, $M:$M, M15, $I:$I, "SI") -> 0 | U15: =Tabla1[[#This Row],[HORAS NO AFINIDAD]]+Tabla1[[#This Row],[HORAS UNIDAD BASICA]]+Tabla1[[#This Row],[HORAS AFINIDAD]] -> 0 | V15: =+Tabla1[[#This Row],[HORAS AFINIDAD]]+Tabla1[[#This Row],[HORAS ACTIVIDAD]]+Tabla1[[#This Row],[HORAS UNIDAD BASICA]]+Tabla1[[#This Row],[HORAS NO AFINIDAD]] -> 0
A16: 15 | C16: =_xlfn.XLOOKUP(Tabla1[[#This Row],[CARRERA]],MAE_CARRERA[NOMBRE_CARRERA],MAE_CARRERA[ID_CARRERA],"Seleccione Carrera") -> Seleccione Carrera | G16: =_xlfn.XLOOKUP(Tabla1[[#This Row],[ASIGNATURA]],MAE_ASIGNATURA[NOM_ASIG],MAE_ASIGNATURA[ID_ASIG],"Seleccione Asignatura") -> Seleccione Asignatura | H16: {=_xlfn.TEXTJOIN("; ",TRUE,TRANSPOSE(_xlfn.UNIQUE(_xlfn._xlws.FILTER(DET_ASIG[DETALLADO],(DET_ASIG[NIVEL]=ASIGNACION!$D16)*(DET_ASIG[ID_CARRERA]=ASIGNACION!$C16)*(DET_ASIG[ID_ASIG]=ASIGNACION!$G16),"No existe información"))))} -> No existe información | J16: =_xlfn.XLOOKUP(Tabla1[[#This Row],[ID_ASIG_CAM_DET]],MAE_ASIGNATURA[ID_ASIG],MAE_ASIGNATURA[HORAS],0) -> 0 | K16: 4 | L16: =+Tabla1[[#This Row],[CALCULAR HORA]]*Tabla1[[#This Row],[HORAS]] -> 0 | N16: =_xlfn.XLOOKUP(Tabla1[[#This Row],[NOMBRE_DOCENT]],MDOCENTES[DATOS_DOCENTE],MDOCENTES[DEDICACION],"Seleccione Docente") -> Seleccione Docente | O16: =_xlfn.XLOOKUP(Tabla1[[#This Row],[NOMBRE_DOCENT]],MDOCENTES[DATOS_DOCENTE],MDOCENTES[ESTUDIO],"Seleccione Docente") -> Seleccione Docente | P16: =COUNTIFS($M:$M, M16, $H:$H, "<>ACTIVIDAD") -> 0 | Q16: =SUMIFS($L:$L, $M:$M, M16, $I:$I, "NO",$H:$H,"<>UNIDAD BASICA") -> 0 | R16: =SUMIFS($L:$L, $M:$M, M16, $H:$H, "UNIDAD BASICA",$I:$I,"NO") -> 0 | S16: =SUMIFS($L:$L, $M:$M, M16, $I:$I, "ACTIVIDAD") -> 0 | T16: =SUMIFS($L:$L, $M:$M, M16, $I:$I, "SI") -> 0 | U16: =Tabla1[[#This Row],[HORAS NO AFINIDAD]]+Tabla1[[#This Row],[HORAS UNIDAD BASICA]]+Tabla1[[#This Row],[HORAS AFINIDAD]] -> 0 | V16: =+Tabla1[[#This Row],[HORAS AFINIDAD]]+Tabla1[[#This Row],[HORAS ACTIVIDAD]]+Tabla1[[#This Row],[HORAS UNIDAD BASICA]]+Tabla1[[#This Row],[HORAS NO AFINIDAD]] -> 0
A17: 16 | C17: =_xlfn.XLOOKUP(Tabla1[[#This Row],[CARRERA]],MAE_CARRERA[NOMBRE_CARRERA],MAE_CARRERA[ID_CARRERA],"Seleccione Carrera") -> Seleccione Carrera | G17: =_xlfn.XLOOKUP(Tabla1[[#This Row],[ASIGNATURA]],MAE_ASIGNATURA[NOM_ASIG],MAE_ASIGNATURA[ID_ASIG],"Seleccione Asignatura") -> Seleccione Asignatura | H17: {=_xlfn.TEXTJOIN("; ",TRUE,TRANSPOSE(_xlfn.UNIQUE(_xlfn._xlws.FILTER(DET_ASIG[DETALLADO],(DET_ASIG[NIVEL]=ASIGNACION!$D17)*(DET_ASIG[ID_CARRERA]=ASIGNACION!$C17)*(DET_ASIG[ID_ASIG]=ASIGNACION!$G17),"No existe información"))))} -> No existe información | J17: =_xlfn.XLOOKUP(Tabla1[[#This Row],[ID_ASIG_CAM_DET]],MAE_ASIGNATURA[ID_ASIG],MAE_ASIGNATURA[HORAS],0) -> 0 | K17: 4 | L17: =+Tabla1[[#This Row],[CALCULAR HORA]]*Tabla1[[#This Row],[HORAS]] -> 0 | N17: =_xlfn.XLOOKUP(Tabla1[[#This Row],[NOMBRE_DOCENT]],MDOCENTES[DATOS_DOCENTE],MDOCENTES[DEDICACION],"Seleccione Docente") -> Seleccione Docente | O17: =_xlfn.XLOOKUP(Tabla1[[#This Row],[NOMBRE_DOCENT]],MDOCENTES[DATOS_DOCENTE],MDOCENTES[ESTUDIO],"Seleccione Docente") -> Seleccione Docente | P17: =COUNTIFS($M:$M, M17, $H:$H, "<>ACTIVIDAD") -> 0 | Q17: =SUMIFS($L:$L, $M:$M, M17, $I:$I, "NO",$H:$H,"<>UNIDAD BASICA") -> 0 | R17: =SUMIFS($L:$L, $M:$M, M17, $H:$H, "UNIDAD BASICA",$I:$I,"NO") -> 0 | S17: =SUMIFS($L:$L, $M:$M, M17, $I:$I, "ACTIVIDAD") -> 0 | T17: =SUMIFS($L:$L, $M:$M, M17, $I:$I, "SI") -> 0 | U17: =Tabla1[[#This Row],[HORAS NO AFINIDAD]]+Tabla1[[#This Row],[HORAS UNIDAD BASICA]]+Tabla1[[#This Row],[HORAS AFINIDAD]] -> 0 | V17: =+Tabla1[[#This Row],[HORAS AFINIDAD]]+Tabla1[[#This Row],[HORAS ACTIVIDAD]]+Tabla1[[#This Row],[HORAS UNIDAD BASICA]]+Tabla1[[#This Row],[HORAS NO AFINIDAD]] -> 0
A18: 17 | C18: =_xlfn.XLOOKUP(Tabla1[[#This Row],[CARRERA]],MAE_CARRERA[NOMBRE_CARRERA],MAE_CARRERA[ID_CARRERA],"Seleccione Carrera") -> Seleccione Carrera | G18: =_xlfn.XLOOKUP(Tabla1[[#This Row],[ASIGNATURA]],MAE_ASIGNATURA[NOM_ASIG],MAE_ASIGNATURA[ID_ASIG],"Seleccione Asignatura") -> Seleccione Asignatura | H18: {=_xlfn.TEXTJOIN("; ",TRUE,TRANSPOSE(_xlfn.UNIQUE(_xlfn._xlws.FILTER(DET_ASIG[DETALLADO],(DET_ASIG[NIVEL]=ASIGNACION!$D18)*(DET_ASIG[ID_CARRERA]=ASIGNACION!$C18)*(DET_ASIG[ID_ASIG]=ASIGNACION!$G18),"No existe información"))))} -> No existe información | J18: =_xlfn.XLOOKUP(Tabla1[[#This Row],[ID_ASIG_CAM_DET]],MAE_ASIGNATURA[ID_ASIG],MAE_ASIGNATURA[HORAS],0) -> 0 | K18: 4 | L18: =+Tabla1[[#This Row],[CALCULAR HORA]]*Tabla1[[#This Row],[HORAS]] -> 0 | N18: =_xlfn.XLOOKUP(Tabla1[[#This Row],[NOMBRE_DOCENT]],MDOCENTES[DATOS_DOCENTE],MDOCENTES[DEDICACION],"Seleccione Docente") -> Seleccione Docente | O18: =_xlfn.XLOOKUP(Tabla1[[#This Row],[NOMBRE_DOCENT]],MDOCENTES[DATOS_DOCENTE],MDOCENTES[ESTUDIO],"Seleccione Docente") -> Seleccione Docente | P18: =COUNTIFS($M:$M, M18, $H:$H, "<>ACTIVIDAD") -> 0 | Q18: =SUMIFS($L:$L, $M:$M, M18, $I:$I, "NO",$H:$H,"<>UNIDAD BASICA") -> 0 | R18: =SUMIFS($L:$L, $M:$M, M18, $H:$H, "UNIDAD BASICA",$I:$I,"NO") -> 0 | S18: =SUMIFS($L:$L, $M:$M, M18, $I:$I, "ACTIVIDAD") -> 0 | T18: =SUMIFS($L:$L, $M:$M, M18, $I:$I, "SI") -> 0 | U18: =Tabla1[[#This Row],[HORAS NO AFINIDAD]]+Tabla1[[#This Row],[HORAS UNIDAD BASICA]]+Tabla1[[#This Row],[HORAS AFINIDAD]] -> 0 | V18: =+Tabla1[[#This Row],[HORAS AFINIDAD]]+Tabla1[[#This Row],[HORAS ACTIVIDAD]]+Tabla1[[#This Row],[HORAS UNIDAD BASICA]]+Tabla1[[#This Row],[HORAS NO AFINIDAD]] -> 0
A19: 18 | C19: =_xlfn.XLOOKUP(Tabla1[[#This Row],[CARRERA]],MAE_CARRERA[NOMBRE_CARRERA],MAE_CARRERA[ID_CARRERA],"Seleccione Carrera") -> Seleccione Carrera | G19: =_xlfn.XLOOKUP(Tabla1[[#This Row],[ASIGNATURA]],MAE_ASIGNATURA[NOM_ASIG],MAE_ASIGNATURA[ID_ASIG],"Seleccione Asignatura") -> Seleccione Asignatura | H19: {=_xlfn.TEXTJOIN("; ",TRUE,TRANSPOSE(_xlfn.UNIQUE(_xlfn._xlws.FILTER(DET_ASIG[DETALLADO],(DET_ASIG[NIVEL]=ASIGNACION!$D19)*(DET_ASIG[ID_CARRERA]=ASIGNACION!$C19)*(DET_ASIG[ID_ASIG]=ASIGNACION!$G19),"No existe información"))))} -> No existe información | J19: =_xlfn.XLOOKUP(Tabla1[[#This Row],[ID_ASIG_CAM_DET]],MAE_ASIGNATURA[ID_ASIG],MAE_ASIGNATURA[HORAS],0) -> 0 | K19: 4 | L19: =+Tabla1[[#This Row],[CALCULAR HORA]]*Tabla1[[#This Row],[HORAS]] -> 0 | N19: =_xlfn.XLOOKUP(Tabla1[[#This Row],[NOMBRE_DOCENT]],MDOCENTES[DATOS_DOCENTE],MDOCENTES[DEDICACION],"Seleccione Docente") -> Seleccione Docente | O19: =_xlfn.XLOOKUP(Tabla1[[#This Row],[NOMBRE_DOCENT]],MDOCENTES[DATOS_DOCENTE],MDOCENTES[ESTUDIO],"Seleccione Docente") -> Seleccione Docente | P19: =COUNTIFS($M:$M, M19, $H:$H, "<>ACTIVIDAD") -> 0 | Q19: =SUMIFS($L:$L, $M:$M, M19, $I:$I, "NO",$H:$H,"<>UNIDAD BASICA") -> 0 | R19: =SUMIFS($L:$L, $M:$M, M19, $H:$H, "UNIDAD BASICA",$I:$I,"NO") -> 0 | S19: =SUMIFS($L:$L, $M:$M, M19, $I:$I, "ACTIVIDAD") -> 0 | T19: =SUMIFS($L:$L, $M:$M, M19, $I:$I, "SI") -> 0 | U19: =Tabla1[[#This Row],[HORAS NO AFINIDAD]]+Tabla1[[#This Row],[HORAS UNIDAD BASICA]]+Tabla1[[#This Row],[HORAS AFINIDAD]] -> 0 | V19: =+Tabla1[[#This Row],[HORAS AFINIDAD]]+Tabla1[[#This Row],[HORAS ACTIVIDAD]]+Tabla1[[#This Row],[HORAS UNIDAD BASICA]]+Tabla1[[#This Row],[HORAS NO AFINIDAD]] -> 0
A20: 19 | C20: =_xlfn.XLOOKUP(Tabla1[[#This Row],[CARRERA]],MAE_CARRERA[NOMBRE_CARRERA],MAE_CARRERA[ID_CARRERA],"Seleccione Carrera") -> Seleccione Carrera | G20: =_xlfn.XLOOKUP(Tabla1[[#This Row],[ASIGNATURA]],MAE_ASIGNATURA[NOM_ASIG],MAE_ASIGNATURA[ID_ASIG],"Seleccione Asignatura") -> Seleccione Asignatura | H20: {=_xlfn.TEXTJOIN("; ",TRUE,TRANSPOSE(_xlfn.UNIQUE(_xlfn._xlws.FILTER(DET_ASIG[DETALLADO],(DET_ASIG[NIVEL]=ASIGNACION!$D20)*(DET_ASIG[ID_CARRERA]=ASIGNACION!$C20)*(DET_ASIG[ID_ASIG]=ASIGNACION!$G20),"No existe información"))))} -> No existe información | J20: =_xlfn.XLOOKUP(Tabla1[[#This Row],[ID_ASIG_CAM_DET]],MAE_ASIGNATURA[ID_ASIG],MAE_ASIGNATURA[HORAS],0) -> 0 | K20: 4 | L20: =+Tabla1[[#This Row],[CALCULAR HORA]]*Tabla1[[#This Row],[HORAS]] -> 0 | N20: =_xlfn.XLOOKUP(Tabla1[[#This Row],[NOMBRE_DOCENT]],MDOCENTES[DATOS_DOCENTE],MDOCENTES[DEDICACION],"Seleccione Docente") -> Seleccione Docente | O20: =_xlfn.XLOOKUP(Tabla1[[#This Row],[NOMBRE_DOCENT]],MDOCENTES[DATOS_DOCENTE],MDOCENTES[ESTUDIO],"Seleccione Docente") -> Seleccione Docente | P20: =COUNTIFS($M:$M, M20, $H:$H, "<>ACTIVIDAD") -> 0 | Q20: =SUMIFS($L:$L, $M:$M, M20, $I:$I, "NO",$H:$H,"<>UNIDAD BASICA") -> 0 | R20: =SUMIFS($L:$L, $M:$M, M20, $H:$H, "UNIDAD BASICA",$I:$I,"NO") -> 0 | S20: =SUMIFS($L:$L, $M:$M, M20, $I:$I, "ACTIVIDAD") -> 0 | T20: =SUMIFS($L:$L, $M:$M, M20, $I:$I, "SI") -> 0 | U20: =Tabla1[[#This Row],[HORAS NO AFINIDAD]]+Tabla1[[#This Row],[HORAS UNIDAD BASICA]]+Tabla1[[#This Row],[HORAS AFINIDAD]] -> 0 | V20: =+Tabla1[[#This Row],[HORAS AFINIDAD]]+Tabla1[[#This Row],[HORAS ACTIVIDAD]]+Tabla1[[#This Row],[HORAS UNIDAD BASICA]]+Tabla1[[#This Row],[HORAS NO AFINIDAD]] -> 0
A21: 20 | C21: =_xlfn.XLOOKUP(Tabla1[[#This Row],[CARRERA]],MAE_CARRERA[NOMBRE_CARRERA],MAE_CARRERA[ID_CARRERA],"Seleccione Carrera") -> Seleccione Carrera | G21: =_xlfn.XLOOKUP(Tabla1[[#This Row],[ASIGNATURA]],MAE_ASIGNATURA[NOM_ASIG],MAE_ASIGNATURA[ID_ASIG],"Seleccione Asignatura") -> Seleccione Asignatura | H21: {=_xlfn.TEXTJOIN("; ",TRUE,TRANSPOSE(_xlfn.UNIQUE(_xlfn._xlws.FILTER(DET_ASIG[DETALLADO],(DET_ASIG[NIVEL]=ASIGNACION!$D21)*(DET_ASIG[ID_CARRERA]=ASIGNACION!$C21)*(DET_ASIG[ID_ASIG]=ASIGNACION!$G21),"No existe información"))))} -> No existe información | J21: =_xlfn.XLOOKUP(Tabla1[[#This Row],[ID_ASIG_CAM_DET]],MAE_ASIGNATURA[ID_ASIG],MAE_ASIGNATURA[HORAS],0) -> 0 | K21: 4 | L21: =+Tabla1[[#This Row],[CALCULAR HORA]]*Tabla1[[#This Row],[HORAS]] -> 0 | N21: =_xlfn.XLOOKUP(Tabla1[[#This Row],[NOMBRE_DOCENT]],MDOCENTES[DATOS_DOCENTE],MDOCENTES[DEDICACION],"Seleccione Docente") -> Seleccione Docente | O21: =_xlfn.XLOOKUP(Tabla1[[#This Row],[NOMBRE_DOCENT]],MDOCENTES[DATOS_DOCENTE],MDOCENTES[ESTUDIO],"Seleccione Docente") -> Seleccione Docente | P21: =COUNTIFS($M:$M, M21, $H:$H, "<>ACTIVIDAD") -> 0 | Q21: =SUMIFS($L:$L, $M:$M, M21, $I:$I, "NO",$H:$H,"<>UNIDAD BASICA") -> 0 | R21: =SUMIFS($L:$L, $M:$M, M21, $H:$H, "UNIDAD BASICA",$I:$I,"NO") -> 0 | S21: =SUMIFS($L:$L, $M:$M, M21, $I:$I, "ACTIVIDAD") -> 0 | T21: =SUMIFS($L:$L, $M:$M, M21, $I:$I, "SI") -> 0 | U21: =Tabla1[[#This Row],[HORAS NO AFINIDAD]]+Tabla1[[#This Row],[HORAS UNIDAD BASICA]]+Tabla1[[#This Row],[HORAS AFINIDAD]] -> 0 | V21: =+Tabla1[[#This Row],[HORAS AFINIDAD]]+Tabla1[[#This Row],[HORAS ACTIVIDAD]]+Tabla1[[#This Row],[HORAS UNIDAD BASICA]]+Tabla1[[#This Row],[HORAS NO AFINIDAD]] -> 0
A22: 21 | C22: =_xlfn.XLOOKUP(Tabla1[[#This Row],[CARRERA]],MAE_CARRERA[NOMBRE_CARRERA],MAE_CARRERA[ID_CARRERA],"Seleccione Carrera") -> Seleccione Carrera | G22: =_xlfn.XLOOKUP(Tabla1[[#This Row],[ASIGNATURA]],MAE_ASIGNATURA[NOM_ASIG],MAE_ASIGNATURA[ID_ASIG],"Seleccione Asignatura") -> Seleccione Asignatura | H22: {=_xlfn.TEXTJOIN("; ",TRUE,TRANSPOSE(_xlfn.UNIQUE(_xlfn._xlws.FILTER(DET_ASIG[DETALLADO],(DET_ASIG[NIVEL]=ASIGNACION!$D22)*(DET_ASIG[ID_CARRERA]=ASIGNACION!$C22)*(DET_ASIG[ID_ASIG]=ASIGNACION!$G22),"No existe información"))))} -> No existe información | J22: =_xlfn.XLOOKUP(Tabla1[[#This Row],[ID_ASIG_CAM_DET]],MAE_ASIGNATURA[ID_ASIG],MAE_ASIGNATURA[HORAS],0) -> 0 | K22: 4 | L22: =+Tabla1[[#This Row],[CALCULAR HORA]]*Tabla1[[#This Row],[HORAS]] -> 0 | N22: =_xlfn.XLOOKUP(Tabla1[[#This Row],[NOMBRE_DOCENT]],MDOCENTES[DATOS_DOCENTE],MDOCENTES[DEDICACION],"Seleccione Docente") -> Seleccione Docente | O22: =_xlfn.XLOOKUP(Tabla1[[#This Row],[NOMBRE_DOCENT]],MDOCENTES[DATOS_DOCENTE],MDOCENTES[ESTUDIO],"Seleccione Docente") -> Seleccione Docente | P22: =COUNTIFS($M:$M, M22, $H:$H, "<>ACTIVIDAD") -> 0 | Q22: =SUMIFS($L:$L, $M:$M, M22, $I:$I, "NO",$H:$H,"<>UNIDAD BASICA") -> 0 | R22: =SUMIFS($L:$L, $M:$M, M22, $H:$H, "UNIDAD BASICA",$I:$I,"NO") -> 0 | S22: =SUMIFS($L:$L, $M:$M, M22, $I:$I, "ACTIVIDAD") -> 0 | T22: =SUMIFS($L:$L, $M:$M, M22, $I:$I, "SI") -> 0 | U22: =Tabla1[[#This Row],[HORAS NO AFINIDAD]]+Tabla1[[#This Row],[HORAS UNIDAD BASICA]]+Tabla1[[#This Row],[HORAS AFINIDAD]] -> 0 | V22: =+Tabla1[[#This Row],[HORAS AFINIDAD]]+Tabla1[[#This Row],[HORAS ACTIVIDAD]]+Tabla1[[#This Row],[HORAS UNIDAD BASICA]]+Tabla1[[#This Row],[HORAS NO AFINIDAD]] -> 0
A23: 22 | C23: =_xlfn.XLOOKUP(Tabla1[[#This Row],[CARRERA]],MAE_CARRERA[NOMBRE_CARRERA],MAE_CARRERA[ID_CARRERA],"Seleccione Carrera") -> Seleccione Carrera | G23: =_xlfn.XLOOKUP(Tabla1[[#This Row],[ASIGNATURA]],MAE_ASIGNATURA[NOM_ASIG],MAE_ASIGNATURA[ID_ASIG],"Seleccione Asignatura") -> Seleccione Asignatura | H23: {=_xlfn.TEXTJOIN("; ",TRUE,TRANSPOSE(_xlfn.UNIQUE(_xlfn._xlws.FILTER(DET_ASIG[DETALLADO],(DET_ASIG[NIVEL]=ASIGNACION!$D23)*(DET_ASIG[ID_CARRERA]=ASIGNACION!$C23)*(DET_ASIG[ID_ASIG]=ASIGNACION!$G23),"No existe información"))))} -> No existe información | J23: =_xlfn.XLOOKUP(Tabla1[[#This Row],[ID_ASIG_CAM_DET]],MAE_ASIGNATURA[ID_ASIG],MAE_ASIGNATURA[HORAS],0) -> 0 | K23: 4 | L23: =+Tabla1[[#This Row],[CALCULAR HORA]]*Tabla1[[#This Row],[HORAS]] -> 0 | N23: =_xlfn.XLOOKUP(Tabla1[[#This Row],[NOMBRE_DOCENT]],MDOCENTES[DATOS_DOCENTE],MDOCENTES[DEDICACION],"Seleccione Docente") -> Seleccione Docente | O23: =_xlfn.XLOOKUP(Tabla1[[#This Row],[NOMBRE_DOCENT]],MDOCENTES[DATOS_DOCENTE],MDOCENTES[ESTUDIO],"Seleccione Docente") -> Seleccione Docente | P23: =COUNTIFS($M:$M, M23, $H:$H, "<>ACTIVIDAD") -> 0 | Q23: =SUMIFS($L:$L, $M:$M, M23, $I:$I, "NO",$H:$H,"<>UNIDAD BASICA") -> 0 | R23: =SUMIFS($L:$L, $M:$M, M23, $H:$H, "UNIDAD BASICA",$I:$I,"NO") -> 0 | S23: =SUMIFS($L:$L, $M:$M, M23, $I:$I, "ACTIVIDAD") -> 0 | T23: =SUMIFS($L:$L, $M:$M, M23, $I:$I, "SI") -> 0 | U23: =Tabla1[[#This Row],[HORAS NO AFINIDAD]]+Tabla1[[#This Row],[HORAS UNIDAD BASICA]]+Tabla1[[#This Row],[HORAS AFINIDAD]] -> 0 | V23: =+Tabla1[[#This Row],[HORAS AFINIDAD]]+Tabla1[[#This Row],[HORAS ACTIVIDAD]]+Tabla1[[#This Row],[HORAS UNIDAD BASICA]]+Tabla1[[#This Row],[HORAS NO AFINIDAD]] -> 0
... A600: 599 | C600: =_xlfn.XLOOKUP(Tabla1[[#This Row],[CARRERA]],MAE_CARRERA[NOMBRE_CARRERA],MAE_CARRERA[ID_CARRERA],"Seleccione Carrera") -> Seleccione Carrera | G600: =_xlfn.XLOOKUP(Tabla1[[#This Row],[ASIGNATURA]],MAE_ASIGNATURA[NOM_ASIG],MAE_ASIGNATURA[ID_ASIG],"Seleccione Asignatura") -> Seleccione Asignatura | H600: {=_xlfn.TEXTJOIN("; ",TRUE,TRANSPOSE(_xlfn.UNIQUE(_xlfn._xlws.FILTER(DET_ASIG[DETALLADO],(DET_ASIG[NIVEL]=ASIGNACION!$D600)*(DET_ASIG[ID_CARRERA]=ASIGNACION!$C600)*(DET_ASIG[ID_ASIG]=ASIGNACION!$G600),"No existe información"))))} -> No existe información | J600: =_xlfn.XLOOKUP(Tabla1[[#This Row],[ID_ASIG_CAM_DET]],MAE_ASIGNATURA[ID_ASIG],MAE_ASIGNATURA[HORAS],0) -> 0 | K600: 4 | L600: =+Tabla1[[#This Row],[CALCULAR HORA]]*Tabla1[[#This Row],[HORAS]] -> 0 | N600: =_xlfn.XLOOKUP(Tabla1[[#This Row],[NOMBRE_DOCENT]],MDOCENTES[DATOS_DOCENTE],MDOCENTES[DEDICACION],"Seleccione Docente") -> Seleccione Docente | O600: =_xlfn.XLOOKUP(Tabla1[[#This Row],[NOMBRE_DOCENT]],MDOCENTES[DATOS_DOCENTE],MDOCENTES[ESTUDIO],"Seleccione Docente") -> Seleccione Docente | P600: =COUNTIFS($M:$M, M600, $H:$H, "<>ACTIVIDAD") -> 0 | Q600: =SUMIFS($L:$L, $M:$M, M600, $I:$I, "NO",$H:$H,"<>UNIDAD BASICA") -> 0 | R600: =SUMIFS($L:$L, $M:$M, M600, $H:$H, "UNIDAD BASICA",$I:$I,"NO") -> 0 | S600: =SUMIFS($L:$L, $M:$M, M600, $I:$I, "ACTIVIDAD") -> 0 | T600: =SUMIFS($L:$L, $M:$M, M600, $I:$I, "SI") -> 0 | U600: =Tabla1[[#This Row],[HORAS NO AFINIDAD]]+Tabla1[[#This Row],[HORAS UNIDAD BASICA]]+Tabla1[[#This Row],[HORAS AFINIDAD]] -> 0 | V600: =+Tabla1[[#This Row],[HORAS AFINIDAD]]+Tabla1[[#This Row],[HORAS ACTIVIDAD]]+Tabla1[[#This Row],[HORAS UNIDAD BASICA]]+Tabla1[[#This Row],[HORAS NO AFINIDAD]] -> 0

Sheet INTERCAMBIO
BQ1: maestria | EA1: lista docente
A2: {=TRANSPOSE(_xlfn.UNIQUE(_xlfn._xlws.FILTER(MAE_ASIGNATURA[ID_NIVEL],MAE_ASIGNATURA[ID_CARRERA]=ASIGNACION!$C2,"No existe información")))} -> 1 | B2: 2 | C2: 3 | D2: 4 | E2: 5 | F2: 6 | G2: 7 | H2: 8 | S2: {=TRANSPOSE(_xlfn.UNIQUE(_xlfn._xlws.FILTER(MAE_ASIGNATURA[NOM_ASIG],(MAE_ASIGNATURA[ID_NIVEL]=ASIGNACION!$D2)*(MAE_ASIGNATURA[ID_CARRERA]=ASIGNACION!$C2),"No existe información")))} -> CONTABILIDAD BÁSICA | T2: MATEMÁTICA | U2: METODOLOGÍA DE LA INVESTIGACIÓN | V2: ADMINISTRACIÓN | W2: MACROECONOMÍA | BD2: {=TRANSPOSE(_xlfn.UNIQUE(_xlfn._xlws.FILTER(DET_ASIG[DETALLADO],(DET_ASIG[ID_CARRERA]=ASIGNACION!$C2)*(DET_ASIG[NIVEL]=ASIGNACION!$D2)*(DET_ASIG[ID_ASIG]=ASIGNACION!$G2),"No existe información")))} -> UNIDAD BASICA | BQ2: {=IFERROR( TRANSPOSE( _xlfn.UNIQUE( _xlfn._xlws.FILTER(MAESTRIA_DETALLADO[MAESTRIA], ISNUMBER(MATCH(MAESTRIA_DETALLADO[CAMPO_DETALLADO], BD2:BP2,0)) ) ) ),IF(BD2="ACTIVIDAD","DOCENCIA",""))} | EA2: {=IF( ASIGNACION!I2="SI", IFERROR( TRANSPOSE( _xlfn.UNIQUE( _xlfn._xlws.FILTER(EDU_DOCENTE[NOMBRE_DOCENTE], ISNUMBER(MATCH(EDU_DOCENTE[MAESTRIA], BQ2:DY2,0)) ) ) ), "" ), TRANSPOSE( _xlfn.UNIQUE(EDU_DOCENTE[NOMBRE_DOCENTE] ) ) )} -> ALCIVAR CEDEÑO BEATRIZ ISABEL | EB2: ALCIVAR VERA GEMA MICHELLE | EC2: ARAUZ CHAVEZ MARIO ROBERTO | ED2: BAILON LOURIDO WALTER ALBERTO | EE2: CALDERERO VILLAGOMEZ ERICK ANTONIO | EF2: CASTILLO GARCIA PAOLA GERMANIA | EG2: CEDEÑO CHOEZ PEDRO JAVIER | EH2: CEVALLOS HOPPE JUAN CARLOS | EI2: DELGADO CHAVEZ MARIA IRASEMA | EJ2: DUARTE VALENCIA CRISTHIAN DARIO | EK2: FORTTY BARBERAN DENNY ALEXANDER | EL2: GUTIERREZ ZAMBRANO CARMEN EBELINA | EM2: INTRIAGO MOLINA GEMA VALERIA | EN2: LINO VELEZ LEONEL LIVINGTON | EO2: LOOR ALCIVAR MARIA ILIANA | EP2: LOOR MIELES TANIA JACQUELINE | EQ2: LOOR SOLORZANO ROSA MARIA | ER2: LOPEZ DELGADO RONALD MAURICIO | ES2: MACIAS VALENCIA DAVID GABRIEL | ET2: MENDOZA ZAMORA WALTER MANUEL | EU2: MOLINA CEVALLOS MARIA LORENA | EV2: MURILLO DELGADO ISAAC GABRIEL | EW2: ANGULO MURILLO NAVIRA GISSELA | EX2: OCHOA SOLEDISPA NESTOR IVAN | EY2: PARRAGA FRANCO SILVANA MARIELA | EZ2: PINARGOTE VASQUEZ NANCY FABIOLA | FA2: REYES VELEZ PEDRO ENRIQUE | FB2: SAN ANDRES HORMAZA DALLAS CECILIA | FC2: SORNOZA ZAMORA JUAN CARLOS | FD2: TOMALA PINTO JESUS JACINTO | FE2: VALLE JARAMILLO SILVIA ARACELY | FF2: VELÁSQUEZ BRAVO IRMA KATHERINE | FG2: VELEZ MENDOZA LAYSY VALERIA | FH2: VINUEZA TELLO SHIRLEY ELIZABETH | FI2: ZAMBRANO ALCIVAR NILDA ISABEL | FJ2: ZAMBRANO LOOR RITA MAYDA | FK2: ZAMBRANO VERA MONICA JANETH | FL2: VERA DELGADO BRYAN ADRIÁN | FM2: MORAN GONZALES DAVID RENATO | FN2: 0
A3: {=TRANSPOSE(_xlfn.UNIQUE(_xlfn._xlws.FILTER(MAE_ASIGNATURA[ID_NIVEL],MAE_ASIGNATURA[ID_CARRERA]=ASIGNACION!$C3,"No existe información")))} -> 1 | B3: 2 | C3: 3 | D3: 4 | E3: 5 | F3: 6 | G3: 7 | H3: 8 | S3: {=TRANSPOSE(_xlfn.UNIQUE(_xlfn._xlws.FILTER(MAE_ASIGNATURA[NOM_ASIG],(MAE_ASIGNATURA[ID_NIVEL]=ASIGNACION!$D3)*(MAE_ASIGNATURA[ID_CARRERA]=ASIGNACION!$C3),"No existe información")))} -> CONTABILIDAD BÁSICA | T3: MATEMÁTICA | U3: METODOLOGÍA DE LA INVESTIGACIÓN | V3: ADMINISTRACIÓN | W3: MACROECONOMÍA | BD3: {=TRANSPOSE(_xlfn.UNIQUE(_xlfn._xlws.FILTER(DET_ASIG[DETALLADO],(DET_ASIG[ID_CARRERA]=ASIGNACION!$C3)*(DET_ASIG[NIVEL]=ASIGNACION!$D3)*(DET_ASIG[ID_ASIG]=ASIGNACION!$G3),"No existe información")))} -> UNIDAD BASICA | BQ3: {=IFERROR( TRANSPOSE( _xlfn.UNIQUE( _xlfn._xlws.FILTER(MAESTRIA_DETALLADO[MAESTRIA], ISNUMBER(MATCH(MAESTRIA_DETALLADO[CAMPO_DETALLADO], BD3:BP3,0)) ) ) ),IF(BD3="ACTIVIDAD","DOCENCIA",""))} | EA3: {=IF( ASIGNACION!I3="SI", IFERROR( TRANSPOSE( _xlfn.UNIQUE( _xlfn._xlws.FILTER(EDU_DOCENTE[NOMBRE_DOCENTE], ISNUMBER(MATCH(EDU_DOCENTE[MAESTRIA], BQ3:DY3,0)) ) ) ), "" ), TRANSPOSE( _xlfn.UNIQUE(EDU_DOCENTE[NOMBRE_DOCENTE] ) ) )} -> ALCIVAR CEDEÑO BEATRIZ ISABEL | EB3: ALCIVAR VERA GEMA MICHELLE | EC3: ARAUZ CHAVEZ MARIO ROBERTO | ED3: BAILON LOURIDO WALTER ALBERTO | EE3: CALDERERO VILLAGOMEZ ERICK ANTONIO | EF3: CASTILLO GARCIA PAOLA GERMANIA | EG3: CEDEÑO CHOEZ PEDRO JAVIER | EH3: CEVALLOS HOPPE JUAN CARLOS | EI3: DELGADO CHAVEZ MARIA IRASEMA | EJ3: DUARTE VALENCIA CRISTHIAN DARIO | EK3: FORTTY BARBERAN DENNY ALEXANDER | EL3: GUTIERREZ ZAMBRANO CARMEN EBELINA | EM3: INTRIAGO MOLINA GEMA VALERIA | EN3: LINO VELEZ LEONEL LIVINGTON | EO3: LOOR ALCIVAR MARIA ILIANA | EP3: LOOR MIELES TANIA JACQUELINE | EQ3: LOOR SOLORZANO ROSA MARIA | ER3: LOPEZ DELGADO RONALD MAURICIO | ES3: MACIAS VALENCIA DAVID GABRIEL | ET3: MENDOZA ZAMORA WALTER MANUEL | EU3: MOLINA CEVALLOS MARIA LORENA | EV3: MURILLO DELGADO ISAAC GABRIEL | EW3: ANGULO MURILLO NAVIRA GISSELA | EX3: OCHOA SOLEDISPA NESTOR IVAN | EY3: PARRAGA FRANCO SILVANA MARIELA | EZ3: PINARGOTE VASQUEZ NANCY FABIOLA | FA3: REYES VELEZ PEDRO ENRIQUE | FB3: SAN ANDRES HORMAZA DALLAS CECILIA | FC3: SORNOZA ZAMORA JUAN CARLOS | FD3: TOMALA PINTO JESUS JACINTO | FE3: VALLE JARAMILLO SILVIA ARACELY | FF3: VELÁSQUEZ BRAVO IRMA KATHERINE | FG3: VELEZ MENDOZA LAYSY VALERIA | FH3: VINUEZA TELLO SHIRLEY ELIZABETH | FI3: ZAMBRANO ALCIVAR NILDA ISABEL | FJ3: ZAMBRANO LOOR RITA MAYDA | FK3: ZAMBRANO VERA MONICA JANETH | FL3: VERA DELGADO BRYAN ADRIÁN | FM3: MORAN GONZALES DAVID RENATO | FN3: 0
A4: {=TRANSPOSE(_xlfn.UNIQUE(_xlfn._xlws.FILTER(MAE_ASIGNATURA[ID_NIVEL],MAE_ASIGNATURA[ID_CARRERA]=ASIGNACION!$C4,"No existe información")))} -> 1 | B4: 2 | C4: 3 | D4: 4 | E4: 5 | F4: 6 | G4: 7 | H4: 8 | S4: {=TRANSPOSE(_xlfn.UNIQUE(_xlfn._xlws.FILTER(MAE_ASIGNATURA[NOM_ASIG],(MAE_ASIGNATURA[ID_NIVEL]=ASIGNACION!$D4)*(MAE_ASIGNATURA[ID_CARRERA]=ASIGNACION!$C4),"No existe información")))} -> CONTABILIDAD BÁSICA | T4: MATEMÁTICA | U4: METODOLOGÍA DE LA INVESTIGACIÓN | V4: ADMINISTRACIÓN | W4: MACROECONOMÍA | BD4: {=TRANSPOSE(_xlfn.UNIQUE(_xlfn._xlws.FILTER(DET_ASIG[DETALLADO],(DET_ASIG[ID_CARRERA]=ASIGNACION!$C4)*(DET_ASIG[NIVEL]=ASIGNACION!$D4)*(DET_ASIG[ID_ASIG]=ASIGNACION!$G4),"No existe información")))} -> UNIDAD BASICA | BQ4: {=IFERROR( TRANSPOSE( _xlfn.UNIQUE( _xlfn._xlws.FILTER(MAESTRIA_DETALLADO[MAESTRIA], ISNUMBER(MATCH(MAESTRIA_DETALLADO[CAMPO_DETALLADO], BD4:BP4,0)) ) ) ),IF(BD4="ACTIVIDAD","DOCENCIA",""))} | EA4: {=IF( ASIGNACION!I4="SI", IFERROR( TRANSPOSE( _xlfn.UNIQUE( _xlfn._xlws.FILTER(EDU_DOCENTE[NOMBRE_DOCENTE], ISNUMBER(MATCH(EDU_DOCENTE[MAESTRIA], BQ4:DY4,0)) ) ) ), "" ), TRANSPOSE( _xlfn.UNIQUE(EDU_DOCENTE[NOMBRE_DOCENTE] ) ) )} -> ALCIVAR CEDEÑO BEATRIZ ISABEL | EB4: ALCIVAR VERA GEMA MICHELLE | EC4: ARAUZ CHAVEZ MARIO ROBERTO | ED4: BAILON LOURIDO WALTER ALBERTO | EE4: CALDERERO VILLAGOMEZ ERICK ANTONIO | EF4: CASTILLO GARCIA PAOLA GERMANIA | EG4: CEDEÑO CHOEZ PEDRO JAVIER | EH4: CEVALLOS HOPPE JUAN CARLOS | EI4: DELGADO CHAVEZ MARIA IRASEMA | EJ4: DUARTE VALENCIA CRISTHIAN DARIO | EK4: FORTTY BARBERAN DENNY ALEXANDER | EL4: GUTIERREZ ZAMBRANO CARMEN EBELINA | EM4: INTRIAGO MOLINA GEMA VALERIA | EN4: LINO VELEZ LEONEL LIVINGTON | EO4: LOOR ALCIVAR MARIA ILIANA | EP4: LOOR MIELES TANIA JACQUELINE | EQ4: LOOR SOLORZANO ROSA MARIA | ER4: LOPEZ DELGADO RONALD MAURICIO | ES4: MACIAS VALENCIA DAVID GABRIEL | ET4: MENDOZA ZAMORA WALTER MANUEL | EU4: MOLINA CEVALLOS MARIA LORENA | EV4: MURILLO DELGADO ISAAC GABRIEL | EW4: ANGULO MURILLO NAVIRA GISSELA | EX4: OCHOA SOLEDISPA NESTOR IVAN | EY4: PARRAGA FRANCO SILVANA MARIELA | EZ4: PINARGOTE VASQUEZ NANCY FABIOLA | FA4: REYES VELEZ PEDRO ENRIQUE | FB4: SAN ANDRES HORMAZA DALLAS CECILIA | FC4: SORNOZA ZAMORA JUAN CARLOS | FD4: TOMALA PINTO JESUS JACINTO | FE4: VALLE JARAMILLO SILVIA ARACELY | FF4: VELÁSQUEZ BRAVO IRMA KATHERINE | FG4: VELEZ MENDOZA LAYSY VALERIA | FH4: VINUEZA TELLO SHIRLEY ELIZABETH | FI4: ZAMBRANO ALCIVAR NILDA ISABEL | FJ4: ZAMBRANO LOOR RITA MAYDA | FK4: ZAMBRANO VERA MONICA JANETH | FL4: VERA DELGADO BRYAN ADRIÁN | FM4: MORAN GONZALES DAVID RENATO | FN4: 0
A5: {=TRANSPOSE(_xlfn.UNIQUE(_xlfn._xlws.FILTER(MAE_ASIGNATURA[ID_NIVEL],MAE_ASIGNATURA[ID_CARRERA]=ASIGNACION!$C5,"No existe información")))} -> 1 | B5: 2 | C5: 3 | D5: 4 | E5: 5 | F5: 6 | G5: 7 | H5: 8 | S5: {=TRANSPOSE(_xlfn.UNIQUE(_xlfn._xlws.FILTER(MAE_ASIGNATURA[NOM_ASIG],(MAE_ASIGNATURA[ID_NIVEL]=ASIGNACION!$D5)*(MAE_ASIGNATURA[ID_CARRERA]=ASIGNACION!$C5),"No existe información")))} -> CONTABILIDAD BÁSICA | T5: MATEMÁTICA | U5: METODOLOGÍA DE LA INVESTIGACIÓN | V5: ADMINISTRACIÓN | W5: MACROECONOMÍA | BD5: {=TRANSPOSE(_xlfn.UNIQUE(_xlfn._xlws.FILTER(DET_ASIG[DETALLADO],(DET_ASIG[ID_CARRERA]=ASIGNACION!$C5)*(DET_ASIG[NIVEL]=ASIGNACION!$D5)*(DET_ASIG[ID_ASIG]=ASIGNACION!$G5),"No existe información")))} -> UNIDAD BASICA | BQ5: {=IFERROR( TRANSPOSE( _xlfn.UNIQUE( _xlfn._xlws.FILTER(MAESTRIA_DETALLADO[MAESTRIA], ISNUMBER(MATCH(MAESTRIA_DETALLADO[CAMPO_DETALLADO], BD5:BP5,0)) ) ) ),IF(BD5="ACTIVIDAD","DOCENCIA",""))} | EA5: {=IF( ASIGNACION!I5="SI", IFERROR( TRANSPOSE( _xlfn.UNIQUE( _xlfn._xlws.FILTER(EDU_DOCENTE[NOMBRE_DOCENTE], ISNUMBER(MATCH(EDU_DOCENTE[MAESTRIA], BQ5:DY5,0)) ) ) ), "" ), TRANSPOSE( _xlfn.UNIQUE(EDU_DOCENTE[NOMBRE_DOCENTE] ) ) )} -> ALCIVAR CEDEÑO BEATRIZ ISABEL | EB5: ALCIVAR VERA GEMA MICHELLE | EC5: ARAUZ CHAVEZ MARIO ROBERTO | ED5: BAILON LOURIDO WALTER ALBERTO | EE5: CALDERERO VILLAGOMEZ ERICK ANTONIO | EF5: CASTILLO GARCIA PAOLA GERMANIA | EG5: CEDEÑO CHOEZ PEDRO JAVIER | EH5: CEVALLOS HOPPE JUAN CARLOS | EI5: DELGADO CHAVEZ MARIA IRASEMA | EJ5: DUARTE VALENCIA CRISTHIAN DARIO | EK5: FORTTY BARBERAN DENNY ALEXANDER | EL5: GUTIERREZ ZAMBRANO CARMEN EBELINA | EM5: INTRIAGO MOLINA GEMA VALERIA | EN5: LINO VELEZ LEONEL LIVINGTON | EO5: LOOR ALCIVAR MARIA ILIANA | EP5: LOOR MIELES TANIA JACQUELINE | EQ5: LOOR SOLORZANO ROSA MARIA | ER5: LOPEZ DELGADO RONALD MAURICIO | ES5: MACIAS VALENCIA DAVID GABRIEL | ET5: MENDOZA ZAMORA WALTER MANUEL | EU5: MOLINA CEVALLOS MARIA LORENA | EV5: MURILLO DELGADO ISAAC GABRIEL | EW5: ANGULO MURILLO NAVIRA GISSELA | EX5: OCHOA SOLEDISPA NESTOR IVAN | EY5: PARRAGA FRANCO SILVANA MARIELA | EZ5: PINARGOTE VASQUEZ NANCY FABIOLA | FA5: REYES VELEZ PEDRO ENRIQUE | FB5: SAN ANDRES HORMAZA DALLAS CECILIA | FC5: SORNOZA ZAMORA JUAN CARLOS | FD5: TOMALA PINTO JESUS JACINTO | FE5: VALLE JARAMILLO SILVIA ARACELY | FF5: VELÁSQUEZ BRAVO IRMA KATHERINE | FG5: VELEZ MENDOZA LAYSY VALERIA | FH5: VINUEZA TELLO SHIRLEY ELIZABETH | FI5: ZAMBRANO ALCIVAR NILDA ISABEL | FJ5: ZAMBRANO LOOR RITA MAYDA | FK5: ZAMBRANO VERA MONICA JANETH | FL5: VERA DELGADO BRYAN ADRIÁN | FM5: MORAN GONZALES DAVID RENATO | FN5: 0
A6: {=TRANSPOSE(_xlfn.UNIQUE(_xlfn._xlws.FILTER(MAE_ASIGNATURA[ID_NIVEL],MAE_ASIGNATURA[ID_CARRERA]=ASIGNACION!$C6,"No existe información")))} -> 1 | B6: 2 | C6: 3 | D6: 4 | E6: 5 | F6: 6 | G6: 7 | H6: 8 | S6: {=TRANSPOSE(_xlfn.UNIQUE(_xlfn._xlws.FILTER(MAE_ASIGNATURA[NOM_ASIG],(MAE_ASIGNATURA[ID_NIVEL]=ASIGNACION!$D6)*(MAE_ASIGNATURA[ID_CARRERA]=ASIGNACION!$C6),"No existe información")))} -> CONTABILIDAD BÁSICA | T6: MATEMÁTICA | U6: METODOLOGÍA DE LA INVESTIGACIÓN | V6: ADMINISTRACIÓN | W6: MACROECONOMÍA | BD6: {=TRANSPOSE(_xlfn.UNIQUE(_xlfn._xlws.FILTER(DET_ASIG[DETALLADO],(DET_ASIG[ID_CARRERA]=ASIGNACION!$C6)*(DET_ASIG[NIVEL]=ASIGNACION!$D6)*(DET_ASIG[ID_ASIG]=ASIGNACION!$G6),"No existe información")))} -> UNIDAD BASICA | BQ6: {=IFERROR( TRANSPOSE( _xlfn.UNIQUE( _xlfn._xlws.FILTER(MAESTRIA_DETALLADO[MAESTRIA], ISNUMBER(MATCH(MAESTRIA_DETALLADO[CAMPO_DETALLADO], BD6:BP6,0)) ) ) ),IF(BD6="ACTIVIDAD","DOCENCIA",""))} | EA6: {=IF( ASIGNACION!I6="SI", IFERROR( TRANSPOSE( _xlfn.UNIQUE( _xlfn._xlws.FILTER(EDU_DOCENTE[NOMBRE_DOCENTE], ISNUMBER(MATCH(EDU_DOCENTE[MAESTRIA], BQ6:DY6,0)) ) ) ), "" ), TRANSPOSE( _xlfn.UNIQUE(EDU_DOCENTE[NOMBRE_DOCENTE] ) ) )} -> ALCIVAR CEDEÑO BEATRIZ ISABEL | EB6: ALCIVAR VERA GEMA MICHELLE | EC6: ARAUZ CHAVEZ MARIO ROBERTO | ED6: BAILON LOURIDO WALTER ALBERTO | EE6: CALDERERO VILLAGOMEZ ERICK ANTONIO | EF6: CASTILLO GARCIA PAOLA GERMANIA | EG6: CEDEÑO CHOEZ PEDRO JAVIER | EH6: CEVALLOS HOPPE JUAN CARLOS | EI6: DELGADO CHAVEZ MARIA IRASEMA | EJ6: DUARTE VALENCIA CRISTHIAN DARIO | EK6: FORTTY BARBERAN DENNY ALEXANDER | EL6: GUTIERREZ ZAMBRANO CARMEN EBELINA | EM6: INTRIAGO MOLINA GEMA VALERIA | EN6: LINO VELEZ LEONEL LIVINGTON | EO6: LOOR ALCIVAR MARIA ILIANA | EP6: LOOR MIELES TANIA JACQUELINE | EQ6: LOOR SOLORZANO ROSA MARIA | ER6: LOPEZ DELGADO RONALD MAURICIO | ES6: MACIAS VALENCIA DAVID GABRIEL | ET6: MENDOZA ZAMORA WALTER MANUEL | EU6: MOLINA CEVALLOS MARIA LORENA | EV6: MURILLO DELGADO ISAAC GABRIEL | EW6: ANGULO MURILLO NAVIRA GISSELA | EX6: OCHOA SOLEDISPA NESTOR IVAN | EY6: PARRAGA FRANCO SILVANA MARIELA | EZ6: PINARGOTE VASQUEZ NANCY FABIOLA | FA6: REYES VELEZ PEDRO ENRIQUE | FB6: SAN ANDRES HORMAZA DALLAS CECILIA | FC6: SORNOZA ZAMORA JUAN CARLOS | FD6: TOMALA PINTO JESUS JACINTO | FE6: VALLE JARAMILLO SILVIA ARACELY | FF6: VELÁSQUEZ BRAVO IRMA KATHERINE | FG6: VELEZ MENDOZA LAYSY VALERIA | FH6: VINUEZA TELLO SHIRLEY ELIZABETH | FI6: ZAMBRANO ALCIVAR NILDA ISABEL | FJ6: ZAMBRANO LOOR RITA MAYDA | FK6: ZAMBRANO VERA MONICA JANETH | FL6: VERA DELGADO BRYAN ADRIÁN | FM6: MORAN GONZALES DAVID RENATO | FN6: 0
A7: {=TRANSPOSE(_xlfn.UNIQUE(_xlfn._xlws.FILTER(MAE_ASIGNATURA[ID_NIVEL],MAE_ASIGNATURA[ID_CARRERA]=ASIGNACION!$C7,"No existe información")))} -> 1 | B7: 2 | C7: 3 | D7: 4 | E7: 5 | F7: 6 | G7: 7 | H7: 8 | S7: {=TRANSPOSE(_xlfn.UNIQUE(_xlfn._xlws.FILTER(MAE_ASIGNATURA[NOM_ASIG],(MAE_ASIGNATURA[ID_NIVEL]=ASIGNACION!$D7)*(MAE_ASIGNATURA[ID_CARRERA]=ASIGNACION!$C7),"No existe información")))} -> CONTABILIDAD BÁSICA | T7: MATEMÁTICA | U7: METODOLOGÍA DE LA INVESTIGACIÓN | V7: ADMINISTRACIÓN | W7: MACROECONOMÍA | BD7: {=TRANSPOSE(_xlfn.UNIQUE(_xlfn._xlws.FILTER(DET_ASIG[DETALLADO],(DET_ASIG[ID_CARRERA]=ASIGNACION!$C7)*(DET_ASIG[NIVEL]=ASIGNACION!$D7)*(DET_ASIG[ID_ASIG]=ASIGNACION!$G7),"No existe información")))} -> UNIDAD BASICA | BQ7: {=IFERROR( TRANSPOSE( _xlfn.UNIQUE( _xlfn._xlws.FILTER(MAESTRIA_DETALLADO[MAESTRIA], ISNUMBER(MATCH(MAESTRIA_DETALLADO[CAMPO_DETALLADO], BD7:BP7,0)) ) ) ),IF(BD7="ACTIVIDAD","DOCENCIA",""))} | EA7: {=IF( ASIGNACION!I7="SI", IFERROR( TRANSPOSE( _xlfn.UNIQUE( _xlfn._xlws.FILTER(EDU_DOCENTE[NOMBRE_DOCENTE], ISNUMBER(MATCH(EDU_DOCENTE[MAESTRIA], BQ7:DY7,0)) ) ) ), "" ), TRANSPOSE( _xlfn.UNIQUE(EDU_DOCENTE[NOMBRE_DOCENTE] ) ) )} -> ALCIVAR CEDEÑO BEATRIZ ISABEL | EB7: ALCIVAR VERA GEMA MICHELLE | EC7: ARAUZ CHAVEZ MARIO ROBERTO | ED7: BAILON LOURIDO WALTER ALBERTO | EE7: CALDERERO VILLAGOMEZ ERICK ANTONIO | EF7: CASTILLO GARCIA PAOLA GERMANIA | EG7: CEDEÑO CHOEZ PEDRO JAVIER | EH7: CEVALLOS HOPPE JUAN CARLOS | EI7: DELGADO CHAVEZ MARIA IRASEMA | EJ7: DUARTE VALENCIA CRISTHIAN DARIO | EK7: FORTTY BARBERAN DENNY ALEXANDER | EL7: GUTIERREZ ZAMBRANO CARMEN EBELINA | EM7: INTRIAGO MOLINA GEMA VALERIA | EN7: LINO VELEZ LEONEL LIVINGTON | EO7: LOOR ALCIVAR MARIA ILIANA | EP7: LOOR MIELES TANIA JACQUELINE | EQ7: LOOR SOLORZANO ROSA MARIA | ER7: LOPEZ DELGADO RONALD MAURICIO | ES7: MACIAS VALENCIA DAVID GABRIEL | ET7: MENDOZA ZAMORA WALTER MANUEL | EU7: MOLINA CEVALLOS MARIA LORENA | EV7: MURILLO DELGADO ISAAC GABRIEL | EW7: ANGULO MURILLO NAVIRA GISSELA | EX7: OCHOA SOLEDISPA NESTOR IVAN | EY7: PARRAGA FRANCO SILVANA MARIELA | EZ7: PINARGOTE VASQUEZ NANCY FABIOLA | FA7: REYES VELEZ PEDRO ENRIQUE | FB7: SAN ANDRES HORMAZA DALLAS CECILIA | FC7: SORNOZA ZAMORA JUAN CARLOS | FD7: TOMALA PINTO JESUS JACINTO | FE7: VALLE JARAMILLO SILVIA ARACELY | FF7: VELÁSQUEZ BRAVO IRMA KATHERINE | FG7: VELEZ MENDOZA LAYSY VALERIA | FH7: VINUEZA TELLO SHIRLEY ELIZABETH | FI7: ZAMBRANO ALCIVAR NILDA ISABEL | FJ7: ZAMBRANO LOOR RITA MAYDA | FK7: ZAMBRANO VERA MONICA JANETH | FL7: VERA DELGADO BRYAN ADRIÁN | FM7: MORAN GONZALES DAVID RENATO | FN7: 0
A8: {=TRANSPOSE(_xlfn.UNIQUE(_xlfn._xlws.FILTER(MAE_ASIGNATURA[ID_NIVEL],MAE_ASIGNATURA[ID_CARRERA]=ASIGNACION!$C8,"No existe información")))} -> 0 | S8: {=TRANSPOSE(_xlfn.UNIQUE(_xlfn._xlws.FILTER(MAE_ASIGNATURA[NOM_ASIG],(MAE_ASIGNATURA[ID_NIVEL]=ASIGNACION!$D8)*(MAE_ASIGNATURA[ID_CARRERA]=ASIGNACION!$C8),"No existe información")))} -> AD5 Elaboración y calificación de evaluaciones | T8: AD4 Preparación de Clases | U8: AD6 Orientación a través de Tutorías | V8: AD8 Participación en colectivos académicos sobre docencia | BD8: {=TRANSPOSE(_xlfn.UNIQUE(_xlfn._xlws.FILTER(DET_ASIG[DETALLADO],(DET_ASIG[ID_CARRERA]=ASIGNACION!$C8)*(DET_ASIG[NIVEL]=ASIGNACION!$D8)*(DET_ASIG[ID_ASIG]=ASIGNACION!$G8),"No existe información")))} -> ACTIVIDAD | BQ8: {=IFERROR( TRANSPOSE( _xlfn.UNIQUE( _xlfn._xlws.FILTER(MAESTRIA_DETALLADO[MAESTRIA], ISNUMBER(MATCH(MAESTRIA_DETALLADO[CAMPO_DETALLADO], BD8:BP8,0)) ) ) ),IF(BD8="ACTIVIDAD","DOCENCIA",""))} -> DOCENCIA | EA8: {=IF( ASIGNACION!I8="SI", IFERROR( TRANSPOSE( _xlfn.UNIQUE( _xlfn._xlws.FILTER(EDU_DOCENTE[NOMBRE_DOCENTE], ISNUMBER(MATCH(EDU_DOCENTE[MAESTRIA], BQ8:DY8,0)) ) ) ), "" ), TRANSPOSE( _xlfn.UNIQUE(EDU_DOCENTE[NOMBRE_DOCENTE] ) ) )} -> ALCIVAR CEDEÑO BEATRIZ ISABEL | EB8: ALCIVAR VERA GEMA MICHELLE | EC8: ARAUZ CHAVEZ MARIO ROBERTO | ED8: BAILON LOURIDO WALTER ALBERTO | EE8: CALDERERO VILLAGOMEZ ERICK ANTONIO | EF8: CASTILLO GARCIA PAOLA GERMANIA | EG8: CEDEÑO CHOEZ PEDRO JAVIER | EH8: CEVALLOS HOPPE JUAN CARLOS | EI8: DELGADO CHAVEZ MARIA IRASEMA | EJ8: DUARTE VALENCIA CRISTHIAN DARIO | EK8: FORTTY BARBERAN DENNY ALEXANDER | EL8: GUTIERREZ ZAMBRANO CARMEN EBELINA | EM8: INTRIAGO MOLINA GEMA VALERIA | EN8: LINO VELEZ LEONEL LIVINGTON | EO8: LOOR ALCIVAR MARIA ILIANA | EP8: LOOR MIELES TANIA JACQUELINE | EQ8: LOOR SOLORZANO ROSA MARIA | ER8: LOPEZ DELGADO RONALD MAURICIO | ES8: MACIAS VALENCIA DAVID GABRIEL | ET8: MENDOZA ZAMORA WALTER MANUEL | EU8: MOLINA CEVALLOS MARIA LORENA | EV8: MURILLO DELGADO ISAAC GABRIEL | EW8: ANGULO MURILLO NAVIRA GISSELA | EX8: OCHOA SOLEDISPA NESTOR IVAN | EY8: PARRAGA FRANCO SILVANA MARIELA | EZ8: PINARGOTE VASQUEZ NANCY FABIOLA | FA8: REYES VELEZ PEDRO ENRIQUE | FB8: SAN ANDRES HORMAZA DALLAS CECILIA | FC8: SORNOZA ZAMORA JUAN CARLOS | FD8: TOMALA PINTO JESUS JACINTO | FE8: VALLE JARAMILLO SILVIA ARACELY | FF8: VELÁSQUEZ BRAVO IRMA KATHERINE | FG8: VELEZ MENDOZA LAYSY VALERIA | FH8: VINUEZA TELLO SHIRLEY ELIZABETH | FI8: ZAMBRANO ALCIVAR NILDA ISABEL | FJ8: ZAMBRANO LOOR RITA MAYDA | FK8: ZAMBRANO VERA MONICA JANETH | FL8: VERA DELGADO BRYAN ADRIÁN | FM8: MORAN GONZALES DAVID RENATO | FN8: 0
