Workbook

Sheet Hoja1
A2: {=TRANSPOSE(_xlfn.UNIQUE(_xlfn._xlws.FILTER(T_ASIGNATURA1[ID_NIVEL],T_ASIGNATURA1[ID_CARRERA]=ASIGNACION!$A2,"No existe información")))} -> 8 | B2: 7 | C2: 6 | D2: 5 | E2: 4 | F2: 3 | G2: 2 | H2: 1 | S2: {=TRANSPOSE(_xlfn.UNIQUE(_xlfn._xlws.FILTER(T_ASIGNATURA1[NOM_ASIG],(T_ASIGNATURA1[ID_NIVEL]=ASIGNACION!$C2)*(T_ASIGNATURA1[ID_CARRERA]=ASIGNACION!$A2),"No existe información")))} -> LEGISLACIÓN MERCANTIL Y SOCIERTARIA | T2: ESTADÍSTICA DESCRIPTIVA | U2: FUNDAMENTOS DE ADMINISTRACIÓN | V2: FUNDAMENTOS DE CONTABILIDAD | BD2: {=TRANSPOSE(_xlfn.UNIQUE(_xlfn._xlws.FILTER(Tabla3[DETALLADO],(Tabla3[NIVEL]=ASIGNACION!$C2)*(Tabla3[CARRERA]=ASIGNACION!$A2),"No existe información")))} -> No existe información | BQ2: {=IFERROR( TRANSPOSE( _xlfn.UNIQUE( _xlfn._xlws.FILTER( Tabla1_1[MAESTRIA], ISNUMBER(MATCH(Tabla1_1[CAMPO_DETALLADO],BD3:BP3,0)) ) ) ), "")} | DZ2: x | EA2: {=IF( ASIGNACION!G2="SI", IFERROR( TRANSPOSE( _xlfn.UNIQUE( _xlfn._xlws.FILTER( Tabla1__2[NOMBRE_DOCENTE], ISNUMBER(MATCH(Tabla1__2[MAESTRIA],BQ2:DY2,0)) ) ) ), "" ), TRANSPOSE( _xlfn.UNIQUE( Tabla1__3[DATOS_DOCENTE] ) ) )} -> ALARCON CHAVEZ CESAR RAUL | EB2: ALCIVAR MERO MARIA JESSENIA | EC2: ALVIA TOALA DAHIANA VALERIA | ED2: BALSECA MACIAS PAOLA ESTEFANIA | EE2: BAYAS ZAMBRANO CARMEN MARIETA | EF2: CACERES LARREATEGUI ALBA LUCIA | EG2: CALDERON ZAMORA OSCAR XAVIER | EH2: CANO LARA EVELYN DYANN | EI2: CEVALLOS ENRIQUEZ RODRIGO PAUL | EJ2: CRUZ MERA RAFER HENRY | EK2: FRANCO CHAVEZ MONICA ALEXANDRA | EL2: FRANCO RODRIGUEZ LUIS ENRIQUE | EM2: GARCIA LOOR ANA DEL ROCIO | EN2: GUADAMUD VERA JESSICA GEOCONDA | EO2: GUEVARA CAÑIZARES MARISSA ALEJANDRA | EP2: HEREDIA COPPIANO GENESIS ESTEFANIA | EQ2: HOLGUIN BRIONES AUDREY JACQUELINE | ER2: MACIAS CATAGUA OTTO WAGNER | ES2: MARCILLO PIN KARLA ROSANNA | ET2: MENDOZA BRIONES AMADO ANTONIO | EU2: MERO MERO RUBEN DARIO | EV2: MORANTE GALARZA JOSE LUIS | EW2: PIGUAVE PEREZ VICENTA ROCIO | EX2: RODRIGUEZ DURAN MIGUEL OSWALDO | EY2: SALCEDO LOOR HERNAN VLADIMIR | EZ2: SANTOS VELEZ MARIA BEATRIZ | FA2: TORO LOOR RICHARD GONZALO | FB2: TRIVIÑO QUIJIJE JEFFERSON ALEXANDER | FC2: VELASCO DELGADO CARLOS ALBERTO | FD2: VELEZ CHAVEZ CARLOS ORLANDO | FE2: VELEZ ROMERO XAVIER ALBERTO | FF2: ZAMBRANO VERA MARIA FERNANDA | FG2: CALDERON ZAMORA MARJORIE JESSENIA | FH2: CANO MURE ERNESTO RODOLFO | FI2: CUADROS OCAMPO CARMINA ISABEL | FJ2: FERNANDEZ ALAVA VANESSA GUADALUPE | FK2: INTRIAGO DURAN MARCOS VINICIO | FL2: LOOR MUÑOZ PRESLEY IDULFO | FM2: LOPEZ DELGADO RONALD MAURICIO | FN2: MENDOZA GARCIA JORGE GREGORIO | FO2: MENENDEZ DELGADO ERICK RODOLFO | FP2: MENESES SALVADOR JUAN CARLOS | FQ2: MUÑOZ MACIAS KARLOS EDUARDO | FR2: PALACIO HANZE CARLOS LUIS | FS2: PARRAGA MOGROVEJO MAYRA IVETH | FT2: SANCHEZ ARTEAGA ALEX ALFONSO | FU2: VELEZ CEDEÑO JOHANNA GUADALUPE | FV2: VELIZ INTRIAGO AMNUSKA KOYITO | FW2: VERA SANTANA HUGO CARLOS | FX2: ALCIVAR CEDEÑO BEATRIZ ISABEL | FY2: ALCIVAR VERA GEMA MICHELLE | FZ2: ANGULO MURILLO NAVIRA GISSELA | GA2: BAILON LOURIDO WALTER ALBERTO | GB2: CALDERERO VILLAGOMEZ ERICK ANTONIO | GC2: CASTILLO GARCIA PAOLA GERMANIA | GD2: CEDEÑO CHOEZ PEDRO JAVIER | GE2: CEVALLOS HOPPE JUAN CARLOS | GF2: DELGADO CHAVEZ MARIA IRASEMA | GG2: DUARTE VALENCIA CRISTHIAN DARIO | GH2: FORTTY BARBERAN DENNY ALEXANDER | GI2: GUTIERREZ ZAMBRANO CARMEN EBELINA | GJ2: HIDALGO AVILA ARGELIO ANTONIO | GK2: INTRIAGO MOLINA GEMA VALERIA | GL2: LINO VELEZ LEONEL LIVINGTON | GM2: LOOR ALCIVAR MARIA ILIANA | GN2: LOOR MIELES TANIA JACQUELINE | GO2: LOOR SOLORZANO ROSA MARIA | GP2: MACÍAS UGALDE LEXANDRA TATIANA | GQ2: MACIAS VALENCIA DAVID GABRIEL | GR2: MENDOZA ZAMORA WALTER MANUEL | GS2: MOLINA CEVALLOS MARIA LORENA | GT2: MOREIRA LARGACHA JUAN MIGUEL | GU2: MURILLO DELGADO ISAAC GABRIEL | GV2: OCHOA SOLEDISPA NESTOR IVAN | GW2: PARRAGA FRANCO SILVANA MARIELA | GX2: PINARGOTE VASQUEZ NANCY FABIOLA | GY2: REYES VELEZ PEDRO ENRIQUE | GZ2: SAN ANDRES HORMAZA DALLAS CECILIA | HA2: SORNOZA ZAMORA JUAN CARLOS | HB2: TOMALA PINTO JESUS JACINTO | HC2: TUBAY CEDEÑO BORIS RICARDO | HD2: VALLE JARAMILLO SILVIA ARACELY | HE2: VELÁSQUEZ BRAVO IRMA KATHERINE | HF2: VELEZ MENDOZA LAYSY VALERIA | HG2: VINUEZA TELLO SHIRLEY ELIZABETH | HH2: ZAMBRANO ALCIVAR NILDA ISABEL | HI2: ZAMBRANO LOOR RITA MAYDA | HJ2: ZAMBRANO VERA MONICA JANETH | HK2: ANDRADE ALVARADO SONIA PATRICIA | HL2: ARAUZ CHAVEZ MARIO ROBERTO | HM2: BARREIRO CEDEÑO ISABEL MONSERRATE | HN2: BERMUDEZ VILLACRESES ROSA MAGDALENA | HO2: CAÑARTE RODRIGUEZ TANIA CECIBEL | HP2: COVEÑA MENÉNDEZ JONATHAN KLEBER | HQ2: GARAY VERA JULIA MARLENE | HR2: IDROVO FLORES PEDRO MANUEL | HS2: LUNA CAICEDO MERCEDES MONICA | HT2: MERO DELGADO OSWALDO WALDEMAR | HU2: PEÑAHERRERA VELEZ CINDY DEL CARMEN | HV2: QUIJIJE ZAMBRANO DIGNA MARGARITA | HW2: RODRIGUEZ SANCHEZ JOHNNY GUSTAVO | HX2: ROJAS ONCE MERCY CELINDA | HY2: SALTOS ALAVA SONIA KARINA | HZ2: VIDAL FERNANDEZ PABLO | IA2: ARAUZ CHAVEZ ANDREA ROBERTHA | IB2: ARIAS ARIAS ANA ELENA | IC2: BADUY MOLINA AARON LEONEL | ID2: BASURTO CEDEÑO XAVIER ALBERTO | IE2: CALDERON BAILON JOSE CALIXTO | IF2: CARREÑO VILLAVICENCIO DIANEXY VIVIANA | IG2: FARFAN TRIVIÑO HUGO ERNESTO | IH2: GRANDA GARCIA MARCO IVAN | II2: HORMAZA VILLAFUERTE SANDY LISBETH | IJ2: JACOME SANTOS XAVIER IVAN | IK2: LOOR CHAVEZ TEMISTOCLES DEODATO | IL2: LOOR MOREIRA ALEXANDRA JACQUELINE | IM2: LOPEZ LEONES CRISTHIAN JOSE | IN2: MEJIA VASQUEZ PERICLES RAMON | IO2: MERO CHAVEZ ULISES FEDERICO | IP2: MOLINA CEDEÑO JIMMY WILMER | IQ2: MOLINA QUIROZ CLAUDIA ANALIA | IR2: MORAN QUIÑONEZ CARLOS JULIO | IS2: PALACIOS BRIONES NURI LUPITA | IT2: PEÑA VÉLEZ ISAURA VANESSA | IU2: PINARGOTE MONTENEGRO KAREN GISELA | IV2: PONCE ANDRADE JOHNNY EDISON | IW2: SABANDO MENDOZA ESTELA ROSSANA | IX2: SOLIS BRAVO HUGO ALFONSO | IY2: VILLAFUERTE MUÑOZ WAGNER OSWALDO | IZ2: VILLAMARIN VILLOTA WALTER HUMBERTO | JA2: ZAMBRANO PEÑARRIETA JOSSELYN JAMILETH | JB2: CARRILLO PICO FEDERICO AVELINO
A3: {=TRANSPOSE(_xlfn.UNIQUE(_xlfn._xlws.FILTER(T_ASIGNATURA1[ID_NIVEL],T_ASIGNATURA1[ID_CARRERA]=ASIGNACION!$A3,"No existe información")))} -> 8 | B3: 7 | C3: 6 | D3: 5 | E3: 4 | F3: 3 | G3: 2 | H3: 1 | S3: {=TRANSPOSE(_xlfn.UNIQUE(_xlfn._xlws.FILTER(T_ASIGNATURA1[NOM_ASIG],(T_ASIGNATURA1[ID_NIVEL]=ASIGNACION!$C3)*(T_ASIGNATURA1[ID_CARRERA]=ASIGNACION!$A3),"No existe información")))} -> ÉTICA PROFESIONAL | T3: PLANIFICACIÓN Y DIRECCIÓN ESTRATÉGICA | U3: GESTIÓN TRIBUTARIA | V3: CONTABILIDAD EN EL SECTOR PÚBLICO | W3: PLANIFICACIÓN DE AUDITORÍAS | BD3: {=TRANSPOSE(_xlfn.UNIQUE(_xlfn._xlws.FILTER(Tabla3[DETALLADO],(Tabla3[NIVEL]=ASIGNACION!$C3)*(Tabla3[CARRERA]=ASIGNACION!$A3),"No existe información")))} -> No existe información | BQ3: {=IFERROR( TRANSPOSE( _xlfn.UNIQUE( _xlfn._xlws.FILTER( Tabla1_1[MAESTRIA], ISNUMBER(MATCH(Tabla1_1[CAMPO_DETALLADO],BD4:BP4,0)) ) ) ), "")} | EA3: {=IFERROR( TRANSPOSE( _xlfn.UNIQUE( _xlfn._xlws.FILTER( Tabla1__2[NOMBRE_DOCENTE], ISNUMBER(MATCH(Tabla1__2[MAESTRIA],BQ3:DY3,0)) ) ) ), "")}
A4: {=TRANSPOSE(_xlfn.UNIQUE(_xlfn._xlws.FILTER(T_ASIGNATURA1[ID_NIVEL],T_ASIGNATURA1[ID_CARRERA]=ASIGNACION!$A4,"No existe información")))} -> 8 | B4: 7 | C4: 6 | D4: 5 | E4: 4 | F4: 3 | G4: 2 | H4: 1 | S4: {=TRANSPOSE(_xlfn.UNIQUE(_xlfn._xlws.FILTER(T_ASIGNATURA1[NOM_ASIG],(T_ASIGNATURA1[ID_NIVEL]=ASIGNACION!$C4)*(T_ASIGNATURA1[ID_CARRERA]=ASIGNACION!$A4),"No existe información")))} -> ÉTICA PROFESIONAL | T4: PLANIFICACIÓN Y DIRECCIÓN ESTRATÉGICA | U4: GESTIÓN TRIBUTARIA | V4: CONTABILIDAD EN EL SECTOR PÚBLICO | W4: PLANIFICACIÓN DE AUDITORÍAS | BD4: {=TRANSPOSE(_xlfn.UNIQUE(_xlfn._xlws.FILTER(Tabla3[DETALLADO],(Tabla3[NIVEL]=ASIGNACION!$C4)*(Tabla3[CARRERA]=ASIGNACION!$A4),"No existe información")))} -> No existe información | BQ4: {=IFERROR( TRANSPOSE( _xlfn.UNIQUE( _xlfn._xlws.FILTER( Tabla1_1[MAESTRIA], ISNUMBER(MATCH(Tabla1_1[CAMPO_DETALLADO],BD5:BP5,0)) ) ) ), "")} | EA4: {=IFERROR( TRANSPOSE( _xlfn.UNIQUE( _xlfn._xlws.FILTER( Tabla1__2[NOMBRE_DOCENTE], ISNUMBER(MATCH(Tabla1__2[MAESTRIA],BQ4:DY4,0)) ) ) ), "")}
A5: {=TRANSPOSE(_xlfn.UNIQUE(_xlfn._xlws.FILTER(T_ASIGNATURA1[ID_NIVEL],T_ASIGNATURA1[ID_CARRERA]=ASIGNACION!$A5,"No existe información")))} -> 8 | B5: 7 | C5: 6 | D5: 5 | E5: 4 | F5: 3 | G5: 2 | H5: 1 | S5: {=TRANSPOSE(_xlfn.UNIQUE(_xlfn._xlws.FILTER(T_ASIGNATURA1[NOM_ASIG],(T_ASIGNATURA1[ID_NIVEL]=ASIGNACION!$C5)*(T_ASIGNATURA1[ID_CARRERA]=ASIGNACION!$A5),"No existe información")))} -> ÉTICA PROFESIONAL | T5: PLANIFICACIÓN Y DIRECCIÓN ESTRATÉGICA | U5: GESTIÓN TRIBUTARIA | V5: CONTABILIDAD EN EL SECTOR PÚBLICO | W5: PLANIFICACIÓN DE AUDITORÍAS | BD5: {=TRANSPOSE(_xlfn.UNIQUE(_xlfn._xlws.FILTER(Tabla3[DETALLADO],(Tabla3[NIVEL]=ASIGNACION!$C5)*(Tabla3[CARRERA]=ASIGNACION!$A5),"No existe información")))} -> No existe información | BQ5: {=IFERROR( TRANSPOSE( _xlfn.UNIQUE( _xlfn._xlws.FILTER( Tabla1_1[MAESTRIA], ISNUMBER(MATCH(Tabla1_1[CAMPO_DETALLADO],BD6:BP6,0)) ) ) ), "")} | EA5: {=IFERROR( TRANSPOSE( _xlfn.UNIQUE( _xlfn._xlws.FILTER( Tabla1__2[NOMBRE_DOCENTE], ISNUMBER(MATCH(Tabla1__2[MAESTRIA],BQ5:DY5,0)) ) ) ), "")}
A6: {=TRANSPOSE(_xlfn.UNIQUE(_xlfn._xlws.FILTER(T_ASIGNATURA1[ID_NIVEL],T_ASIGNATURA1[ID_CARRERA]=ASIGNACION!$A6,"No existe información")))} -> 8 | B6: 7 | C6: 6 | D6: 5 | E6: 4 | F6: 3 | G6: 2 | H6: 1 | S6: {=TRANSPOSE(_xlfn.UNIQUE(_xlfn._xlws.FILTER(T_ASIGNATURA1[NOM_ASIG],(T_ASIGNATURA1[ID_NIVEL]=ASIGNACION!$C6)*(T_ASIGNATURA1[ID_CARRERA]=ASIGNACION!$A6),"No existe información")))} -> ÉTICA PROFESIONAL | T6: PLANIFICACIÓN Y DIRECCIÓN ESTRATÉGICA | U6: GESTIÓN TRIBUTARIA | V6: CONTABILIDAD EN EL SECTOR PÚBLICO | W6: PLANIFICACIÓN DE AUDITORÍAS | BD6: {=TRANSPOSE(_xlfn.UNIQUE(_xlfn._xlws.FILTER(Tabla3[DETALLADO],(Tabla3[NIVEL]=ASIGNACION!$C6)*(Tabla3[CARRERA]=ASIGNACION!$A6),"No existe información")))} -> No existe información | BQ6: {=IFERROR( TRANSPOSE( _xlfn.UNIQUE( _xlfn._xlws.FILTER( Tabla1_1[MAESTRIA], ISNUMBER(MATCH(Tabla1_1[CAMPO_DETALLADO],BD7:BP7,0)) ) ) ), "")} | EA6: {=IFERROR( TRANSPOSE( _xlfn.UNIQUE( _xlfn._xlws.FILTER( Tabla1__2[NOMBRE_DOCENTE], ISNUMBER(MATCH(Tabla1__2[MAESTRIA],BQ6:DY6,0)) ) ) ), "")}
A7: {=TRANSPOSE(_xlfn.UNIQUE(_xlfn._xlws.FILTER(T_ASIGNATURA1[ID_NIVEL],T_ASIGNATURA1[ID_CARRERA]=ASIGNACION!$A7,"No existe información")))} -> 8 | B7: 7 | C7: 6 | D7: 5 | E7: 4 | F7: 3 | G7: 2 | H7: 1 | S7: {=TRANSPOSE(_xlfn.UNIQUE(_xlfn._xlws.FILTER(T_ASIGNATURA1[NOM_ASIG],(T_ASIGNATURA1[ID_NIVEL]=ASIGNACION!$C7)*(T_ASIGNATURA1[ID_CARRERA]=ASIGNACION!$A7),"No existe información")))} -> ÉTICA PROFESIONAL | T7: PLANIFICACIÓN Y DIRECCIÓN ESTRATÉGICA | U7: GESTIÓN TRIBUTARIA | V7: CONTABILIDAD EN EL SECTOR PÚBLICO | W7: PLANIFICACIÓN DE AUDITORÍAS | BD7: {=TRANSPOSE(_xlfn.UNIQUE(_xlfn._xlws.FILTER(Tabla3[DETALLADO],(Tabla3[NIVEL]=ASIGNACION!$C7)*(Tabla3[CARRERA]=ASIGNACION!$A7),"No existe información")))} -> No existe información | BQ7: {=IFERROR( TRANSPOSE( _xlfn.UNIQUE( _xlfn._xlws.FILTER( Tabla1_1[MAESTRIA], ISNUMBER(MATCH(Tabla1_1[CAMPO_DETALLADO],BD8:BP8,0)) ) ) ), "")} | EA7: {=IFERROR( TRANSPOSE( _xlfn.UNIQUE( _xlfn._xlws.FILTER( Tabla1__2[NOMBRE_DOCENTE], ISNUMBER(MATCH(Tabla1__2[MAESTRIA],BQ7:DY7,0)) ) ) ), "")}
A8: {=TRANSPOSE(_xlfn.UNIQUE(_xlfn._xlws.FILTER(T_ASIGNATURA1[ID_NIVEL],T_ASIGNATURA1[ID_CARRERA]=ASIGNACION!$A8,"No existe información")))} -> 8 | B8: 7 | C8: 6 | D8: 5 | E8: 4 | F8: 3 | G8: 2 | H8: 1 | S8: {=TRANSPOSE(_xlfn.UNIQUE(_xlfn._xlws.FILTER(T_ASIGNATURA1[NOM_ASIG],(T_ASIGNATURA1[ID_NIVEL]=ASIGNACION!$C8)*(T_ASIGNATURA1[ID_CARRERA]=ASIGNACION!$A8),"No existe información")))} -> GESTIÓN DE TALENTO HUMANO | T8: FUNDAMENTOS DE AUDITORÍAS | U8: ADMINISTRACIÓN FINANCIERA | V8: CONTABILIDAD SOCIAL Y AMBIENTAL | W8: CONTABILIDAD DE COSTOS | BD8: {=TRANSPOSE(_xlfn.UNIQUE(_xlfn._xlws.FILTER(Tabla3[DETALLADO],(Tabla3[NIVEL]=ASIGNACION!$C8)*(Tabla3[CARRERA]=ASIGNACION!$A8),"No existe información")))} -> No existe información | BQ8: {=IFERROR( TRANSPOSE( _xlfn.UNIQUE( _xlfn._xlws.FILTER( Tabla1_1[MAESTRIA], ISNUMBER(MATCH(Tabla1_1[CAMPO_DETALLADO],BD9:BP9,0)) ) ) ), "")} | EA8: {=IFERROR( TRANSPOSE( _xlfn.UNIQUE( _xlfn._xlws.FILTER( Tabla1__2[NOMBRE_DOCENTE], ISNUMBER(MATCH(Tabla1__2[MAESTRIA],BQ8:DY8,0)) ) ) ), "")}
A9: {=TRANSPOSE(_xlfn.UNIQUE(_xlfn._xlws.FILTER(T_ASIGNATURA1[ID_NIVEL],T_ASIGNATURA1[ID_CARRERA]=ASIGNACION!$A9,"No existe información")))} -> 8 | B9: 7 | C9: 6 | D9: 5 | E9: 4 | F9: 3 | G9: 2 | H9: 1 | S9: {=TRANSPOSE(_xlfn.UNIQUE(_xlfn._xlws.FILTER(T_ASIGNATURA1[NOM_ASIG],(T_ASIGNATURA1[ID_NIVEL]=ASIGNACION!$C9)*(T_ASIGNATURA1[ID_CARRERA]=ASIGNACION!$A9),"No existe información")))} -> AUDITORÍA INTEGRAL | T9: AUDITORÍA FORENSE | U9: AUDITORÍA DE SISTEMAS DE INFORMACIÓN | V9: LIDERAZGO Y GESTIÓN DE AUDITORIA | W9: DISEÑO, DESARROLLO Y EVALUACIÓN DE PROYECTOS | BD9: {=TRANSPOSE(_xlfn.UNIQUE(_xlfn._xlws.FILTER(Tabla3[DETALLADO],(Tabla3[NIVEL]=ASIGNACION!$C9)*(Tabla3[CARRERA]=ASIGNACION!$A9),"No existe información")))} -> No existe información | BQ9: {=IFERROR( TRANSPOSE( _xlfn.UNIQUE( _xlfn._xlws.FILTER( Tabla1_1[MAESTRIA], ISNUMBER(MATCH(Tabla1_1[CAMPO_DETALLADO],BD10:BP10,0)) ) ) ), "")} | EA9: {=IFERROR( TRANSPOSE( _xlfn.UNIQUE( _xlfn._xlws.FILTER( Tabla1__2[NOMBRE_DOCENTE], ISNUMBER(MATCH(Tabla1__2[MAESTRIA],BQ9:DY9,0)) ) ) ), "")}
A10: {=TRANSPOSE(_xlfn.UNIQUE(_xlfn._xlws.FILTER(T_ASIGNATURA1[ID_NIVEL],T_ASIGNATURA1[ID_CARRERA]=ASIGNACION!$A10,"No existe información")))} -> 8 | B10: 7 | C10: 6 | D10: 5 | E10: 4 | F10: 3 | G10: 2 | H10: 1 | S10: {=TRANSPOSE(_xlfn.UNIQUE(_xlfn._xlws.FILTER(T_ASIGNATURA1[NOM_ASIG],(T_ASIGNATURA1[ID_NIVEL]=ASIGNACION!$C10)*(T_ASIGNATURA1[ID_CARRERA]=ASIGNACION!$A10),"No existe información")))} -> ÉTICA PROFESIONAL | T10: PLANIFICACIÓN Y DIRECCIÓN ESTRATÉGICA | U10: GESTIÓN TRIBUTARIA | V10: CONTABILIDAD EN EL SECTOR PÚBLICO | W10: PLANIFICACIÓN DE AUDITORÍAS | BD10: {=TRANSPOSE(_xlfn.UNIQUE(_xlfn._xlws.FILTER(Tabla3[DETALLADO],(Tabla3[NIVEL]=ASIGNACION!$C10)*(Tabla3[CARRERA]=ASIGNACION!$A10),"No existe información")))} -> No existe información | BQ10: {=IFERROR( TRANSPOSE( _xlfn.UNIQUE( _xlfn._xlws.FILTER( Tabla1_1[MAESTRIA], ISNUMBER(MATCH(Tabla1_1[CAMPO_DETALLADO],BD11:BP11,0)) ) ) ), "")} | EA10: {=IFERROR( TRANSPOSE( _xlfn.UNIQUE( _xlfn._xlws.FILTER( Tabla1__2[NOMBRE_DOCENTE], ISNUMBER(MATCH(Tabla1__2[MAESTRIA],BQ10:DY10,0)) ) ) ), "")}
A11: {=TRANSPOSE(_xlfn.UNIQUE(_xlfn._xlws.FILTER(T_ASIGNATURA1[ID_NIVEL],T_ASIGNATURA1[ID_CARRERA]=ASIGNACION!$A11,"No existe información")))} -> 8 | B11: 7 | C11: 6 | D11: 5 | E11: 4 | F11: 3 | G11: 2 | H11: 1 | S11: {=TRANSPOSE(_xlfn.UNIQUE(_xlfn._xlws.FILTER(T_ASIGNATURA1[NOM_ASIG],(T_ASIGNATURA1[ID_NIVEL]=ASIGNACION!$C11)*(T_ASIGNATURA1[ID_CARRERA]=ASIGNACION!$A11),"No existe información")))} -> ÉTICA PROFESIONAL | T11: PLANIFICACIÓN Y DIRECCIÓN ESTRATÉGICA | U11: GESTIÓN TRIBUTARIA | V11: CONTABILIDAD EN EL SECTOR PÚBLICO | W11: PLANIFICACIÓN DE AUDITORÍAS | BD11: {=TRANSPOSE(_xlfn.UNIQUE(_xlfn._xlws.FILTER(Tabla3[DETALLADO],(Tabla3[NIVEL]=ASIGNACION!$C11)*(Tabla3[CARRERA]=ASIGNACION!$A11),"No existe información")))} -> No existe información | BQ11: {=IFERROR( TRANSPOSE( _xlfn.UNIQUE( _xlfn._xlws.FILTER( Tabla1_1[MAESTRIA], ISNUMBER(MATCH(Tabla1_1[CAMPO_DETALLADO],BD12:BP12,0)) ) ) ), "")} | EA11: {=IFERROR( TRANSPOSE( _xlfn.UNIQUE( _xlfn._xlws.FILTER( Tabla1__2[NOMBRE_DOCENTE], ISNUMBER(MATCH(Tabla1__2[MAESTRIA],BQ11:DY11,0)) ) ) ), "")}
A12: {=TRANSPOSE(_xlfn.UNIQUE(_xlfn._xlws.FILTER(T_ASIGNATURA1[ID_NIVEL],T_ASIGNATURA1[ID_CARRERA]=ASIGNACION!$A12,"No existe información")))} -> 8 | B12: 7 | C12: 6 | D12: 5 | E12: 4 | F12: 3 | G12: 2 | H12: 1 | S12: {=TRANSPOSE(_xlfn.UNIQUE(_xlfn._xlws.FILTER(T_ASIGNATURA1[NOM_ASIG],(T_ASIGNATURA1[ID_NIVEL]=ASIGNACION!$C12)*(T_ASIGNATURA1[ID_CARRERA]=ASIGNACION!$A12),"No existe información")))} -> AUDITORÍA INTEGRAL | T12: AUDITORÍA FORENSE | U12: AUDITORÍA DE SISTEMAS DE INFORMACIÓN | V12: LIDERAZGO Y GESTIÓN DE AUDITORIA | W12: DISEÑO, DESARROLLO Y EVALUACIÓN DE PROYECTOS | BD12: {=TRANSPOSE(_xlfn.UNIQUE(_xlfn._xlws.FILTER(Tabla3[DETALLADO],(Tabla3[NIVEL]=ASIGNACION!$C12)*(Tabla3[CARRERA]=ASIGNACION!$A12),"No existe información")))} -> No existe información | BQ12: {=IFERROR( TRANSPOSE( _xlfn.UNIQUE( _xlfn._xlws.FILTER( Tabla1_1[MAESTRIA], ISNUMBER(MATCH(Tabla1_1[CAMPO_DETALLADO],BD13:BP13,0)) ) ) ), "")} | EA12: {=IFERROR( TRANSPOSE( _xlfn.UNIQUE( _xlfn._xlws.FILTER( Tabla1__2[NOMBRE_DOCENTE], ISNUMBER(MATCH(Tabla1__2[MAESTRIA],BQ12:DY12,0)) ) ) ), "")}
A13: {=TRANSPOSE(_xlfn.UNIQUE(_xlfn._xlws.FILTER(T_ASIGNATURA1[ID_NIVEL],T_ASIGNATURA1[ID_CARRERA]=ASIGNACION!$A13,"No existe información")))} -> 8 | B13: 7 | C13: 6 | D13: 5 | E13: 4 | F13: 3 | G13: 2 | H13: 1 | S13: {=TRANSPOSE(_xlfn.UNIQUE(_xlfn._xlws.FILTER(T_ASIGNATURA1[NOM_ASIG],(T_ASIGNATURA1[ID_NIVEL]=ASIGNACION!$C13)*(T_ASIGNATURA1[ID_CARRERA]=ASIGNACION!$A13),"No existe información")))} -> LEGISLACIÓN LABORAL | T13: ESTADÍSTICA INFERENCIAL | U13: MATEMÁTICA FINANCIERA | V13: CONTABILIDAD FINANCIERA | BD13: {=TRANSPOSE(_xlfn.UNIQUE(_xlfn._xlws.FILTER(Tabla3[DETALLADO],(Tabla3[NIVEL]=ASIGNACION!$C13)*(Tabla3[CARRERA]=ASIGNACION!$A13),"No existe información")))} -> No existe información | BQ13: {=IFERROR( TRANSPOSE( _xlfn.UNIQUE( _xlfn._xlws.FILTER( Tabla1_1[MAESTRIA], ISNUMBER(MATCH(Tabla1_1[CAMPO_DETALLADO],BD14:BP14,0)) ) ) ), "")} | EA13: {=IFERROR( TRANSPOSE( _xlfn.UNIQUE( _xlfn._xlws.FILTER( Tabla1__2[NOMBRE_DOCENTE], ISNUMBER(MATCH(Tabla1__2[MAESTRIA],BQ13:DY13,0)) ) ) ), "")}
A14: {=TRANSPOSE(_xlfn.UNIQUE(_xlfn._xlws.FILTER(T_ASIGNATURA1[ID_NIVEL],T_ASIGNATURA1[ID_CARRERA]=ASIGNACION!$A14,"No existe información")))} -> 8 | B14: 7 | C14: 6 | D14: 5 | E14: 4 | F14: 3 | G14: 2 | H14: 1 | S14: {=TRANSPOSE(_xlfn.UNIQUE(_xlfn._xlws.FILTER(T_ASIGNATURA1[NOM_ASIG],(T_ASIGNATURA1[ID_NIVEL]=ASIGNACION!$C14)*(T_ASIGNATURA1[ID_CARRERA]=ASIGNACION!$A14),"No existe información")))} -> LEGISLACIÓN MERCANTIL Y SOCIERTARIA | T14: ESTADÍSTICA DESCRIPTIVA | U14: FUNDAMENTOS DE ADMINISTRACIÓN | V14: FUNDAMENTOS DE CONTABILIDAD | BD14: {=TRANSPOSE(_xlfn.UNIQUE(_xlfn._xlws.FILTER(Tabla3[DETALLADO],(Tabla3[NIVEL]=ASIGNACION!$C14)*(Tabla3[CARRERA]=ASIGNACION!$A14),"No existe información")))} -> No existe información | BQ14: {=IFERROR( TRANSPOSE( _xlfn.UNIQUE( _xlfn._xlws.FILTER( Tabla1_1[MAESTRIA], ISNUMBER(MATCH(Tabla1_1[CAMPO_DETALLADO],BD15:BP15,0)) ) ) ), "")} | EA14: {=IFERROR( TRANSPOSE( _xlfn.UNIQUE( _xlfn._xlws.FILTER( Tabla1__2[NOMBRE_DOCENTE], ISNUMBER(MATCH(Tabla1__2[MAESTRIA],BQ14:DY14,0)) ) ) ), "")}
A15: {=TRANSPOSE(_xlfn.UNIQUE(_xlfn._xlws.FILTER(T_ASIGNATURA1[ID_NIVEL],T_ASIGNATURA1[ID_CARRERA]=ASIGNACION!$A15,"No existe información")))} -> 8 | B15: 7 | C15: 6 | D15: 5 | E15: 4 | F15: 3 | G15: 2 | H15: 1 | S15: {=TRANSPOSE(_xlfn.UNIQUE(_xlfn._xlws.FILTER(T_ASIGNATURA1[NOM_ASIG],(T_ASIGNATURA1[ID_NIVEL]=ASIGNACION!$C15)*(T_ASIGNATURA1[ID_CARRERA]=ASIGNACION!$A15),"No existe información")))} -> No existe información | BD15: {=TRANSPOSE(_xlfn.UNIQUE(_xlfn._xlws.FILTER(Tabla3[DETALLADO],(Tabla3[NIVEL]=ASIGNACION!$C15)*(Tabla3[CARRERA]=ASIGNACION!$A15),"No existe información")))} -> No existe información | BQ15: {=IFERROR( TRANSPOSE( _xlfn.UNIQUE( _xlfn._xlws.FILTER( Tabla1_1[MAESTRIA], ISNUMBER(MATCH(Tabla1_1[CAMPO_DETALLADO],BD16:BP16,0)) ) ) ), "")} | EA15: {=IFERROR( TRANSPOSE( _xlfn.UNIQUE( _xlfn._xlws.FILTER( Tabla1__2[NOMBRE_DOCENTE], ISNUMBER(MATCH(Tabla1__2[MAESTRIA],BQ15:DY15,0)) ) ) ), "")}
A16: {=TRANSPOSE(_xlfn.UNIQUE(_xlfn._xlws.FILTER(T_ASIGNATURA1[ID_NIVEL],T_ASIGNATURA1[ID_CARRERA]=ASIGNACION!$A16,"No existe información")))} -> 8 | B16: 7 | C16: 6 | D16: 5 | E16: 4 | F16: 3 | G16: 2 | H16: 1 | S16: {=TRANSPOSE(_xlfn.UNIQUE(_xlfn._xlws.FILTER(T_ASIGNATURA1[NOM_ASIG],(T_ASIGNATURA1[ID_NIVEL]=ASIGNACION!$C16)*(T_ASIGNATURA1[ID_CARRERA]=ASIGNACION!$A16),"No existe información")))} -> No existe información | BD16: {=TRANSPOSE(_xlfn.UNIQUE(_xlfn._xlws.FILTER(Tabla3[DETALLADO],(Tabla3[NIVEL]=ASIGNACION!$C16)*(Tabla3[CARRERA]=ASIGNACION!$A16),"No existe información")))} -> No existe información | BQ16: {=IFERROR( TRANSPOSE( _xlfn.UNIQUE( _xlfn._xlws.FILTER( Tabla1_1[MAESTRIA], ISNUMBER(MATCH(Tabla1_1[CAMPO_DETALLADO],BD17:BP17,0)) ) ) ), "")} | EA16: {=IFERROR( TRANSPOSE( _xlfn.UNIQUE( _xlfn._xlws.FILTER( Tabla1__2[NOMBRE_DOCENTE], ISNUMBER(MATCH(Tabla1__2[MAESTRIA],BQ16:DY16,0)) ) ) ), "")}
A17: {=TRANSPOSE(_xlfn.UNIQUE(_xlfn._xlws.FILTER(T_ASIGNATURA1[ID_NIVEL],T_ASIGNATURA1[ID_CARRERA]=ASIGNACION!$A17,"No existe información")))} -> 8 | B17: 7 | C17: 6 | D17: 5 | E17: 4 | F17: 3 | G17: 2 | H17: 1 | S17: {=TRANSPOSE(_xlfn.UNIQUE(_xlfn._xlws.FILTER(T_ASIGNATURA1[NOM_ASIG],(T_ASIGNATURA1[ID_NIVEL]=ASIGNACION!$C17)*(T_ASIGNATURA1[ID_CARRERA]=ASIGNACION!$A17),"No existe información")))} -> No existe información | BD17: {=TRANSPOSE(_xlfn.UNIQUE(_xlfn._xlws.FILTER(Tabla3[DETALLADO],(Tabla3[NIVEL]=ASIGNACION!$C17)*(Tabla3[CARRERA]=ASIGNACION!$A17),"No existe información")))} -> No existe información | BQ17: {=IFERROR( TRANSPOSE( _xlfn.UNIQUE( _xlfn._xlws.FILTER( Tabla1_1[MAESTRIA], ISNUMBER(MATCH(Tabla1_1[CAMPO_DETALLADO],BD18:BP18,0)) ) ) ), "")} | EA17: {=IFERROR( TRANSPOSE( _xlfn.UNIQUE( _xlfn._xlws.FILTER( Tabla1__2[NOMBRE_DOCENTE], ISNUMBER(MATCH(Tabla1__2[MAESTRIA],BQ17:DY17,0)) ) ) ), "")}
A18: {=TRANSPOSE(_xlfn.UNIQUE(_xlfn._xlws.FILTER(T_ASIGNATURA1[ID_NIVEL],T_ASIGNATURA1[ID_CARRERA]=ASIGNACION!$A18,"No existe información")))} -> 8 | B18: 7 | C18: 6 | D18: 5 | E18: 4 | F18: 3 | G18: 2 | H18: 1 | S18: {=TRANSPOSE(_xlfn.UNIQUE(_xlfn._xlws.FILTER(T_ASIGNATURA1[NOM_ASIG],(T_ASIGNATURA1[ID_NIVEL]=ASIGNACION!$C18)*(T_ASIGNATURA1[ID_CARRERA]=ASIGNACION!$A18),"No existe información")))} -> No existe información | BD18: {=TRANSPOSE(_xlfn.UNIQUE(_xlfn._xlws.FILTER(Tabla3[DETALLADO],(Tabla3[NIVEL]=ASIGNACION!$C18)*(Tabla3[CARRERA]=ASIGNACION!$A18),"No existe información")))} -> No existe información | BQ18: {=IFERROR( TRANSPOSE( _xlfn.UNIQUE( _xlfn._xlws.FILTER( Tabla1_1[MAESTRIA], ISNUMBER(MATCH(Tabla1_1[CAMPO_DETALLADO],BD19:BP19,0)) ) ) ), "")} | EA18: {=IFERROR( TRANSPOSE( _xlfn.UNIQUE( _xlfn._xlws.FILTER( Tabla1__2[NOMBRE_DOCENTE], ISNUMBER(MATCH(Tabla1__2[MAESTRIA],BQ18:DY18,0)) ) ) ), "")}
A19: {=TRANSPOSE(_xlfn.UNIQUE(_xlfn._xlws.FILTER(T_ASIGNATURA1[ID_NIVEL],T_ASIGNATURA1[ID_CARRERA]=ASIGNACION!$A19,"No existe información")))} -> 8 | B19: 7 | C19: 6 | D19: 5 | E19: 4 | F19: 3 | G19: 2 | H19: 1 | S19: {=TRANSPOSE(_xlfn.UNIQUE(_xlfn._xlws.FILTER(T_ASIGNATURA1[NOM_ASIG],(T_ASIGNATURA1[ID_NIVEL]=ASIGNACION!$C19)*(T_ASIGNATURA1[ID_CARRERA]=ASIGNACION!$A19),"No existe información")))} -> #REF! | BD19: {=TRANSPOSE(_xlfn.UNIQUE(_xlfn._xlws.FILTER(Tabla3[DETALLADO],(Tabla3[NIVEL]=ASIGNACION!$C19)*(Tabla3[CARRERA]=ASIGNACION!$A19),"No existe información")))} -> #REF! | BQ19: {=IFERROR( TRANSPOSE( _xlfn.UNIQUE( _xlfn._xlws.FILTER( Tabla1_1[MAESTRIA], ISNUMBER(MATCH(Tabla1_1[CAMPO_DETALLADO],BD20:BP20,0)) ) ) ), "")} | EA19: {=IFERROR( TRANSPOSE( _xlfn.UNIQUE( _xlfn._xlws.FILTER( Tabla1__2[NOMBRE_DOCENTE], ISNUMBER(MATCH(Tabla1__2[MAESTRIA],BQ19:DY19,0)) ) ) ), "")}
A20: {=TRANSPOSE(_xlfn.UNIQUE(_xlfn._xlws.FILTER(T_ASIGNATURA1[ID_NIVEL],T_ASIGNATURA1[ID_CARRERA]=ASIGNACION!$A20,"No existe información")))} -> 8 | B20: 7 | C20: 6 | D20: 5 | E20: 4 | F20: 3 | G20: 2 | H20: 1 | S20: {=TRANSPOSE(_xlfn.UNIQUE(_xlfn._xlws.FILTER(T_ASIGNATURA1[NOM_ASIG],(T_ASIGNATURA1[ID_NIVEL]=ASIGNACION!$C20)*(T_ASIGNATURA1[ID_CARRERA]=ASIGNACION!$A20),"No existe información")))} -> #REF! | BD20: {=TRANSPOSE(_xlfn.UNIQUE(_xlfn._xlws.FILTER(Tabla3[DETALLADO],(Tabla3[NIVEL]=ASIGNACION!$C20)*(Tabla3[CARRERA]=ASIGNACION!$A20),"No existe información")))} -> #REF! | BQ20: {=IFERROR( TRANSPOSE( _xlfn.UNIQUE( _xlfn._xlws.FILTER( Tabla1_1[MAESTRIA], ISNUMBER(MATCH(Tabla1_1[CAMPO_DETALLADO],BD21:BP21,0)) ) ) ), "")} | EA20: {=IFERROR( TRANSPOSE( _xlfn.UNIQUE( _xlfn._xlws.FILTER( Tabla1__2[NOMBRE_DOCENTE], ISNUMBER(MATCH(Tabla1__2[MAESTRIA],BQ20:DY20,0)) ) ) ), "")}
A21: {=TRANSPOSE(_xlfn.UNIQUE(_xlfn._xlws.FILTER(T_ASIGNATURA1[ID_NIVEL],T_ASIGNATURA1[ID_CARRERA]=ASIGNACION!$A21,"No existe información")))} -> 8 | B21: 7 | C21: 6 | D21: 5 | E21: 4 | F21: 3 | G21: 2 | H21: 1 | S21: {=TRANSPOSE(_xlfn.UNIQUE(_xlfn._xlws.FILTER(T_ASIGNATURA1[NOM_ASIG],(T_ASIGNATURA1[ID_NIVEL]=ASIGNACION!$C21)*(T_ASIGNATURA1[ID_CARRERA]=ASIGNACION!$A21),"No existe información")))} -> #REF! | BD21: {=TRANSPOSE(_xlfn.UNIQUE(_xlfn._xlws.FILTER(Tabla3[DETALLADO],(Tabla3[NIVEL]=ASIGNACION!$C21)*(Tabla3[CARRERA]=ASIGNACION!$A21),"No existe información")))} -> #REF! | BQ21: {=IFERROR( TRANSPOSE( _xlfn.UNIQUE( _xlfn._xlws.FILTER( Tabla1_1[MAESTRIA], ISNUMBER(MATCH(Tabla1_1[CAMPO_DETALLADO],BD22:BP22,0)) ) ) ), "")} | EA21: {=IFERROR( TRANSPOSE( _xlfn.UNIQUE( _xlfn._xlws.FILTER( Tabla1__2[NOMBRE_DOCENTE], ISNUMBER(MATCH(Tabla1__2[MAESTRIA],BQ21:DY21,0)) ) ) ), "")}
A22: {=TRANSPOSE(_xlfn.UNIQUE(_xlfn._xlws.FILTER(T_ASIGNATURA1[ID_NIVEL],T_ASIGNATURA1[ID_CARRERA]=ASIGNACION!$A22,"No existe información")))} -> 8 | B22: 7 | C22: 6 | D22: 5 | E22: 4 | F22: 3 | G22: 2 | H22: 1 | S22: {=TRANSPOSE(_xlfn.UNIQUE(_xlfn._xlws.FILTER(T_ASIGNATURA1[NOM_ASIG],(T_ASIGNATURA1[ID_NIVEL]=ASIGNACION!$C22)*(T_ASIGNATURA1[ID_CARRERA]=ASIGNACION!$A22),"No existe información")))} -> #REF! | BD22: {=TRANSPOSE(_xlfn.UNIQUE(_xlfn._xlws.FILTER(Tabla3[DETALLADO],(Tabla3[NIVEL]=ASIGNACION!$C22)*(Tabla3[CARRERA]=ASIGNACION!$A22),"No existe información")))} -> #REF! | BQ22: {=IFERROR( TRANSPOSE( _xlfn.UNIQUE( _xlfn._xlws.FILTER( Tabla1_1[MAESTRIA], ISNUMBER(MATCH(Tabla1_1[CAMPO_DETALLADO],BD23:BP23,0)) ) ) ), "")} | EA22: {=IFERROR( TRANSPOSE( _xlfn.UNIQUE( _xlfn._xlws.FILTER( Tabla1__2[NOMBRE_DOCENTE], ISNUMBER(MATCH(Tabla1__2[MAESTRIA],BQ22:DY22,0)) ) ) ), "")}
A23: {=TRANSPOSE(_xlfn.UNIQUE(_xlfn._xlws.FILTER(T_ASIGNATURA1[ID_NIVEL],T_ASIGNATURA1[ID_CARRERA]=ASIGNACION!$A23,"No existe información")))} -> 8 | B23: 7 | C23: 6 | D23: 5 | E23: 4 | F23: 3 | G23: 2 | H23: 1 | S23: {=TRANSPOSE(_xlfn.UNIQUE(_xlfn._xlws.FILTER(T_ASIGNATURA1[NOM_ASIG],(T_ASIGNATURA1[ID_NIVEL]=ASIGNACION!$C23)*(T_ASIGNATURA1[ID_CARRERA]=ASIGNACION!$A23),"No existe información")))} -> #REF! | BD23: {=TRANSPOSE(_xlfn.UNIQUE(_xlfn._xlws.FILTER(Tabla3[DETALLADO],(Tabla3[NIVEL]=ASIGNACION!$C23)*(Tabla3[CARRERA]=ASIGNACION!$A23),"No existe información")))} -> #REF! | BQ23: {=IFERROR( TRANSPOSE( _xlfn.UNIQUE( _xlfn._xlws.FILTER( Tabla1_1[MAESTRIA], ISNUMBER(MATCH(Tabla1_1[CAMPO_DETALLADO],BD24:BP24,0)) ) ) ), "")} | EA23: {=IFERROR( TRANSPOSE( _xlfn.UNIQUE( _xlfn._xlws.FILTER( Tabla1__2[NOMBRE_DOCENTE], ISNUMBER(MATCH(Tabla1__2[MAESTRIA],BQ23:DY23,0)) ) ) ), "")}
A24: {=TRANSPOSE(_xlfn.UNIQUE(_xlfn._xlws.FILTER(T_ASIGNATURA1[ID_NIVEL],T_ASIGNATURA1[ID_CARRERA]=ASIGNACION!$A24,"No existe información")))} -> No existe información | S24: {=TRANSPOSE(_xlfn.UNIQUE(_xlfn._xlws.FILTER(T_ASIGNATURA1[NOM_ASIG],(T_ASIGNATURA1[ID_NIVEL]=ASIGNACION!$C24)*(T_ASIGNATURA1[ID_CARRERA]=ASIGNACION!$A24),"No existe información")))} -> No existe información | BD24: {=TRANSPOSE(_xlfn.UNIQUE(_xlfn._xlws.FILTER(Tabla3[DETALLADO],(Tabla3[NIVEL]=ASIGNACION!$C24)*(Tabla3[CARRERA]=ASIGNACION!$A24),"No existe información")))} -> No existe información | BQ24: {=IFERROR( TRANSPOSE( _xlfn.UNIQUE( _xlfn._xlws.FILTER( Tabla1_1[MAESTRIA], ISNUMBER(MATCH(Tabla1_1[CAMPO_DETALLADO],BD25:BP25,0)) ) ) ), "")} | EA24: {=IFERROR( TRANSPOSE( _xlfn.UNIQUE( _xlfn._xlws.FILTER( Tabla1__2[NOMBRE_DOCENTE], ISNUMBER(MATCH(Tabla1__2[MAESTRIA],BQ24:DY24,0)) ) ) ), "")}
A25: {=TRANSPOSE(_xlfn.UNIQUE(_xlfn._xlws.FILTER(T_ASIGNATURA1[ID_NIVEL],T_ASIGNATURA1[ID_CARRERA]=ASIGNACION!$A25,"No existe información")))} -> No existe información | S25: {=TRANSPOSE(_xlfn.UNIQUE(_xlfn._xlws.FILTER(T_ASIGNATURA1[NOM_ASIG],(T_ASIGNATURA1[ID_NIVEL]=ASIGNACION!$C25)*(T_ASIGNATURA1[ID_CARRERA]=ASIGNACION!$A25),"No existe información")))} -> No existe información | BD25: {=TRANSPOSE(_xlfn.UNIQUE(_xlfn._xlws.FILTER(Tabla3[DETALLADO],(Tabla3[NIVEL]=ASIGNACION!$C25)*(Tabla3[CARRERA]=ASIGNACION!$A25),"No existe información")))} -> No existe información | BQ25: {=IFERROR( TRANSPOSE( _xlfn.UNIQUE( _xlfn._xlws.FILTER( Tabla1_1[MAESTRIA], ISNUMBER(MATCH(Tabla1_1[CAMPO_DETALLADO],BD26:BP26,0)) ) ) ), "")} | EA25: {=IFERROR( TRANSPOSE( _xlfn.UNIQUE( _xlfn._xlws.FILTER( Tabla1__2[NOMBRE_DOCENTE], ISNUMBER(MATCH(Tabla1__2[MAESTRIA],BQ25:DY25,0)) ) ) ), "")}
A26: {=TRANSPOSE(_xlfn.UNIQUE(_xlfn._xlws.FILTER(T_ASIGNATURA1[ID_NIVEL],T_ASIGNATURA1[ID_CARRERA]=ASIGNACION!$A26,"No existe información")))} -> No existe información | S26: {=TRANSPOSE(_xlfn.UNIQUE(_xlfn._xlws.FILTER(T_ASIGNATURA1[NOM_ASIG],(T_ASIGNATURA1[ID_NIVEL]=ASIGNACION!$C26)*(T_ASIGNATURA1[ID_CARRERA]=ASIGNACION!$A26),"No existe información")))} -> No existe información | BD26: {=TRANSPOSE(_xlfn.UNIQUE(_xlfn._xlws.FILTER(Tabla3[DETALLADO],(Tabla3[NIVEL]=ASIGNACION!$C26)*(Tabla3[CARRERA]=ASIGNACION!$A26),"No existe información")))} -> No existe información | BQ26: {=IFERROR( TRANSPOSE( _xlfn.UNIQUE( _xlfn._xlws.FILTER( Tabla1_1[MAESTRIA], ISNUMBER(MATCH(Tabla1_1[CAMPO_DETALLADO],BD27:BP27,0)) ) ) ), "")} | EA26: {=IFERROR( TRANSPOSE( _xlfn.UNIQUE( _xlfn._xlws.FILTER( Tabla1__2[NOMBRE_DOCENTE], ISNUMBER(MATCH(Tabla1__2[MAESTRIA],BQ26:DY26,0)) ) ) ), "")}
A27: {=TRANSPOSE(_xlfn.UNIQUE(_xlfn._xlws.FILTER(T_ASIGNATURA1[ID_NIVEL],T_ASIGNATURA1[ID_CARRERA]=ASIGNACION!$A27,"No existe información")))} -> No existe información | S27: {=TRANSPOSE(_xlfn.UNIQUE(_xlfn._xlws.FILTER(T_ASIGNATURA1[NOM_ASIG],(T_ASIGNATURA1[ID_NIVEL]=ASIGNACION!$C27)*(T_ASIGNATURA1[ID_CARRERA]=ASIGNACION!$A27),"No existe información")))} -> No existe información | BQ27: {=IFERROR( TRANSPOSE( _xlfn.UNIQUE( _xlfn._xlws.FILTER( Tabla1_1[MAESTRIA], ISNUMBER(MATCH(Tabla1_1[CAMPO_DETALLADO],BD28:BP28,0)) ) ) ), "")} | EA27: {=IFERROR( TRANSPOSE( _xlfn.UNIQUE( _xlfn._xlws.FILTER( Tabla1__2[NOMBRE_DOCENTE], ISNUMBER(MATCH(Tabla1__2[MAESTRIA],BQ27:DY27,0)) ) ) ), "")}
A28: {=TRANSPOSE(_xlfn.UNIQUE(_xlfn._xlws.FILTER(T_ASIGNATURA1[ID_NIVEL],T_ASIGNATURA1[ID_CARRERA]=ASIGNACION!$A28,"No existe información")))} -> No existe información | S28: {=TRANSPOSE(_xlfn.UNIQUE(_xlfn._xlws.FILTER(T_ASIGNATURA1[NOM_ASIG],(T_ASIGNATURA1[ID_NIVEL]=ASIGNACION!$C28)*(T_ASIGNATURA1[ID_CARRERA]=ASIGNACION!$A28),"No existe información")))} -> No existe información | BQ28: {=IFERROR( TRANSPOSE( _xlfn.UNIQUE( _xlfn._xlws.FILTER( Tabla1_1[MAESTRIA], ISNUMBER(MATCH(Tabla1_1[CAMPO_DETALLADO],BD29:BP29,0)) ) ) ), "")} | EA28: {=IFERROR( TRANSPOSE( _xlfn.UNIQUE( _xlfn._xlws.FILTER( Tabla1__2[NOMBRE_DOCENTE], ISNUMBER(MATCH(Tabla1__2[MAESTRIA],BQ28:DY28,0)) ) ) ), "")}
A29: {=TRANSPOSE(_xlfn.UNIQUE(_xlfn._xlws.FILTER(T_ASIGNATURA1[ID_NIVEL],T_ASIGNATURA1[ID_CARRERA]=ASIGNACION!$A29,"No existe información")))} -> No existe información | S29: {=TRANSPOSE(_xlfn.UNIQUE(_xlfn._xlws.FILTER(T_ASIGNATURA1[NOM_ASIG],(T_ASIGNATURA1[ID_NIVEL]=ASIGNACION!$C29)*(T_ASIGNATURA1[ID_CARRERA]=ASIGNACION!$A29),"No existe información")))} -> No existe información | BQ29: {=IFERROR( TRANSPOSE( _xlfn.UNIQUE( _xlfn._xlws.FILTER( Tabla1_1[MAESTRIA], ISNUMBER(MATCH(Tabla1_1[CAMPO_DETALLADO],BD30:BP30,0)) ) ) ), "")} | EA29: {=IFERROR( TRANSPOSE( _xlfn.UNIQUE( _xlfn._xlws.FILTER( Tabla1__2[NOMBRE_DOCENTE], ISNUMBER(MATCH(Tabla1__2[MAESTRIA],BQ29:DY29,0)) ) ) ), "")}
A30: {=TRANSPOSE(_xlfn.UNIQUE(_xlfn._xlws.FILTER(T_ASIGNATURA1[ID_NIVEL],T_ASIGNATURA1[ID_CARRERA]=ASIGNACION!$A30,"No existe información")))} -> No existe información | S30: {=TRANSPOSE(_xlfn.UNIQUE(_xlfn._xlws.FILTER(T_ASIGNATURA1[NOM_ASIG],(T_ASIGNATURA1[ID_NIVEL]=ASIGNACION!$C30)*(T_ASIGNATURA1[ID_CARRERA]=ASIGNACION!$A30),"No existe información")))} -> No existe información | BQ30: {=IFERROR( TRANSPOSE( _xlfn.UNIQUE( _xlfn._xlws.FILTER( Tabla1_1[MAESTRIA], ISNUMBER(MATCH(Tabla1_1[CAMPO_DETALLADO],BD31:BP31,0)) ) ) ), "")} | EA30: {=IFERROR( TRANSPOSE( _xlfn.UNIQUE( _xlfn._xlws.FILTER( Tabla1__2[NOMBRE_DOCENTE], ISNUMBER(MATCH(Tabla1__2[MAESTRIA],BQ30:DY30,0)) ) ) ), "")}
A31: {=TRANSPOSE(_xlfn.UNIQUE(_xlfn._xlws.FILTER(T_ASIGNATURA1[ID_NIVEL],T_ASIGNATURA1[ID_CARRERA]=ASIGNACION!$A31,"No existe información")))} -> No existe información | S31: {=TRANSPOSE(_xlfn.UNIQUE(_xlfn._xlws.FILTER(T_ASIGNATURA1[NOM_ASIG],(T_ASIGNATURA1[ID_NIVEL]=ASIGNACION!$C31)*(T_ASIGNATURA1[ID_CARRERA]=ASIGNACION!$A31),"No existe información")))} -> No existe información | BQ31: {=IFERROR( TRANSPOSE( _xlfn.UNIQUE( _xlfn._xlws.FILTER( Tabla1_1[MAESTRIA], ISNUMBER(MATCH(Tabla1_1[CAMPO_DETALLADO],BD32:BP32,0)) ) ) ), "")} | EA31: {=IFERROR( TRANSPOSE( _xlfn.UNIQUE( _xlfn._xlws.FILTER( Tabla1__2[NOMBRE_DOCENTE], ISNUMBER(MATCH(Tabla1__2[MAESTRIA],BQ31:DY31,0)) ) ) ), "")}
A32: {=TRANSPOSE(_xlfn.UNIQUE(_xlfn._xlws.FILTER(T_ASIGNATURA1[ID_NIVEL],T_ASIGNATURA1[ID_CARRERA]=ASIGNACION!$A32,"No existe información")))} -> No existe información | S32: {=TRANSPOSE(_xlfn.UNIQUE(_xlfn._xlws.FILTER(T_ASIGNATURA1[NOM_ASIG],(T_ASIGNATURA1[ID_NIVEL]=ASIGNACION!$C32)*(T_ASIGNATURA1[ID_CARRERA]=ASIGNACION!$A32),"No existe información")))} -> No existe información | BQ32: {=IFERROR( TRANSPOSE( _xlfn.UNIQUE( _xlfn._xlws.FILTER( Tabla1_1[MAESTRIA], ISNUMBER(MATCH(Tabla1_1[CAMPO_DETALLADO],BD33:BP33,0)) ) ) ), "")} | EA32: {=IFERROR( TRANSPOSE( _xlfn.UNIQUE( _xlfn._xlws.FILTER( Tabla1__2[NOMBRE_DOCENTE], ISNUMBER(MATCH(Tabla1__2[MAESTRIA],BQ32:DY32,0)) ) ) ), "")}
A33: {=TRANSPOSE(_xlfn.UNIQUE(_xlfn._xlws.FILTER(T_ASIGNATURA1[ID_NIVEL],T_ASIGNATURA1[ID_CARRERA]=ASIGNACION!$A33,"No existe información")))} -> No existe información | S33: {=TRANSPOSE(_xlfn.UNIQUE(_xlfn._xlws.FILTER(T_ASIGNATURA1[NOM_ASIG],(T_ASIGNATURA1[ID_NIVEL]=ASIGNACION!$C33)*(T_ASIGNATURA1[ID_CARRERA]=ASIGNACION!$A33),"No existe información")))} -> No existe información | BQ33: {=IFERROR( TRANSPOSE( _xlfn.UNIQUE( _xlfn._xlws.FILTER( Tabla1_1[MAESTRIA], ISNUMBER(MATCH(Tabla1_1[CAMPO_DETALLADO],BD34:BP34,0)) ) ) ), "")} | EA33: {=IFERROR( TRANSPOSE( _xlfn.UNIQUE( _xlfn._xlws.FILTER( Tabla1__2[NOMBRE_DOCENTE], ISNUMBER(MATCH(Tabla1__2[MAESTRIA],BQ33:DY33,0)) ) ) ), "")}
A34: {=TRANSPOSE(_xlfn.UNIQUE(_xlfn._xlws.FILTER(T_ASIGNATURA1[ID_NIVEL],T_ASIGNATURA1[ID_CARRERA]=ASIGNACION!$A34,"No existe información")))} -> No existe información | S34: {=TRANSPOSE(_xlfn.UNIQUE(_xlfn._xlws.FILTER(T_ASIGNATURA1[NOM_ASIG],(T_ASIGNATURA1[ID_NIVEL]=ASIGNACION!$C34)*(T_ASIGNATURA1[ID_CARRERA]=ASIGNACION!$A34),"No existe información")))} -> No existe información | BQ34: {=IFERROR( TRANSPOSE( _xlfn.UNIQUE( _xlfn._xlws.FILTER( Tabla1_1[MAESTRIA], ISNUMBER(MATCH(Tabla1_1[CAMPO_DETALLADO],BD35:BP35,0)) ) ) ), "")} | EA34: {=IFERROR( TRANSPOSE( _xlfn.UNIQUE( _xlfn._xlws.FILTER( Tabla1__2[NOMBRE_DOCENTE], ISNUMBER(MATCH(Tabla1__2[MAESTRIA],BQ34:DY34,0)) ) ) ), "")}
A35: {=TRANSPOSE(_xlfn.UNIQUE(_xlfn._xlws.FILTER(T_ASIGNATURA1[ID_NIVEL],T_ASIGNATURA1[ID_CARRERA]=ASIGNACION!$A35,"No existe información")))} -> No existe información | S35: {=TRANSPOSE(_xlfn.UNIQUE(_xlfn._xlws.FILTER(T_ASIGNATURA1[NOM_ASIG],(T_ASIGNATURA1[ID_NIVEL]=ASIGNACION!$C35)*(T_ASIGNATURA1[ID_CARRERA]=ASIGNACION!$A35),"No existe información")))} -> No existe información | BQ35: {=IFERROR( TRANSPOSE( _xlfn.UNIQUE( _xlfn._xlws.FILTER( Tabla1_1[MAESTRIA], ISNUMBER(MATCH(Tabla1_1[CAMPO_DETALLADO],BD36:BP36,0)) ) ) ), "")} | EA35: {=IFERROR( TRANSPOSE( _xlfn.UNIQUE( _xlfn._xlws.FILTER( Tabla1__2[NOMBRE_DOCENTE], ISNUMBER(MATCH(Tabla1__2[MAESTRIA],BQ35:DY35,0)) ) ) ), "")}
A36: {=TRANSPOSE(_xlfn.UNIQUE(_xlfn._xlws.FILTER(T_ASIGNATURA1[ID_NIVEL],T_ASIGNATURA1[ID_CARRERA]=ASIGNACION!$A36,"No existe información")))} -> No existe información | S36: {=TRANSPOSE(_xlfn.UNIQUE(_xlfn._xlws.FILTER(T_ASIGNATURA1[NOM_ASIG],(T_ASIGNATURA1[ID_NIVEL]=ASIGNACION!$C36)*(T_ASIGNATURA1[ID_CARRERA]=ASIGNACION!$A36),"No existe información")))} -> No existe información | BQ36: {=IFERROR( TRANSPOSE( _xlfn.UNIQUE( _xlfn._xlws.FILTER( Tabla1_1[MAESTRIA], ISNUMBER(MATCH(Tabla1_1[CAMPO_DETALLADO],BD37:BP37,0)) ) ) ), "")} | EA36: {=IFERROR( TRANSPOSE( _xlfn.UNIQUE( _xlfn._xlws.FILTER( Tabla1__2[NOMBRE_DOCENTE], ISNUMBER(MATCH(Tabla1__2[MAESTRIA],BQ36:DY36,0)) ) ) ), "")}
A37: {=TRANSPOSE(_xlfn.UNIQUE(_xlfn._xlws.FILTER(T_ASIGNATURA1[ID_NIVEL],T_ASIGNATURA1[ID_CARRERA]=ASIGNACION!$A37,"No existe información")))} -> No existe información | S37: {=TRANSPOSE(_xlfn.UNIQUE(_xlfn._xlws.FILTER(T_ASIGNATURA1[NOM_ASIG],(T_ASIGNATURA1[ID_NIVEL]=ASIGNACION!$C37)*(T_ASIGNATURA1[ID_CARRERA]=ASIGNACION!$A37),"No existe información")))} -> No existe información | BQ37: {=IFERROR( TRANSPOSE( _xlfn.UNIQUE( _xlfn._xlws.FILTER( Tabla1_1[MAESTRIA], ISNUMBER(MATCH(Tabla1_1[CAMPO_DETALLADO],BD38:BP38,0)) ) ) ), "")} | EA37: {=IFERROR( TRANSPOSE( _xlfn.UNIQUE( _xlfn._xlws.FILTER( Tabla1__2[NOMBRE_DOCENTE], ISNUMBER(MATCH(Tabla1__2[MAESTRIA],BQ37:DY37,0)) ) ) ), "")}
A38: {=TRANSPOSE(_xlfn.UNIQUE(_xlfn._xlws.FILTER(T_ASIGNATURA1[ID_NIVEL],T_ASIGNATURA1[ID_CARRERA]=ASIGNACION!$A38,"No existe información")))} -> No existe información | S38: {=TRANSPOSE(_xlfn.UNIQUE(_xlfn._xlws.FILTER(T_ASIGNATURA1[NOM_ASIG],(T_ASIGNATURA1[ID_NIVEL]=ASIGNACION!$C38)*(T_ASIGNATURA1[ID_CARRERA]=ASIGNACION!$A38),"No existe información")))} -> No existe información | BQ38: {=IFERROR( TRANSPOSE( _xlfn.UNIQUE( _xlfn._xlws.FILTER( Tabla1_1[MAESTRIA], ISNUMBER(MATCH(Tabla1_1[CAMPO_DETALLADO],BD39:BP39,0)) ) ) ), "")} | EA38: {=IFERROR( TRANSPOSE( _xlfn.UNIQUE( _xlfn._xlws.FILTER( Tabla1__2[NOMBRE_DOCENTE], ISNUMBER(MATCH(Tabla1__2[MAESTRIA],BQ38:DY38,0)) ) ) ), "")}
... A602: {=TRANSPOSE(_xlfn.UNIQUE(_xlfn._xlws.FILTER(T_ASIGNATURA1[ID_NIVEL],T_ASIGNATURA1[ID_CARRERA]=ASIGNACION!$A602,"No existe información")))} -> No existe información | S602: {=TRANSPOSE(_xlfn.UNIQUE(_xlfn._xlws.FILTER(T_ASIGNATURA1[NOM_ASIG],(T_ASIGNATURA1[ID_NIVEL]=ASIGNACION!$C602)*(T_ASIGNATURA1[ID_CARRERA]=ASIGNACION!$A602),"No existe información")))} -> No existe información | BQ602: {=IFERROR( TRANSPOSE( _xlfn.UNIQUE( _xlfn._xlws.FILTER( Tabla1_1[MAESTRIA], ISNUMBER(MATCH(Tabla1_1[CAMPO_DETALLADO],BD603:BP603,0)) ) ) ), "")} | EA602: {=IFERROR( TRANSPOSE( _xlfn.UNIQUE( _xlfn._xlws.FILTER( Tabla1__2[NOMBRE_DOCENTE], ISNUMBER(MATCH(Tabla1__2[MAESTRIA],BQ602:DY602,0)) ) ) ), "")}
BQ603: {=IFERROR( TRANSPOSE( _xlfn.UNIQUE( _xlfn._xlws.FILTER( Tabla1_1[MAESTRIA], ISNUMBER(MATCH(Tabla1_1[CAMPO_DETALLADO],BD604:BP604,0)) ) ) ), "")} | EA603: {=IFERROR( TRANSPOSE( _xlfn.UNIQUE( _xlfn._xlws.FILTER( Tabla1__2[NOMBRE_DOCENTE], ISNUMBER(MATCH(Tabla1__2[MAESTRIA],BQ603:DY603,0)) ) ) ), "")}
BQ604: {=IFERROR( TRANSPOSE( _xlfn.UNIQUE( _xlfn._xlws.FILTER( Tabla1_1[MAESTRIA], ISNUMBER(MATCH(Tabla1_1[CAMPO_DETALLADO],BD605:BP605,0)) ) ) ), "")} | EA604: {=IFERROR( TRANSPOSE( _xlfn.UNIQUE( _xlfn._xlws.FILTER( Tabla1__2[NOMBRE_DOCENTE], ISNUMBER(MATCH(Tabla1__2[MAESTRIA],BQ604:DY604,0)) ) ) ), "")}
...

Sheet ASIGNACION
A1: CARRERA | B1: ID_CARRERA | C1: NIVEL | D1: PARALELO | E1: ASIGNATURA | F1: CAMPO | G1: AFINIDAD | H1: HORAS | I1: # SEMANAS | J1: HORAS_SEMANAS | K1: H.ADI_01 | L1: H.ADI_02 | M1: H.INVESTIGACION | N1: TOTAL | O1: NOMBRE_DOCENT | P1: TOTAL_HORAS_DOCENTE | Q1: CEDULA_DOCENTE
A2: AUDITORÍA Y CONTROL DE GESTIÓN 2024 | B2: =_xlfn.XLOOKUP(Tabla1[[#This Row],[CARRERA]],T_CARREAS1[NOMBRE_CARRERA],T_CARREAS1[ID_CARRERA]) -> 2026-FCACC-2 | C2: 1 | D2: A | E2: FUNDAMENTOS DE ADMINISTRACIÓN | F2: {=_xlfn.TEXTJOIN(", ",TRUE,TRANSPOSE(_xlfn.UNIQUE(_xlfn._xlws.FILTER(Tabla3[DETALLADO],(Tabla3[NIVEL]=ASIGNACION!$C2)*(Tabla3[CARRERA]=ASIGNACION!$A2)*(Tabla3[ASIGNATURA]=ASIGNACION!$E2),"No existe información"))))} -> No existe información | G2: NO | H2: {=_xlfn.SINGLE(_xlfn.XLOOKUP(1,(T_ASIGNATURA1[ID_CARRERA]=Tabla1[[#This Row],[CARRERA]])*(T_ASIGNATURA1[NOM_ASIG]=Tabla1[[#This Row],[ASIGNATURA]])*(T_ASIGNATURA1[ID_NIVEL]=Tabla1[[#This Row],[NIVEL]]),T_ASIGNATURA1[HORAS],0))} -> 5 | I2: 9 | J2: =+Tabla1[[#This Row],['# SEMANAS]]*Tabla1[[#This Row],[HORAS]] -> 45 | M2: 5 | N2: =+Tabla1[[#This Row],[H.INVESTIGACION]]+Tabla1[[#This Row],[H.ADI_02]]+Tabla1[[#This Row],[H.ADI_01]]+Tabla1[[#This Row],[HORAS_SEMANAS]] -> 50 | O2: SORNOZA ZAMORA JUAN CARLOS | P2: =SUMIF($O:$O, O2, $N:$N) -> 97 | Q2: =_xlfn.XLOOKUP(Tabla1[[#This Row],[NOMBRE_DOCENT]],Tabla1__3[DATOS_DOCENTE],Tabla1__3[ID_DOCENTE]) -> 1311778698
A3: AUDITORÍA Y CONTROL DE GESTIÓN 2024 | B3: =_xlfn.XLOOKUP(Tabla1[[#This Row],[CARRERA]],T_CARREAS1[NOMBRE_CARRERA],T_CARREAS1[ID_CARRERA]) -> 2026-FCACC-2 | C3: 4 | D3: A | E3: CONTABILIDAD EN EL SECTOR PÚBLICO | F3: {=_xlfn.TEXTJOIN(", ",TRUE,TRANSPOSE(_xlfn.UNIQUE(_xlfn._xlws.FILTER(Tabla3[DETALLADO],(Tabla3[NIVEL]=ASIGNACION!$C3)*(Tabla3[CARRERA]=ASIGNACION!$A3)*(Tabla3[ASIGNATURA]=ASIGNACION!$E3),"No existe información"))))} -> No existe información | G3: SI | H3: {=_xlfn.SINGLE(_xlfn.XLOOKUP(1,(T_ASIGNATURA1[ID_CARRERA]=Tabla1[[#This Row],[CARRERA]])*(T_ASIGNATURA1[NOM_ASIG]=Tabla1[[#This Row],[ASIGNATURA]])*(T_ASIGNATURA1[ID_NIVEL]=Tabla1[[#This Row],[NIVEL]]),T_ASIGNATURA1[HORAS],0))} -> 4 | I3: 9 | J3: =+Tabla1[[#This Row],['# SEMANAS]]*Tabla1[[#This Row],[HORAS]] -> 36 | M3: 6 | N3: =+Tabla1[[#This Row],[H.INVESTIGACION]]+Tabla1[[#This Row],[H.ADI_02]]+Tabla1[[#This Row],[H.ADI_01]]+Tabla1[[#This Row],[HORAS_SEMANAS]] -> 42 | O3: SORNOZA ZAMORA JUAN CARLOS | P3: =SUMIF($O:$O, O3, $N:$N) -> 97 | Q3: =_xlfn.XLOOKUP(Tabla1[[#This Row],[NOMBRE_DOCENT]],Tabla1__3[DATOS_DOCENTE],Tabla1__3[ID_DOCENTE]) -> 1311778698
A4: AUDITORÍA Y CONTROL DE GESTIÓN 2024 | B4: =_xlfn.XLOOKUP(Tabla1[[#This Row],[CARRERA]],T_CARREAS1[NOMBRE_CARRERA],T_CARREAS1[ID_CARRERA]) -> 2026-FCACC-2 | C4: 4 | E4: MACROECONOMÍA | F4: {=_xlfn.TEXTJOIN(", ",TRUE,TRANSPOSE(_xlfn.UNIQUE(_xlfn._xlws.FILTER(Tabla3[DETALLADO],(Tabla3[NIVEL]=ASIGNACION!$C4)*(Tabla3[CARRERA]=ASIGNACION!$A4)*(Tabla3[ASIGNATURA]=ASIGNACION!$E4),"No existe información"))))} -> No existe información | H4: {=_xlfn.SINGLE(_xlfn.XLOOKUP(1,(T_ASIGNATURA1[ID_CARRERA]=Tabla1[[#This Row],[CARRERA]])*(T_ASIGNATURA1[NOM_ASIG]=Tabla1[[#This Row],[ASIGNATURA]])*(T_ASIGNATURA1[ID_NIVEL]=Tabla1[[#This Row],[NIVEL]]),T_ASIGNATURA1[HORAS],0))} -> 0 | J4: =+Tabla1[[#This Row],['# SEMANAS]]*Tabla1[[#This Row],[HORAS]] -> 0 | M4: 5 | N4: =+Tabla1[[#This Row],[H.INVESTIGACION]]+Tabla1[[#This Row],[H.ADI_02]]+Tabla1[[#This Row],[H.ADI_01]]+Tabla1[[#This Row],[HORAS_SEMANAS]] -> 5 | O4: SORNOZA ZAMORA JUAN CARLOS | P4: =SUMIF($O:$O, O4, $N:$N) -> 97 | Q4: =_xlfn.XLOOKUP(Tabla1[[#This Row],[NOMBRE_DOCENT]],Tabla1__3[DATOS_DOCENTE],Tabla1__3[ID_DOCENTE]) -> 1311778698
A5: AUDITORÍA Y CONTROL DE GESTIÓN 2024 | B5: =_xlfn.XLOOKUP(Tabla1[[#This Row],[CARRERA]],T_CARREAS1[NOMBRE_CARRERA],T_CARREAS1[ID_CARRERA]) -> 2026-FCACC-2 | C5: 4 | D5: A | E5: GESTIÓN DOCUMENTAL Y ARCHIVÍSTICA | F5: {=_xlfn.TEXTJOIN(", ",TRUE,TRANSPOSE(_xlfn.UNIQUE(_xlfn._xlws.FILTER(Tabla3[DETALLADO],(Tabla3[NIVEL]=ASIGNACION!$C5)*(Tabla3[CARRERA]=ASIGNACION!$A5)*(Tabla3[ASIGNATURA]=ASIGNACION!$E5),"No existe información"))))} -> No existe información | H5: {=_xlfn.SINGLE(_xlfn.XLOOKUP(1,(T_ASIGNATURA1[ID_CARRERA]=Tabla1[[#This Row],[CARRERA]])*(T_ASIGNATURA1[NOM_ASIG]=Tabla1[[#This Row],[ASIGNATURA]])*(T_ASIGNATURA1[ID_NIVEL]=Tabla1[[#This Row],[NIVEL]]),T_ASIGNATURA1[HORAS],0))} -> 0 | J5: =+Tabla1[[#This Row],['# SEMANAS]]*Tabla1[[#This Row],[HORAS]] -> 0 | N5: =+Tabla1[[#This Row],[H.INVESTIGACION]]+Tabla1[[#This Row],[H.ADI_02]]+Tabla1[[#This Row],[H.ADI_01]]+Tabla1[[#This Row],[HORAS_SEMANAS]] -> 0 | O5: CALDERON ZAMORA OSCAR XAVIER | P5: =SUMIF($O:$O, O5, $N:$N) -> 0 | Q5: =_xlfn.XLOOKUP(Tabla1[[#This Row],[NOMBRE_DOCENT]],Tabla1__3[DATOS_DOCENTE],Tabla1__3[ID_DOCENTE]) -> 1310729676
A6: AUDITORÍA Y CONTROL DE GESTIÓN 2024 | B6: =_xlfn.XLOOKUP(Tabla1[[#This Row],[CARRERA]],T_CARREAS1[NOMBRE_CARRERA],T_CARREAS1[ID_CARRERA]) -> 2026-FCACC-2 | C6: 4 | E6: 04 ADMINISTRACIÓN DEL TALENTO HUMANO | F6: {=_xlfn.TEXTJOIN(", ",TRUE,TRANSPOSE(_xlfn.UNIQUE(_xlfn._xlws.FILTER(Tabla3[DETALLADO],(Tabla3[NIVEL]=ASIGNACION!$C6)*(Tabla3[CARRERA]=ASIGNACION!$A6)*(Tabla3[ASIGNATURA]=ASIGNACION!$E6),"No existe información"))))} -> No existe información | H6: {=_xlfn.SINGLE(_xlfn.XLOOKUP(1,(T_ASIGNATURA1[ID_CARRERA]=Tabla1[[#This Row],[CARRERA]])*(T_ASIGNATURA1[NOM_ASIG]=Tabla1[[#This Row],[ASIGNATURA]])*(T_ASIGNATURA1[ID_NIVEL]=Tabla1[[#This Row],[NIVEL]]),T_ASIGNATURA1[HORAS],0))} -> 0 | J6: =+Tabla1[[#This Row],['# SEMANAS]]*Tabla1[[#This Row],[HORAS]] -> 0 | N6: =+Tabla1[[#This Row],[H.INVESTIGACION]]+Tabla1[[#This Row],[H.ADI_02]]+Tabla1[[#This Row],[H.ADI_01]]+Tabla1[[#This Row],[HORAS_SEMANAS]] -> 0 | O6: ALVIA TOALA DAHIANA VALERIA | P6: =SUMIF($O:$O, O6, $N:$N) -> 0 | Q6: =_xlfn.XLOOKUP(Tabla1[[#This Row],[NOMBRE_DOCENT]],Tabla1__3[DATOS_DOCENTE],Tabla1__3[ID_DOCENTE]) -> 1312179292
A7: AUDITORÍA Y CONTROL DE GESTIÓN 2024 | B7: =_xlfn.XLOOKUP(Tabla1[[#This Row],[CARRERA]],T_CARREAS1[NOMBRE_CARRERA],T_CARREAS1[ID_CARRERA]) -> 2026-FCACC-2 | C7: 4 | E7: PLANIFICACIÓN Y DIRECCIÓN ESTRATÉGICA | F7: {=_xlfn.TEXTJOIN(", ",TRUE,TRANSPOSE(_xlfn.UNIQUE(_xlfn._xlws.FILTER(Tabla3[DETALLADO],(Tabla3[NIVEL]=ASIGNACION!$C7)*(Tabla3[CARRERA]=ASIGNACION!$A7)*(Tabla3[ASIGNATURA]=ASIGNACION!$E7),"No existe información"))))} -> No existe información | H7: {=_xlfn.SINGLE(_xlfn.XLOOKUP(1,(T_ASIGNATURA1[ID_CARRERA]=Tabla1[[#This Row],[CARRERA]])*(T_ASIGNATURA1[NOM_ASIG]=Tabla1[[#This Row],[ASIGNATURA]])*(T_ASIGNATURA1[ID_NIVEL]=Tabla1[[#This Row],[NIVEL]]),T_ASIGNATURA1[HORAS],0))} -> 4 | J7: =+Tabla1[[#This Row],['# SEMANAS]]*Tabla1[[#This Row],[HORAS]] -> 0 | N7: =+Tabla1[[#This Row],[H.INVESTIGACION]]+Tabla1[[#This Row],[H.ADI_02]]+Tabla1[[#This Row],[H.ADI_01]]+Tabla1[[#This Row],[HORAS_SEMANAS]] -> 0 | O7: BALSECA MACIAS PAOLA ESTEFANIA | P7: =SUMIF($O:$O, O7, $N:$N) -> 0 | Q7: =_xlfn.XLOOKUP(Tabla1[[#This Row],[NOMBRE_DOCENT]],Tabla1__3[DATOS_DOCENTE],Tabla1__3[ID_DOCENTE]) -> 1308397239
A8: AUDITORÍA Y CONTROL DE GESTIÓN 2024 | B8: =_xlfn.XLOOKUP(Tabla1[[#This Row],[CARRERA]],T_CARREAS1[NOMBRE_CARRERA],T_CARREAS1[ID_CARRERA]) -> 2026-FCACC-2 | C8: 3 | D8: B | E8: CONTABILIDAD AVANZADA | F8: {=_xlfn.TEXTJOIN(", ",TRUE,TRANSPOSE(_xlfn.UNIQUE(_xlfn._xlws.FILTER(Tabla3[DETALLADO],(Tabla3[NIVEL]=ASIGNACION!$C8)*(Tabla3[CARRERA]=ASIGNACION!$A8)*(Tabla3[ASIGNATURA]=ASIGNACION!$E8),"No existe información"))))} -> No existe información | H8: {=_xlfn.SINGLE(_xlfn.XLOOKUP(1,(T_ASIGNATURA1[ID_CARRERA]=Tabla1[[#This Row],[CARRERA]])*(T_ASIGNATURA1[NOM_ASIG]=Tabla1[[#This Row],[ASIGNATURA]])*(T_ASIGNATURA1[ID_NIVEL]=Tabla1[[#This Row],[NIVEL]]),T_ASIGNATURA1[HORAS],0))} -> 0 | J8: =+Tabla1[[#This Row],['# SEMANAS]]*Tabla1[[#This Row],[HORAS]] -> 0 | N8: =+Tabla1[[#This Row],[H.INVESTIGACION]]+Tabla1[[#This Row],[H.ADI_02]]+Tabla1[[#This Row],[H.ADI_01]]+Tabla1[[#This Row],[HORAS_SEMANAS]] -> 0 | O8: SORNOZA ZAMORA JUAN CARLOS | P8: =SUMIF($O:$O, O8, $N:$N) -> 97 | Q8: =_xlfn.XLOOKUP(Tabla1[[#This Row],[NOMBRE_DOCENT]],Tabla1__3[DATOS_DOCENTE],Tabla1__3[ID_DOCENTE]) -> 1311778698
A9: AUDITORÍA Y CONTROL DE GESTIÓN 2024 | B9: =_xlfn.XLOOKUP(Tabla1[[#This Row],[CARRERA]],T_CARREAS1[NOMBRE_CARRERA],T_CARREAS1[ID_CARRERA]) -> 2026-FCACC-2 | C9: 8 | E9: BUSINESS ENGLISH | F9: {=_xlfn.TEXTJOIN(", ",TRUE,TRANSPOSE(_xlfn.UNIQUE(_xlfn._xlws.FILTER(Tabla3[DETALLADO],(Tabla3[NIVEL]=ASIGNACION!$C9)*(Tabla3[CARRERA]=ASIGNACION!$A9)*(Tabla3[ASIGNATURA]=ASIGNACION!$E9),"No existe información"))))} -> No existe información | H9: {=_xlfn.SINGLE(_xlfn.XLOOKUP(1,(T_ASIGNATURA1[ID_CARRERA]=Tabla1[[#This Row],[CARRERA]])*(T_ASIGNATURA1[NOM_ASIG]=Tabla1[[#This Row],[ASIGNATURA]])*(T_ASIGNATURA1[ID_NIVEL]=Tabla1[[#This Row],[NIVEL]]),T_ASIGNATURA1[HORAS],0))} -> 0 | J9: =+Tabla1[[#This Row],['# SEMANAS]]*Tabla1[[#This Row],[HORAS]] -> 0 | N9: =+Tabla1[[#This Row],[H.INVESTIGACION]]+Tabla1[[#This Row],[H.ADI_02]]+Tabla1[[#This Row],[H.ADI_01]]+Tabla1[[#This Row],[HORAS_SEMANAS]] -> 0 | P9: =SUMIF($O:$O, O9, $N:$N) -> 0 | Q9: =_xlfn.XLOOKUP(Tabla1[[#This Row],[NOMBRE_DOCENT]],Tabla1__3[DATOS_DOCENTE],Tabla1__3[ID_DOCENTE]) -> #N/A
A10: AUDITORÍA Y CONTROL DE GESTIÓN 2024 | B10: =_xlfn.XLOOKUP(Tabla1[[#This Row],[CARRERA]],T_CARREAS1[NOMBRE_CARRERA],T_CARREAS1[ID_CARRERA]) -> 2026-FCACC-2 | C10: 4 | E10: 04 EMPLEABILIDAD Y DESARROLLO PROFESIONAL (GTH) | F10: {=_xlfn.TEXTJOIN(", ",TRUE,TRANSPOSE(_xlfn.UNIQUE(_xlfn._xlws.FILTER(Tabla3[DETALLADO],(Tabla3[NIVEL]=ASIGNACION!$C10)*(Tabla3[CARRERA]=ASIGNACION!$A10)*(Tabla3[ASIGNATURA]=ASIGNACION!$E10),"No existe información"))))} -> No existe información | H10: {=_xlfn.SINGLE(_xlfn.XLOOKUP(1,(T_ASIGNATURA1[ID_CARRERA]=Tabla1[[#This Row],[CARRERA]])*(T_ASIGNATURA1[NOM_ASIG]=Tabla1[[#This Row],[ASIGNATURA]])*(T_ASIGNATURA1[ID_NIVEL]=Tabla1[[#This Row],[NIVEL]]),T_ASIGNATURA1[HORAS],0))} -> 0 | J10: =+Tabla1[[#This Row],['# SEMANAS]]*Tabla1[[#This Row],[HORAS]] -> 0 | N10: =+Tabla1[[#This Row],[H.INVESTIGACION]]+Tabla1[[#This Row],[H.ADI_02]]+Tabla1[[#This Row],[H.ADI_01]]+Tabla1[[#This Row],[HORAS_SEMANAS]] -> 0 | P10: =SUMIF($O:$O, O10, $N:$N) -> 0 | Q10: =_xlfn.XLOOKUP(Tabla1[[#This Row],[NOMBRE_DOCENT]],Tabla1__3[DATOS_DOCENTE],Tabla1__3[ID_DOCENTE]) -> #N/A
A11: AUDITORÍA Y CONTROL DE GESTIÓN 2024 | B11: =_xlfn.XLOOKUP(Tabla1[[#This Row],[CARRERA]],T_CARREAS1[NOMBRE_CARRERA],T_CARREAS1[ID_CARRERA]) -> 2026-FCACC-2 | C11: 4 | E11: HERRAMIENTAS DIGITALES AVANZADAS PARA LA GESTIÓN DE INFORMACIÓN | F11: {=_xlfn.TEXTJOIN(", ",TRUE,TRANSPOSE(_xlfn.UNIQUE(_xlfn._xlws.FILTER(Tabla3[DETALLADO],(Tabla3[NIVEL]=ASIGNACION!$C11)*(Tabla3[CARRERA]=ASIGNACION!$A11)*(Tabla3[ASIGNATURA]=ASIGNACION!$E11),"No existe información"))))} -> No existe información | H11: {=_xlfn.SINGLE(_xlfn.XLOOKUP(1,(T_ASIGNATURA1[ID_CARRERA]=Tabla1[[#This Row],[CARRERA]])*(T_ASIGNATURA1[NOM_ASIG]=Tabla1[[#This Row],[ASIGNATURA]])*(T_ASIGNATURA1[ID_NIVEL]=Tabla1[[#This Row],[NIVEL]]),T_ASIGNATURA1[HORAS],0))} -> 0 | J11: =+Tabla1[[#This Row],['# SEMANAS]]*Tabla1[[#This Row],[HORAS]] -> 0 | N11: =+Tabla1[[#This Row],[H.INVESTIGACION]]+Tabla1[[#This Row],[H.ADI_02]]+Tabla1[[#This Row],[H.ADI_01]]+Tabla1[[#This Row],[HORAS_SEMANAS]] -> 0 | O11: CARRILLO PICO FEDERICO AVELINO | P11: =SUMIF($O:$O, O11, $N:$N) -> 0 | Q11: =_xlfn.XLOOKUP(Tabla1[[#This Row],[NOMBRE_DOCENT]],Tabla1__3[DATOS_DOCENTE],Tabla1__3[ID_DOCENTE]) -> 1311778458
A12: AUDITORÍA Y CONTROL DE GESTIÓN 2024 | B12: =_xlfn.XLOOKUP(Tabla1[[#This Row],[CARRERA]],T_CARREAS1[NOMBRE_CARRERA],T_CARREAS1[ID_CARRERA]) -> 2026-FCACC-2 | C12: 8 | E12: BUSINESS INTELLIGENCE | F12: {=_xlfn.TEXTJOIN(", ",TRUE,TRANSPOSE(_xlfn.UNIQUE(_xlfn._xlws.FILTER(Tabla3[DETALLADO],(Tabla3[NIVEL]=ASIGNACION!$C12)*(Tabla3[CARRERA]=ASIGNACION!$A12)*(Tabla3[ASIGNATURA]=ASIGNACION!$E12),"No existe información"))))} -> No existe información | H12: {=_xlfn.SINGLE(_xlfn.XLOOKUP(1,(T_ASIGNATURA1[ID_CARRERA]=Tabla1[[#This Row],[CARRERA]])*(T_ASIGNATURA1[NOM_ASIG]=Tabla1[[#This Row],[ASIGNATURA]])*(T_ASIGNATURA1[ID_NIVEL]=Tabla1[[#This Row],[NIVEL]]),T_ASIGNATURA1[HORAS],0))} -> 0 | J12: =+Tabla1[[#This Row],['# SEMANAS]]*Tabla1[[#This Row],[HORAS]] -> 0 | N12: =+Tabla1[[#This Row],[H.INVESTIGACION]]+Tabla1[[#This Row],[H.ADI_02]]+Tabla1[[#This Row],[H.ADI_01]]+Tabla1[[#This Row],[HORAS_SEMANAS]] -> 0 | P12: =SUMIF($O:$O, O12, $N:$N) -> 0 | Q12: =_xlfn.XLOOKUP(Tabla1[[#This Row],[NOMBRE_DOCENT]],Tabla1__3[DATOS_DOCENTE],Tabla1__3[ID_DOCENTE]) -> #N/A
A13: AUDITORÍA Y CONTROL DE GESTIÓN 2024 | B13: =_xlfn.XLOOKUP(Tabla1[[#This Row],[CARRERA]],T_CARREAS1[NOMBRE_CARRERA],T_CARREAS1[ID_CARRERA]) -> 2026-FCACC-2 | C13: 2 | E13: 02 ADMINISTRACIÓN ESTRATÉGICA | F13: {=_xlfn.TEXTJOIN(", ",TRUE,TRANSPOSE(_xlfn.UNIQUE(_xlfn._xlws.FILTER(Tabla3[DETALLADO],(Tabla3[NIVEL]=ASIGNACION!$C13)*(Tabla3[CARRERA]=ASIGNACION!$A13)*(Tabla3[ASIGNATURA]=ASIGNACION!$E13),"No existe información"))))} -> No existe información | H13: {=_xlfn.SINGLE(_xlfn.XLOOKUP(1,(T_ASIGNATURA1[ID_CARRERA]=Tabla1[[#This Row],[CARRERA]])*(T_ASIGNATURA1[NOM_ASIG]=Tabla1[[#This Row],[ASIGNATURA]])*(T_ASIGNATURA1[ID_NIVEL]=Tabla1[[#This Row],[NIVEL]]),T_ASIGNATURA1[HORAS],0))} -> 0 | J13: =+Tabla1[[#This Row],['# SEMANAS]]*Tabla1[[#This Row],[HORAS]] -> 0 | N13: =+Tabla1[[#This Row],[H.INVESTIGACION]]+Tabla1[[#This Row],[H.ADI_02]]+Tabla1[[#This Row],[H.ADI_01]]+Tabla1[[#This Row],[HORAS_SEMANAS]] -> 0 | P13: =SUMIF($O:$O, O13, $N:$N) -> 0 | Q13: =_xlfn.XLOOKUP(Tabla1[[#This Row],[NOMBRE_DOCENT]],Tabla1__3[DATOS_DOCENTE],Tabla1__3[ID_DOCENTE]) -> #N/A
A14: AUDITORÍA Y CONTROL DE GESTIÓN 2024 | B14: =_xlfn.XLOOKUP(Tabla1[[#This Row],[CARRERA]],T_CARREAS1[NOMBRE_CARRERA],T_CARREAS1[ID_CARRERA]) -> 2026-FCACC-2 | C14: 1 | E14: 01 DERECHO APLICADO A LA GESTIÓN INMOBIIARIA (BR) | F14: {=_xlfn.TEXTJOIN(", ",TRUE,TRANSPOSE(_xlfn.UNIQUE(_xlfn._xlws.FILTER(Tabla3[DETALLADO],(Tabla3[NIVEL]=ASIGNACION!$C14)*(Tabla3[CARRERA]=ASIGNACION!$A14)*(Tabla3[ASIGNATURA]=ASIGNACION!$E14),"No existe información"))))} -> No existe información | H14: {=_xlfn.SINGLE(_xlfn.XLOOKUP(1,(T_ASIGNATURA1[ID_CARRERA]=Tabla1[[#This Row],[CARRERA]])*(T_ASIGNATURA1[NOM_ASIG]=Tabla1[[#This Row],[ASIGNATURA]])*(T_ASIGNATURA1[ID_NIVEL]=Tabla1[[#This Row],[NIVEL]]),T_ASIGNATURA1[HORAS],0))} -> 0 | J14: =+Tabla1[[#This Row],['# SEMANAS]]*Tabla1[[#This Row],[HORAS]] -> 0 | N14: =+Tabla1[[#This Row],[H.INVESTIGACION]]+Tabla1[[#This Row],[H.ADI_02]]+Tabla1[[#This Row],[H.ADI_01]]+Tabla1[[#This Row],[HORAS_SEMANAS]] -> 0 | P14: =SUMIF($O:$O, O14, $N:$N) -> 0 | Q14: =_xlfn.XLOOKUP(Tabla1[[#This Row],[NOMBRE_DOCENT]],Tabla1__3[DATOS_DOCENTE],Tabla1__3[ID_DOCENTE]) -> #N/A
A15: AUDITORÍA Y CONTROL DE GESTIÓN 2024 | B15: =_xlfn.XLOOKUP(Tabla1[[#This Row],[CARRERA]],T_CARREAS1[NOMBRE_CARRERA],T_CARREAS1[ID_CARRERA]) -> 2026-FCACC-2 | F15: {=_xlfn.TEXTJOIN(", ",TRUE,TRANSPOSE(_xlfn.UNIQUE(_xlfn._xlws.FILTER(Tabla3[DETALLADO],(Tabla3[NIVEL]=ASIGNACION!$C15)*(Tabla3[CARRERA]=ASIGNACION!$A15)*(Tabla3[ASIGNATURA]=ASIGNACION!$E15),"No existe información"))))} -> No existe información | H15: {=_xlfn.SINGLE(_xlfn.XLOOKUP(1,(T_ASIGNATURA1[ID_CARRERA]=Tabla1[[#This Row],[CARRERA]])*(T_ASIGNATURA1[NOM_ASIG]=Tabla1[[#This Row],[ASIGNATURA]])*(T_ASIGNATURA1[ID_NIVEL]=Tabla1[[#This Row],[NIVEL]]),T_ASIGNATURA1[HORAS],0))} -> 0 | J15: =+Tabla1[[#This Row],['# SEMANAS]]*Tabla1[[#This Row],[HORAS]] -> 0 | N15: =+Tabla1[[#This Row],[H.INVESTIGACION]]+Tabla1[[#This Row],[H.ADI_02]]+Tabla1[[#This Row],[H.ADI_01]]+Tabla1[[#This Row],[HORAS_SEMANAS]] -> 0 | P15: =SUMIF($O:$O, O15, $N:$N) -> 0 | Q15: =_xlfn.XLOOKUP(Tabla1[[#This Row],[NOMBRE_DOCENT]],Tabla1__3[DATOS_DOCENTE],Tabla1__3[ID_DOCENTE]) -> #N/A
A16: AUDITORÍA Y CONTROL DE GESTIÓN 2024 | B16: =_xlfn.XLOOKUP(Tabla1[[#This Row],[CARRERA]],T_CARREAS1[NOMBRE_CARRERA],T_CARREAS1[ID_CARRERA]) -> 2026-FCACC-2 | F16: {=_xlfn.TEXTJOIN(", ",TRUE,TRANSPOSE(_xlfn.UNIQUE(_xlfn._xlws.FILTER(Tabla3[DETALLADO],(Tabla3[NIVEL]=ASIGNACION!$C16)*(Tabla3[CARRERA]=ASIGNACION!$A16)*(Tabla3[ASIGNATURA]=ASIGNACION!$E16),"No existe información"))))} -> No existe información | H16: {=_xlfn.SINGLE(_xlfn.XLOOKUP(1,(T_ASIGNATURA1[ID_CARRERA]=Tabla1[[#This Row],[CARRERA]])*(T_ASIGNATURA1[NOM_ASIG]=Tabla1[[#This Row],[ASIGNATURA]])*(T_ASIGNATURA1[ID_NIVEL]=Tabla1[[#This Row],[NIVEL]]),T_ASIGNATURA1[HORAS],0))} -> 0 | J16: =+Tabla1[[#This Row],['# SEMANAS]]*Tabla1[[#This Row],[HORAS]] -> 0 | N16: =+Tabla1[[#This Row],[H.INVESTIGACION]]+Tabla1[[#This Row],[H.ADI_02]]+Tabla1[[#This Row],[H.ADI_01]]+Tabla1[[#This Row],[HORAS_SEMANAS]] -> 0 | P16: =SUMIF($O:$O, O16, $N:$N) -> 0 | Q16: =_xlfn.XLOOKUP(Tabla1[[#This Row],[NOMBRE_DOCENT]],Tabla1__3[DATOS_DOCENTE],Tabla1__3[ID_DOCENTE]) -> #N/A
A17: AUDITORÍA Y CONTROL DE GESTIÓN 2024 | B17: =_xlfn.XLOOKUP(Tabla1[[#This Row],[CARRERA]],T_CARREAS1[NOMBRE_CARRERA],T_CARREAS1[ID_CARRERA]) -> 2026-FCACC-2 | F17: {=_xlfn.TEXTJOIN(", ",TRUE,TRANSPOSE(_xlfn.UNIQUE(_xlfn._xlws.FILTER(Tabla3[DETALLADO],(Tabla3[NIVEL]=ASIGNACION!$C17)*(Tabla3[CARRERA]=ASIGNACION!$A17)*(Tabla3[ASIGNATURA]=ASIGNACION!$E17),"No existe información"))))} -> No existe información | H17: {=_xlfn.SINGLE(_xlfn.XLOOKUP(1,(T_ASIGNATURA1[ID_CARRERA]=Tabla1[[#This Row],[CARRERA]])*(T_ASIGNATURA1[NOM_ASIG]=Tabla1[[#This Row],[ASIGNATURA]])*(T_ASIGNATURA1[ID_NIVEL]=Tabla1[[#This Row],[NIVEL]]),T_ASIGNATURA1[HORAS],0))} -> 0 | J17: =+Tabla1[[#This Row],['# SEMANAS]]*Tabla1[[#This Row],[HORAS]] -> 0 | N17: =+Tabla1[[#This Row],[H.INVESTIGACION]]+Tabla1[[#This Row],[H.ADI_02]]+Tabla1[[#This Row],[H.ADI_01]]+Tabla1[[#This Row],[HORAS_SEMANAS]] -> 0 | P17: =SUMIF($O:$O, O17, $N:$N) -> 0 | Q17: =_xlfn.XLOOKUP(Tabla1[[#This Row],[NOMBRE_DOCENT]],Tabla1__3[DATOS_DOCENTE],Tabla1__3[ID_DOCENTE]) -> #N/A
A18: AUDITORÍA Y CONTROL DE GESTIÓN 2024 | B18: =_xlfn.XLOOKUP(Tabla1[[#This Row],[CARRERA]],T_CARREAS1[NOMBRE_CARRERA],T_CARREAS1[ID_CARRERA]) -> 2026-FCACC-2 | F18: {=_xlfn.TEXTJOIN(", ",TRUE,TRANSPOSE(_xlfn.UNIQUE(_xlfn._xlws.FILTER(Tabla3[DETALLADO],(Tabla3[NIVEL]=ASIGNACION!$C18)*(Tabla3[CARRERA]=ASIGNACION!$A18)*(Tabla3[ASIGNATURA]=ASIGNACION!$E18),"No existe información"))))} -> No existe información | H18: {=_xlfn.SINGLE(_xlfn.XLOOKUP(1,(T_ASIGNATURA1[ID_CARRERA]=Tabla1[[#This Row],[CARRERA]])*(T_ASIGNATURA1[NOM_ASIG]=Tabla1[[#This Row],[ASIGNATURA]])*(T_ASIGNATURA1[ID_NIVEL]=Tabla1[[#This Row],[NIVEL]]),T_ASIGNATURA1[HORAS],0))} -> 0 | J18: =+Tabla1[[#This Row],['# SEMANAS]]*Tabla1[[#This Row],[HORAS]] -> 0 | N18: =+Tabla1[[#This Row],[H.INVESTIGACION]]+Tabla1[[#This Row],[H.ADI_02]]+Tabla1[[#This Row],[H.ADI_01]]+Tabla1[[#This Row],[HORAS_SEMANAS]] -> 0 | P18: =SUMIF($O:$O, O18, $N:$N) -> 0 | Q18: =_xlfn.XLOOKUP(Tabla1[[#This Row],[NOMBRE_DOCENT]],Tabla1__3[DATOS_DOCENTE],Tabla1__3[ID_DOCENTE]) -> #N/A
A19: AUDITORÍA Y CONTROL DE GESTIÓN 2024 | B19: =_xlfn.XLOOKUP(Tabla1[[#This Row],[CARRERA]],T_CARREAS1[NOMBRE_CARRERA],T_CARREAS1[ID_CARRERA]) -> 2026-FCACC-2 | C19: {=INDIRECT(A19)} -> #REF! | F19: {=_xlfn.TEXTJOIN(", ",TRUE,TRANSPOSE(_xlfn.UNIQUE(_xlfn._xlws.FILTER(Tabla3[DETALLADO],(Tabla3[NIVEL]=ASIGNACION!$C19)*(Tabla3[CARRERA]=ASIGNACION!$A19)*(Tabla3[ASIGNATURA]=ASIGNACION!$E19),"No existe información"))))} -> #REF! | H19: {=_xlfn.SINGLE(_xlfn.XLOOKUP(1,(T_ASIGNATURA1[ID_CARRERA]=Tabla1[[#This Row],[CARRERA]])*(T_ASIGNATURA1[NOM_ASIG]=Tabla1[[#This Row],[ASIGNATURA]])*(T_ASIGNATURA1[ID_NIVEL]=Tabla1[[#This Row],[NIVEL]]),T_ASIGNATURA1[HORAS],0))} -> 0 | J19: =+Tabla1[[#This Row],['# SEMANAS]]*Tabla1[[#This Row],[HORAS]] -> 0 | N19: =+Tabla1[[#This Row],[H.INVESTIGACION]]+Tabla1[[#This Row],[H.ADI_02]]+Tabla1[[#This Row],[H.ADI_01]]+Tabla1[[#This Row],[HORAS_SEMANAS]] -> 0 | P19: =SUMIF($O:$O, O19, $N:$N) -> 0 | Q19: =_xlfn.XLOOKUP(Tabla1[[#This Row],[NOMBRE_DOCENT]],Tabla1__3[DATOS_DOCENTE],Tabla1__3[ID_DOCENTE]) -> #N/A
A20: AUDITORÍA Y CONTROL DE GESTIÓN 2024 | B20: =_xlfn.XLOOKUP(Tabla1[[#This Row],[CARRERA]],T_CARREAS1[NOMBRE_CARRERA],T_CARREAS1[ID_CARRERA]) -> 2026-FCACC-2 | C20: {=INDIRECT(A20)} -> #REF! | F20: {=_xlfn.TEXTJOIN(", ",TRUE,TRANSPOSE(_xlfn.UNIQUE(_xlfn._xlws.FILTER(Tabla3[DETALLADO],(Tabla3[NIVEL]=ASIGNACION!$C20)*(Tabla3[CARRERA]=ASIGNACION!$A20)*(Tabla3[ASIGNATURA]=ASIGNACION!$E20),"No existe información"))))} -> #REF! | H20: {=_xlfn.SINGLE(_xlfn.XLOOKUP(1,(T_ASIGNATURA1[ID_CARRERA]=Tabla1[[#This Row],[CARRERA]])*(T_ASIGNATURA1[NOM_ASIG]=Tabla1[[#This Row],[ASIGNATURA]])*(T_ASIGNATURA1[ID_NIVEL]=Tabla1[[#This Row],[NIVEL]]),T_ASIGNATURA1[HORAS],0))} -> 0 | J20: =+Tabla1[[#This Row],['# SEMANAS]]*Tabla1[[#This Row],[HORAS]] -> 0 | N20: =+Tabla1[[#This Row],[H.INVESTIGACION]]+Tabla1[[#This Row],[H.ADI_02]]+Tabla1[[#This Row],[H.ADI_01]]+Tabla1[[#This Row],[HORAS_SEMANAS]] -> 0 | P20: =SUMIF($O:$O, O20, $N:$N) -> 0 | Q20: =_xlfn.XLOOKUP(Tabla1[[#This Row],[NOMBRE_DOCENT]],Tabla1__3[DATOS_DOCENTE],Tabla1__3[ID_DOCENTE]) -> #N/A
